Workbook

Sheet 合计数量
A2: 部位 | B2: 板厚 | C2: 单位 | D2: 图纸数量 | G2: 复核数量 | H2: 差异 | I2: 备注
D3: Q355 | E3: Q420 | F3: 合计
A4: 钢梁 | B4: 0.18 | C4: kg | F4: =D4+E4 -> 0 | G4: =SUMIFS(主梁数量!$J$4:$J$3777,主梁数量!$G$4:$G$3777,0.18) -> 0.01580072 | H4: =G4-F4 -> 0.01580072 | I4: 未完成:无来源页
B5: 4 | C5: kg | D5: 343.2 | E5: 107.3 | F5: =D5+E5 -> 450.5 | G5: =SUMIFS(主梁数量!$J$4:$J$3777,主梁数量!$G$4:$G$3777,4) -> 5981.4179 | H5: =G5-F5 -> 5530.9179 | I5: 来源页57,61,74,78,82,90,102,106,115,119,123,131,137,142,171,175,187,191,199,203,212,216,224,230
B6: 6 | C6: kg | F6: =D6+E6 -> 0 | G6: =SUMIFS(主梁数量!$J$4:$J$3777,主梁数量!$G$4:$G$3777,6) -> 4041.8695 | H6: =G6-F6 -> 4041.8695 | I6: 未完成:无来源页
B7: 8 | C7: kg | D7: 883.2 | F7: =D7+E7 -> 883.2 | G7: =SUMIFS(主梁数量!$J$4:$J$3777,主梁数量!$G$4:$G$3777,8) -> 825187.62 | H7: =G7-F7 -> 824304.42 | I7: 来源页82,106,123,175,191,199,203,216
B8: 10 | C8: kg | F8: =D8+E8 -> 0 | G8: =SUMIFS(主梁数量!$J$4:$J$3777,主梁数量!$G$4:$G$3777,10)+横隔板!N139 -> 78746.349 | H8: =G8-F8 -> 78746.349 | I8: 未完成:无来源页
B9: 12 | C9: kg | D9: 727.2 | F9: =D9+E9 -> 727.2 | G9: =SUMIFS(主梁数量!$J$4:$J$3777,主梁数量!$G$4:$G$3777,12)+横隔板!O139 -> 615901.45 | H9: =G9-F9 -> 615174.25 | I9: 来源页102,106,191
B10: 14 | C10: kg | D10: 34571.9 | E10: 1837.3 | F10: =D10+E10 -> 36409.2 | G10: =SUMIFS(主梁数量!$J$4:$J$3777,主梁数量!$G$4:$G$3777,14)+横隔板!P139 -> 3101000.1 | H10: =G10-F10 -> 3064590.9 | I10: 来源页57,61,74,78,90,102,106,115,119,123,131,137,142,171,175,187,203,212,216,224,230
B11: 16 | C11: kg | D11: 79775.9 | E11: 12789 | F11: =D11+E11 -> 92564.9 | G11: =SUMIFS(主梁数量!$J$4:$J$3777,主梁数量!$G$4:$G$3777,16)+横隔板!Q139 -> 268843.35 | H11: =G11-F11 -> 176278.45 | I11: 来源页53,57,61,74,78,82,90,102,106,115,119,123,131,137,142,158,171,175,187,199,203,212,216,224,230
B12: 20 | C12: kg | D12: 289469.5 | F12: =D12+E12 -> 289469.5 | G12: =SUMIFS(主梁数量!$J$4:$J$3777,主梁数量!$G$4:$G$3777,20)+横隔板!R139 -> 1171114.3 | H12: =G12-F12 -> 881644.83 | I12: 来源页53,57,61,82,90,102,106,123,131,137,142,158,175,187,191,199,203,216,224,230
B13: 24 | C13: kg | D13: 201691.3 | E13: 7296.3 | F13: =D13+E13 -> 208987.6 | G13: =SUMIFS(主梁数量!$J$4:$J$3777,主梁数量!$G$4:$G$3777,24)+横隔板!S139 -> 1442470.5 | H13: =G13-F13 -> 1233482.9 | I13: 来源页53,57,61,74,78,82,90,102,106,115,119,123,131,137,142,158,171,175,187,191,199,203,212,216,224,230
B14: 28 | C14: kg | D14: 56119.4 | E14: 8759.1 | F14: =D14+E14 -> 64878.5 | G14: =SUMIFS(主梁数量!$J$4:$J$3777,主梁数量!$G$4:$G$3777,28)+横隔板!T139 -> 175678.8 | H14: =G14-F14 -> 110800.3 | I14: 来源页53,74,78,82,90,102,106,115,123,137,142,158,171,175,187,191,199,203,212,216,230
B15: 30 | C15: kg | F15: =D15+E15 -> 0 | G15: =SUMIFS(主梁数量!$J$4:$J$3777,主梁数量!$G$4:$G$3777,30)+横隔板!U139 -> 2411.52 | H15: =G15-F15 -> 2411.52 | I15: 未完成:无来源页
B16: 32 | C16: kg | D16: 245506.8 | E16: 131358.3 | F16: =D16+E16 -> 376865.1 | G16: =SUMIFS(主梁数量!$J$4:$J$3777,主梁数量!$G$4:$G$3777,32) -> 892300.08 | H16: =G16-F16 -> 515434.98 | I16: 来源页53,57,61,74,78,82,90,102,106,115,119,123,131,137,142,158,171,175,187,199,203,212,216,224,230
B17: 36 | C17: kg | D17: 320751.9 | E17: 12558.6 | F17: =D17+E17 -> 333310.5 | G17: =SUMIFS(主梁数量!$J$4:$J$3777,主梁数量!$G$4:$G$3777,36) -> 643930.03 | H17: =G17-F17 -> 310619.53 | I17: 来源页57,61,74,78,82,90,102,106,115,119,123,131,137,142,171,175,187,191,199,203,212,216,224,230
B18: 40 | C18: kg | D18: 332927.5 | E18: 140254.1 | F18: =D18+E18 -> 473181.6 | G18: =SUMIFS(主梁数量!$J$4:$J$3777,主梁数量!$G$4:$G$3777,40)+横隔板!V139 -> 398336.65 | H18: =G18-F18 -> -74844.949 | I18: 来源页57,61,74,78,90,102,106,115,119,123,131,137,142,171,175,187,203,212,216,224,230
B19: 44 | C19: kg | D19: 64347.4 | E19: 122459.4 | F19: =D19+E19 -> 186806.8 | G19: =SUMIFS(主梁数量!$J$4:$J$3777,主梁数量!$G$4:$G$3777,44) -> 110023.5 | H19: =G19-F19 -> -76783.301 | I19: 来源页53,74,78,82,90,102,106,115,123,158,171,175,187,199,203,212,216
B20: 48 | C20: kg | D20: 0 | E20: 127179.6 | F20: =D20+E20 -> 127179.6 | G20: =SUMIFS(主梁数量!$J$4:$J$3777,主梁数量!$G$4:$G$3777,48) -> 150975.53 | H20: =G20-F20 -> 23795.928 | I20: 来源页74,78,106,115,119,171,203,212
B21: 50 | C21: kg | F21: =D21+E21 -> 0 | G21: =SUMIFS(主梁数量!$J$4:$J$3777,主梁数量!$G$4:$G$3777,50)+横隔板!W139 -> 10688.56 | H21: =G21-F21 -> 10688.56 | I21: 未完成:无来源页
B22: 60 | C22: kg | F22: =D22+E22 -> 0 | G22: =SUMIFS(主梁数量!$J$4:$J$3777,主梁数量!$G$4:$G$3777,60) -> 12202.951 | H22: =G22-F22 -> 12202.951 | I22: 未完成:无来源页
B23: 80 | C23: kg | D23: 4069.4 | E23: 4659.8 | F23: =D23+E23 -> 8729.2 | G23: =SUMIFS(主梁数量!$J$4:$J$3777,主梁数量!$G$4:$G$3777,80) -> 9319.52 | H23: =G23-F23 -> 590.32 | I23: 来源页115,137,230
B24: 100 | C24: kg | D24: 2543.4 | E24: 0 | F24: =D24+E24 -> 2543.4 | G24: =SUMIFS(主梁数量!$J$4:$J$3777,主梁数量!$G$4:$G$3777,100) -> 11649.4 | H24: =G24-F24 -> 9106 | I24: 来源页74,142
A25: 梁底挡块 | B25: 20 | C25: kg | F25: 7638.4 | G25: =梁底挡块!F8 -> 7639.68 | H25: =G25-F25 -> 1.28
A26: 钢梁制造合计 | C26: kg | F26: =SUM(F4:F25) -> 2210625.2 | G26: =SUM(G4:G25) -> 9938443.3 | H26: =G26-F26 -> 7727818.1
A27: 附属预埋 | B27: 护栏 | C27: kg | F27: 588.9 | G27: 0 | H27: =G27-F27 -> -588.9 | I27: 属于伸缩缝出护栏挡板，与混凝土护栏浇筑标段有冲突，待确认
B28: 排水 | C28: kg | F28: =7835.2 -> 7835.2 | G28: =附属预埋件!F11 -> 7836 | H28: =G28-F28 -> 0.8

Sheet 主梁数量
A2: 梁板编号 | B2: 板件名称 | C2: 位置 | D2: 材质 | E2: 长 | F2: 宽 | G2: 厚 | H2: 单件重 | I2: 数量 | J2: 合计重量 | K2: 备注 | L2: 梁板编号 | M2: 复核数量 | U2: 图纸数量 | V2: 差异 | W2: 备注
E3: mm | F3: mm | G3: mm | H3: kg | J3: kg | M3: 12 | N3: 14 | O3: 16 | P3: 20 | Q3: 24 | R3: 30 | S3: 40 | T3: 合计
A4: P1 | C4: 节段1~节段2 | D4: Q355D | E4: 1020 | F4: 1800 | G4: 16 | H4: =(E4/1000)*(F4/1000)*(G4/1000)*7850 -> 230.6016 | I4: 2 | J4: =H4*I4 -> 461.2032 | K4: 来源页52 | L4: =A4 -> P1 | M4: =SUMIF(G4:G31,$M$3,J4:J31) -> 0 | N4: =SUMIF(G4:G31,$N$3,J4:J31) -> 0 | O4: =SUMIF(G4:G31,$O$3,J4:J31) -> 2868.4026 | P4: =SUMIF(G4:G31,$P$3,J4:J31) -> 12008.819 | Q4: =SUMIF(G4:G31,$Q$3,J4:J31) -> 1542.7699 | R4: =SUMIF(G4:G31,$R$3,J4:J31) -> 0 | S4: =SUMIF(G4:G31,$S$3,J4:J31) -> 0 | T4: =SUM(M4:S32) -> 16419.992 | U4: 142867.8 | V4: =T4-U4 -> -126447.81
C5: 节段1~节段2 | D5: Q355D | E5: 1020 | F5: 500 | G5: 16 | H5: =(E5/1000)*(F5/1000)*(G5/1000)*7850 -> 64.056 | I5: 2 | J5: =H5*I5 -> 128.112 | K5: 来源页52
C6: 节段1~节段2 | D6: Q355D | E6: 1020 | F6: 500 | G6: 16 | H6: =(E6/1000)*(F6/1000)*(G6/1000)*7850 -> 64.056 | I6: 2 | J6: =H6*I6 -> 128.112 | K6: 来源页52
C7: 节段1~节段2 | D7: Q355D | E7: 1020 | F7: 600 | G7: 16 | H7: =(E7/1000)*(F7/1000)*(G7/1000)*7850 -> 76.8672 | I7: 2 | J7: =H7*I7 -> 153.7344 | K7: 来源页52
C8: 节段1~节段2 | D8: Q355D | E8: 1420 | F8: 1100 | G8: 28 | H8: =(E8/1000)*(F8/1000)*(G8/1000)*7850 -> 343.3276 | I8: 1 | J8: =H8*I8 -> 343.3276 | K8: 来源页52
C9: 节段1~节段2 | D9: Q355D | E9: 1420 | F9: 400 | G9: 28 | H9: =(E9/1000)*(F9/1000)*(G9/1000)*7850 -> 124.8464 | I9: 2 | J9: =H9*I9 -> 249.6928 | K9: 来源页52
C10: 节段1~节段2 | D10: Q355D | E10: 920 | F10: 200 | G10: 20 | H10: =(E10/1000)*(F10/1000)*(G10/1000)*7850 -> 28.888 | I10: 10 | J10: =H10*I10 -> 288.88 | K10: 来源页52
C11: 节段1~节段2 | D11: Q355D | E11: 600 | F11: 1800 | G11: 20 | H11: =(E11/1000)*(F11/1000)*(G11/1000)*7850 -> 169.56 | I11: 2 | J11: =H11*I11 -> 339.12 | K11: 来源页52
C12: 节段1~节段2 | D12: Q355D | E12: 820 | F12: 1700 | G12: 20 | H12: =(E12/1000)*(F12/1000)*(G12/1000)*7850 -> 218.858 | I12: 2 | J12: =H12*I12 -> 437.716 | K12: 来源页52
C13: 节段1~节段2 | D13: Q355D | E13: 820 | F13: 800 | G13: 20 | H13: =(E13/1000)*(F13/1000)*(G13/1000)*7850 -> 102.992 | I13: 4 | J13: =H13*I13 -> 411.968 | K13: 来源页52
C14: 节段1~节段2 | D14: Q355D | E14: 1120 | F14: 1100 | G14: 32 | H14: =(E14/1000)*(F14/1000)*(G14/1000)*7850 -> 309.4784 | I14: 1 | J14: =H14*I14 -> 309.4784 | K14: 来源页52
C15: 节段1~节段2 | D15: Q355D | E15: 1120 | F15: 400 | G15: 32 | H15: =(E15/1000)*(F15/1000)*(G15/1000)*7850 -> 112.5376 | I15: 2 | J15: =H15*I15 -> 225.0752 | K15: 来源页52
C16: 节段1~节段2 | D16: Q355D | E16: 920 | F16: 200 | G16: 20 | H16: =(E16/1000)*(F16/1000)*(G16/1000)*7850 -> 28.888 | I16: 9 | J16: =H16*I16 -> 259.992 | K16: 【待核】来源页52
... C31: 节段02 | D31: Q355D | E31: 2057 | F31: 200 | G31: 16 | H31: =(E31/1000)*(F31/1000)*(G31/1000)*7850 -> 51.67184 | I31: 4 | J31: =H31*I31 -> 206.68736 | K31: 来源页53
B32: 小计 | J32: =SUM(J4:J31) -> 18986.364
A33: N15b | C33: 节段02 | D33: Q355B | E33: 2057 | F33: 40 | G33: 4 | H33: =(E33/1000)*(F33/1000)*(G33/1000)*7850 -> 2.583592 | I33: 4 | J33: =H33*I33 -> 10.334368 | K33: 来源页53 | L33: =A33 -> N15b | M33: =SUMIF(G33:G57,$M$3,J33:J57) -> 0 | N33: =SUMIF(G33:G57,$N$3,J33:J57) -> 672.84956 | O33: =SUMIF(G33:G57,$O$3,J33:J57) -> 2253.5906 | P33: =SUMIF(G33:G57,$P$3,J33:J57) -> 8836.1484 | Q33: =SUMIF(G33:G57,$Q$3,J33:J57) -> 17548.507 | R33: =SUMIF(G33:G57,$R$3,J33:J57) -> 0 | S33: =SUMIF(G33:G57,$S$3,J33:J57) -> 0 | T33: =SUM(M33:S58) -> 29311.095 | U33: 141450.9 | V33: =T33-U33 -> -112139.8
C34: 节段02 | D34: Q355D | E34: 800 | F34: 400 | G34: 16 | H34: =(E34/1000)*(F34/1000)*(G34/1000)*7850 -> 40.192 | I34: 4 | J34: =H34*I34 -> 160.768 | K34: 来源页53
C35: 节段02 | D35: Q355D | E35: 7902 | F35: 240 | G35: 20 | H35: =(E35/1000)*(F35/1000)*(G35/1000)*7850 -> 297.74736 | I35: 9 | J35: =H35*I35 -> 2679.7262 | K35: 【待核】来源页53
C36: 节段02 | D36: Q355D | E36: 10151 | F36: 240 | G36: 20 | H36: =(E36/1000)*(F36/1000)*(G36/1000)*7850 -> 382.48968 | I36: 9 | J36: =H36*I36 -> 3442.4071 | K36: 【待核】来源页53
C37: 节段02 | D37: Q355D | E37: 7902 | F37: 2500 | G37: 24 | H37: =(E37/1000)*(F37/1000)*(G37/1000)*7850 -> 3721.842 | I37: 1 | J37: =H37*I37 -> 3721.842 | K37: 来源页53
C38: 节段02 | D38: Q355D | E38: 10105 | F38: 2500 | G38: 24 | H38: =(E38/1000)*(F38/1000)*(G38/1000)*7850 -> 4759.455 | I38: 1 | J38: =H38*I38 -> 4759.455 | K38: 来源页53
C39: 节段02 | D39: Q355D | E39: 10305 | F39: 1880 | G39: 24 | H39: =(E39/1000)*(F39/1000)*(G39/1000)*7850 -> 3649.9486 | I39: 2 | J39: =H39*I39 -> 7299.8971 | K39: 来源页53
C40: 节段02 | D40: Q355D | E40: 1800 | F40: 1200 | G40: 16 | H40: =(E40/1000)*(F40/1000)*(G40/1000)*7850 -> 271.296 | I40: 3 | J40: =H40*I40 -> 813.888 | K40: 来源页53
C41: 节段02 | D41: Q355D | E41: 1800 | F41: 1200 | G41: 16 | H41: =(E41/1000)*(F41/1000)*(G41/1000)*7850 -> 271.296 | I41: 3 | J41: =H41*I41 -> 813.888 | K41: 来源页53
C42: 节段02 | D42: Q355D | E42: 2057 | F42: 200 | G42: 16 | H42: =(E42/1000)*(F42/1000)*(G42/1000)*7850 -> 51.67184 | I42: 9 | J42: =H42*I42 -> 465.04656 | K42: 【待核】来源页53
C43: 节段02 | D43: Q355D | E43: 7902 | F43: 240 | G43: 20 | H43: =(E43/1000)*(F43/1000)*(G43/1000)*7850 -> 297.74736 | I43: 2 | J43: =H43*I43 -> 595.49472 | K43: 来源页53
C44: 节段02 | D44: Q355D | E44: 7902 | F44: 240 | G44: 20 | H44: =(E44/1000)*(F44/1000)*(G44/1000)*7850 -> 297.74736 | I44: 2 | J44: =H44*I44 -> 595.49472 | K44: 来源页53
C45: 节段02 | D45: Q355D | E45: 10105 | F45: 240 | G45: 20 | H45: =(E45/1000)*(F45/1000)*(G45/1000)*7850 -> 380.7564 | I45: 4 | J45: =H45*I45 -> 1523.0256 | K45: 来源页53
... C57: 节段02 | D57: Q355D | E57: 6425 | F57: 320 | G57: 32 | H57: =(E57/1000)*(F57/1000)*(G57/1000)*7850 -> 516.4672 | I57: 1 | J57: =H57*I57 -> 516.4672 | K57: 来源页53
B58: 小计 | J58: =SUM(J33:J57) -> 53186.604
A59: N53b | C59: 节段02 | D59: Q355D | E59: 6025 | F59: 320 | G59: 32 | H59: =(E59/1000)*(F59/1000)*(G59/1000)*7850 -> 484.3136 | I59: 1 | J59: =H59*I59 -> 484.3136 | K59: 来源页53 | L59: =A59 -> N53b | M59: =SUMIF(G59:G83,$M$3,J59:J83) -> 0 | N59: =SUMIF(G59:G83,$N$3,J59:J83) -> 4257.482 | O59: =SUMIF(G59:G83,$O$3,J59:J83) -> 1232.8896 | P59: =SUMIF(G59:G83,$P$3,J59:J83) -> 1967.524 | Q59: =SUMIF(G59:G83,$Q$3,J59:J83) -> 0 | R59: =SUMIF(G59:G83,$R$3,J59:J83) -> 0 | S59: =SUMIF(G59:G83,$S$3,J59:J83) -> 0 | T59: =SUM(M59:S84) -> 7457.8956 | U59: 141854 | V59: =T59-U59 -> -134396.1
C60: 节段02 | D60: Q355D | E60: 1200 | F60: 1200 | G60: 16 | H60: =(E60/1000)*(F60/1000)*(G60/1000)*7850 -> 180.864 | I60: 2 | J60: =H60*I60 -> 361.728 | K60: 来源页53
C61: 节段02 | D61: Q355D | E61: 2150 | F61: 320 | G61: 32 | H61: =(E61/1000)*(F61/1000)*(G61/1000)*7850 -> 172.8256 | I61: 2 | J61: =H61*I61 -> 345.6512 | K61: 来源页53
C62: 节段02 | D62: Q355D | E62: 1980 | F62: 610 | G62: 14 | H62: =(E62/1000)*(F62/1000)*(G62/1000)*7850 -> 132.73722 | I62: 9 | J62: =H62*I62 -> 1194.635 | K62: 【待核】来源页53
C63: 节段02 | D63: Q355D | E63: 1980 | F63: 630 | G63: 14 | H63: =(E63/1000)*(F63/1000)*(G63/1000)*7850 -> 137.08926 | I63: 9 | J63: =H63*I63 -> 1233.8033 | K63: 【待核】来源页53
C64: 节段02 | D64: Q355D | E64: 1800 | F64: 610 | G64: 14 | H64: =(E64/1000)*(F64/1000)*(G64/1000)*7850 -> 120.6702 | I64: 9 | J64: =H64*I64 -> 1086.0318 | K64: 【待核】来源页53
C65: 节段02 | D65: Q355D | E65: 1800 | F65: 626 | G65: 14 | H65: =(E65/1000)*(F65/1000)*(G65/1000)*7850 -> 123.83532 | I65: 6 | J65: =H65*I65 -> 743.01192 | K65: 来源页53
D66: Q355D | E66: 1020 | F66: 1800 | G66: 16 | H66: =(E66/1000)*(F66/1000)*(G66/1000)*7850 -> 230.6016 | I66: 2 | J66: =H66*I66 -> 461.2032 | K66: 来源页56
...

Sheet 横隔板
A2: 梁板编号 | B2: 板件名称 | C2: 位置 | D2: 材质 | E2: 长 | F2: 宽 | G2: 厚 | H2: 数量 | I2: 单件重 | J2: 全桥数量 | K2: 合计重量 | L2: 备注 | M2: 梁板编号 | O2: 复核数量 | Y2: 图纸数量 | Z2: 差异 | AA2: 备注
E3: mm | F3: mm | G3: mm | I3: kg | K3: kg | N3: 10 | O3: 12 | P3: 14 | Q3: 16 | R3: 20 | S3: 24 | T3: 28 | U3: 30 | V3: 40 | W3: 50 | X3: 合计
A4: 横隔板 | B4: Z1边支点横隔板 | C4: N1 | D4: Q355MD | E4: 1951 | F4: 1790 | G4: 20 | H4: 1 | I4: =(E4/1000)*(F4/1000)*(G4/1000)*7850*H4 -> 548.28953 | J4: 32 | K4: =I4*J4 -> 17545.265 | M4: =B4 -> Z1边支点横隔板 | O4: =SUMIF(G4:G22,$O$3,K4:K22) -> 646.4 | P4: =SUMIF(G4:G22,$P$3,K4:K22) -> 0 | Q4: =SUMIF(G4:G22,$Q$3,K4:K22) -> 0 | R4: =SUMIF(G4:G22,$R$3,K4:K22) -> 131616.82 | S4: =SUMIF(G4:G22,$S$3,K4:K22) -> 0 | U4: =SUMIF(G4:G22,$U$3,K4:K22) -> 2411.52 | V4: =SUMIF(G4:G22,$V$3,K4:K22) -> 6430.72 | X4: =SUM(O4:V23) -> 141105.46 | Y4: 141101.8 | Z4: =X4-Y4 -> 3.66464
C5: N2 | D5: Q355MD | E5: 2718 | F5: 2550 | G5: 20 | H5: 1 | I5: 1033.76 | J5: 32 | K5: =I5*J5 -> 33080.32
C6: N3 | D6: Q355MD | E6: 2653 | F6: 470 | G6: 20 | H6: 1 | I6: 132.31 | J6: 32 | K6: =I6*J6 -> 4233.92
C7: N3' | D7: Q355MD | E7: 2653 | F7: 440 | G7: 20 | H7: 1 | I7: 119.56 | J7: 32 | K7: =I7*J7 -> 3825.92
C8: N3a | D8: Q355MD | E8: 2671 | F8: 470 | G8: 20 | H8: 1 | I8: 132.98 | J8: 32 | K8: =I8*J8 -> 4255.36
C9: N3a' | D9: Q355MD | E9: 2671 | F9: 440 | G9: 20 | H9: 1 | I9: 120.24 | J9: 32 | K9: =I9*J9 -> 3847.68
C10: N3b | D10: Q355MD | E10: 2689 | F10: 470 | G10: 20 | H10: 1 | I10: 133.66 | J10: 32 | K10: =I10*J10 -> 4277.12
C11: N3b' | D11: Q355MD | E11: 2689 | F11: 440 | G11: 20 | H11: 1 | I11: 120.91 | J11: 32 | K11: =I11*J11 -> 3869.12
C12: N3c | D12: Q355MD | E12: 2707 | F12: 470 | G12: 20 | H12: 1 | I12: 134.34 | J12: 32 | K12: =I12*J12 -> 4298.88
C13: N3c' | D13: Q355MD | E13: 2707 | F13: 440 | G13: 20 | H13: 1 | I13: 121.59 | J13: 32 | K13: =I13*J13 -> 3890.88
C14: N3d | D14: Q355MD | E14: 1150 | F14: 470 | G14: 20 | H14: 1 | I14: 75.68 | J14: 32 | K14: =I14*J14 -> 2421.76
C15: N3d' | D15: Q355MD | E15: 1150 | F15: 440 | G15: 20 | H15: 1 | I15: 62.32 | J15: 32 | K15: =I15*J15 -> 1994.24
C16: N4 | D16: Q355MD | E16: 776 | F16: 160 | G16: 20 | H16: 2 | I16: =(E16/1000)*(F16/1000)*(G16/1000)*7850*H16 -> 38.98624 | J16: 32 | K16: =I16*J16 -> 1247.5597
C17: N5 | D17: Q355MD | E17: 500 | F17: 240 | G17: 20 | H17: 2 | I17: 33.7 | J17: 32 | K17: =I17*J17 -> 1078.4
C18: N6 | D18: Q355MD | E18: 400 | F18: 400 | G18: 30 | H18: 2 | I18: =(E18/1000)*(F18/1000)*(G18/1000)*7850*H18 -> 75.36 | J18: 32 | K18: =I18*J18 -> 2411.52
C19: N7 | D19: Q355MD | E19: 800 | F19: 800 | G19: 40 | H19: 1 | I19: =(E19/1000)*(F19/1000)*(G19/1000)*7850*H19 -> 200.96 | J19: 32 | K19: =I19*J19 -> 6430.72
C20: N8 | D20: Q355MD | E20: 840 | F20: 540 | G20: 12 | H20: 2 | I20: 20.2 | J20: 32 | K20: =I20*J20 -> 646.4 | L20: 数量有误需设计核实
C21: N9 | D21: Q355MD | E21: 2718 | F21: 2550 | G21: 20 | H21: 1 | I21: 1033.8 | J21: 32 | K21: =I21*J21 -> 33081.6
C22: N10 | D22: Q355MD | E22: 740 | F22: 785 | G22: 20 | H22: 1 | I22: 270.9 | J22: 32 | K22: =I22*J22 -> 8668.8
B23: 小计 | K23: =SUM(K4:K22) -> 141105.46
A24: 横隔板 | B24: T1上层挑梁 | C24: N1T | D24: Q355MD | E24: 1109 | F24: 575 | G24: 20 | H24: 1 | I24: 65.3 | J24: 4 | K24: =I24*J24 -> 261.2 | M24: =B24 -> T1上层挑梁 | N24: =K26 -> 109.2 | Q24: =K27+K28 -> 234 | R24: =K24+K25 -> 1188.4 | X24: =SUM(N24:V24) -> 1531.6 | Y24: 1532.1 | Z24: =X24-Y24 -> -0.5
C25: N2T | D25: Q355MD | E25: 1790 | F25: 825 | G25: 20 | H25: 1 | I25: 231.8 | J25: 4 | K25: =I25*J25 -> 927.2
C26: N3T | D26: Q355MD | E26: 1161 | F26: 300 | G26: 10 | H26: 1 | I26: 27.3 | J26: 4 | K26: =I26*J26 -> 109.2
C27: N4T | D27: Q355MD | E27: 1234 | F27: 160 | G27: 16 | H27: 2 | I27: 49.6 | J27: 4 | K27: =I27*J27 -> 198.4
C28: N4Ta | D28: Q355MD | E28: 444 | F28: 160 | G28: 16 | H28: 1 | I28: 8.9 | J28: 4 | K28: =I28*J28 -> 35.6 | L28: 数量有误需设计核实
B29: 小计 | K29: =SUM(K24:K28) -> 1531.6
A30: 横隔板 | B30: T2上层挑梁 | C30: N1 | D30: Q355MD | E30: 1109 | F30: 575 | G30: 20 | H30: 1 | I30: 59.4 | J30: 4 | K30: =I30*J30 -> 237.6 | M30: =B30 -> T2上层挑梁 | N30: =K32 -> 100.8 | Q30: =K33+K34 -> 234 | R30: =K30+K31 -> 1052.4 | X30: =SUM(N30:V30) -> 1387.2 | Y30: 1387.5 | Z30: =X30-Y30 -> -0.3
C31: N2 | D31: Q355MD | E31: 1790 | F31: 725 | G31: 20 | H31: 1 | I31: 203.7 | J31: 4 | K31: =I31*J31 -> 814.8
C32: N3 | D32: Q355MD | E32: 1071 | F32: 300 | G32: 10 | H32: 1 | I32: 25.2 | J32: 4 | K32: =I32*J32 -> 100.8
C33: N4 | D33: Q355MD | E33: 1234 | F33: 160 | G33: 16 | H33: 2 | I33: 49.6 | J33: 4 | K33: =I33*J33 -> 198.4
C34: N4a | D34: Q355MD | E34: 444 | F34: 160 | G34: 16 | H34: 1 | I34: 8.9 | J34: 4 | K34: =I34*J34 -> 35.6 | L34: 数量有误需设计核实
B35: 小计 | K35: =SUM(K30:K34) -> 1387.2
A36: 横隔板 | B36: T3下层挑梁 | C36: N1' | D36: Q355MD | E36: 634 | F36: 575 | G36: 20 | H36: 1 | I36: 37.2 | J36: 8 | K36: =I36*J36 -> 297.6 | M36: =B36 -> T3下层挑梁 | N36: =K38 -> 139.2 | Q36: =K39+K40 -> 269.6 | R36: =K36+K37 -> 1084.8 | X36: =SUM(N36:V36) -> 1493.6 | Y36: 1492.9 | Z36: =X36-Y36 -> 0.7
C37: N2' | D37: Q355MD | E37: 1790 | F37: 350 | G37: 20 | H37: 1 | I37: 98.4 | J37: 8 | K37: =I37*J37 -> 787.2
C38: N3' | D38: Q355MD | E38: 738 | F38: 300 | G38: 10 | H38: 1 | I38: 17.4 | J38: 8 | K38: =I38*J38 -> 139.2
C39: N4' | D39: Q355MD | E39: 1234 | F39: 160 | G39: 16 | H39: 1 | I39: 24.8 | J39: 8 | K39: =I39*J39 -> 198.4
C40: N4a' | D40: Q355MD | E40: 444 | F40: 160 | G40: 16 | H40: 1 | I40: 8.9 | J40: 8 | K40: =I40*J40 -> 71.2
B41: 小计 | K41: =SUM(K36:K40) -> 1493.6
...

Sheet 梁底挡块
A2: 梁板编号 | B2: 板件名称 | C2: 位置 | D2: 材质 | E2: 长 | F2: 宽 | G2: 厚 | H2: 数量 | I2: 单件重 | J2: 全桥数量 | K2: 合计重量 | L2: 备注 | M2: 梁板编号 | S2: 图纸数量 | T2: 差异 | U2: 备注
E3: mm | F3: mm | G3: mm | I3: kg | K3: kg | N3: 16 | O3: 20 | P3: 24 | Q3: 28 | R3: 合计
A4: 梁间横梁 | B4: XJHL1 | C4: N1 | D4: Q355MD | E4: 600 | F4: 700 | G4: 20 | H4: 1 | I4: =(E4/1000)*(F4/1000)*(G4/1000)*7850*H4 -> 65.94 | J4: 32 | K4: =I4*J4 -> 2110.08 | M4: =B4 -> XJHL1 | O4: =K6 -> 7639.68 | R4: =SUM(N4:Q6) -> 7639.68 | S4: 7638.4 | T4: =R4-S4 -> 1.28
C5: N2 | D5: Q355MD | G5: 20 | H5: 4 | I5: 172.8 | J5: 32 | K5: =I5*J5 -> 5529.6
B6: 小计 | K6: =SUM(K4:K5) -> 7639.68
A7: 名称 | D7: 材质 | E7: 单位 | F7: 复核数量 | G7: 图纸数量 | I7: 差异
A8: 合计 | D8: =D5 -> Q355MD | E8: kg | F8: =R4 -> 7639.68 | G8: =S4 -> 7638.4 | I8: =F8-G8 -> 1.28

Sheet 附属预埋件
A2: 梁板编号 | B2: 板件名称 | C2: 位置 | D2: 材质 | E2: 长 | F2: 宽 | G2: 厚 | H2: 数量 | I2: 单件重 | J2: 全桥数量 | K2: 合计重量 | L2: 备注 | M2: 梁板编号 | S2: 图纸数量 | T2: 差异 | U2: 备注
E3: mm | F3: mm | G3: mm | I3: kg | K3: kg | N3: 4 | O3: 12 | P3: 24 | Q3: 28 | R3: 合计
A4: 排水 | B4: XJHL1 | C4: 上层N1 | D4: Q355C | E4: 647 | F4: 280 | G4: 12 | H4: 1 | I4: 15.83 | J4: 200 | K4: =I4*J4 -> 3166 | M4: =B4 -> XJHL1 | N4: =K8 -> 668 | O4: =K4+K5+K6+K7 -> 7168 | R4: =SUM(N4:Q9) -> 7836 | S4: 7835.18 | T4: =R4-S4 -> 0.82
C5: 下层N1 | D5: Q355C | E5: 277 | F5: 280 | G5: 12 | H5: 1 | I5: 6.07 | J5: 200 | K5: =I5*J5 -> 1214
C6: 上层N2 | D6: Q355C | E6: 530 | F6: 150 | G6: 12 | H6: 1 | I6: 5.23 | J6: 400 | K6: =I6*J6 -> 2092
C7: 下层N2 | D7: Q355C | E7: 160 | F7: 150 | G7: 12 | H7: 1 | I7: 1.74 | J7: 400 | K7: =I7*J7 -> 696
C8: N3 | D8: Q355C | E8: 663 | F8: 80 | G8: 4 | H8: 1 | I8: 1.67 | J8: 400 | K8: =I8*J8 -> 668
B9: 小计 | K9: =SUM(K4:K8) -> 7836
A10: 名称 | D10: 材质 | E10: 单位 | F10: 复核数量 | G10: 图纸数量 | I10: 差异
A11: 合计 | D11: =D8 -> Q355C | E11: kg | F11: =R4 -> 7836 | G11: =S4 -> 7835.18 | I11: =F11-G11 -> 0.82
