Workbook

Sheet 合计数量
A1: 新沙高架桥主桥上构钢结构数量复核汇总表（K6+418.3）
A2: 部位 | B2: 板厚 | C2: 单位 | D2: 图纸数量(kg) | G2: 复核数量(kg) | H2: 差异 | I2: 备注
D3: Q355D | E3: Q420D | F3: 合计
A4: 主桁 | B4: 14 | C4: kg | D4: 56947.4 | E4: 2518.5 | F4: =N(D4)+N(E4) -> 59465.9 | G4: =SUM(SUMIFS(主梁数量!$J$4:$J$1299,主梁数量!$D$4:$D$1299,D$3,主梁数量!$G$4:$G$1299,$B4),SUMIFS(主梁数量!$J$4:$J$1299,主梁数量!$D$4:$D$1299,E$3,主梁数量!$G$4:$G$1299,$B4),SUMIFS(横隔板!$J$4:$J$489,横隔板!$D$4:$D$489,D$3,横隔板!$G$4:$G$489,$B4),SUMIFS(横隔板!$J$4:$J$489,横隔板!$D$4:$D$489,E$3,横隔板!$G$4:$G$489,$B4)) -> 75247.263 | H4: =G4-F4 -> 15781.363
B5: 16 | C5: kg | D5: 115785.1 | E5: 27946.9 | F5: =N(D5)+N(E5) -> 143732 | G5: =SUM(SUMIFS(主梁数量!$J$4:$J$1299,主梁数量!$D$4:$D$1299,D$3,主梁数量!$G$4:$G$1299,$B5),SUMIFS(主梁数量!$J$4:$J$1299,主梁数量!$D$4:$D$1299,E$3,主梁数量!$G$4:$G$1299,$B5),SUMIFS(横隔板!$J$4:$J$489,横隔板!$D$4:$D$489,D$3,横隔板!$G$4:$G$489,$B5),SUMIFS(横隔板!$J$4:$J$489,横隔板!$D$4:$D$489,E$3,横隔板!$G$4:$G$489,$B5)) -> 139615.15 | H5: =G5-F5 -> -4116.8549
B6: 20 | C6: kg | D6: 423735 | F6: =N(D6)+N(E6) -> 423735 | G6: =SUM(SUMIFS(主梁数量!$J$4:$J$1299,主梁数量!$D$4:$D$1299,D$3,主梁数量!$G$4:$G$1299,$B6),SUMIFS(主梁数量!$J$4:$J$1299,主梁数量!$D$4:$D$1299,E$3,主梁数量!$G$4:$G$1299,$B6),SUMIFS(横隔板!$J$4:$J$489,横隔板!$D$4:$D$489,D$3,横隔板!$G$4:$G$489,$B6),SUMIFS(横隔板!$J$4:$J$489,横隔板!$D$4:$D$489,E$3,横隔板!$G$4:$G$489,$B6)) -> 468434.68 | H6: =G6-F6 -> 44699.677
B7: 24 | C7: kg | D7: 301501 | F7: =N(D7)+N(E7) -> 301501 | G7: =SUM(SUMIFS(主梁数量!$J$4:$J$1299,主梁数量!$D$4:$D$1299,D$3,主梁数量!$G$4:$G$1299,$B7),SUMIFS(主梁数量!$J$4:$J$1299,主梁数量!$D$4:$D$1299,E$3,主梁数量!$G$4:$G$1299,$B7),SUMIFS(横隔板!$J$4:$J$489,横隔板!$D$4:$D$489,D$3,横隔板!$G$4:$G$489,$B7),SUMIFS(横隔板!$J$4:$J$489,横隔板!$D$4:$D$489,E$3,横隔板!$G$4:$G$489,$B7)) -> 379066.25 | H7: =G7-F7 -> 77565.249
B8: 28 | C8: kg | D8: 60106.8 | F8: =N(D8)+N(E8) -> 60106.8 | G8: =SUM(SUMIFS(主梁数量!$J$4:$J$1299,主梁数量!$D$4:$D$1299,D$3,主梁数量!$G$4:$G$1299,$B8),SUMIFS(主梁数量!$J$4:$J$1299,主梁数量!$D$4:$D$1299,E$3,主梁数量!$G$4:$G$1299,$B8),SUMIFS(横隔板!$J$4:$J$489,横隔板!$D$4:$D$489,D$3,横隔板!$G$4:$G$489,$B8),SUMIFS(横隔板!$J$4:$J$489,横隔板!$D$4:$D$489,E$3,横隔板!$G$4:$G$489,$B8)) -> 55654.767 | H8: =G8-F8 -> -4452.0333
B9: 32 | C9: kg | D9: 398720.8 | E9: 275007.2 | F9: =N(D9)+N(E9) -> 673728 | G9: =SUM(SUMIFS(主梁数量!$J$4:$J$1299,主梁数量!$D$4:$D$1299,D$3,主梁数量!$G$4:$G$1299,$B9),SUMIFS(主梁数量!$J$4:$J$1299,主梁数量!$D$4:$D$1299,E$3,主梁数量!$G$4:$G$1299,$B9),SUMIFS(横隔板!$J$4:$J$489,横隔板!$D$4:$D$489,D$3,横隔板!$G$4:$G$489,$B9),SUMIFS(横隔板!$J$4:$J$489,横隔板!$D$4:$D$489,E$3,横隔板!$G$4:$G$489,$B9)) -> 736367.63 | H9: =G9-F9 -> 62639.634
B10: 36 | C10: kg | D10: 521193.4 | E10: 3283.8 | F10: =N(D10)+N(E10) -> 524477.2 | G10: =SUM(SUMIFS(主梁数量!$J$4:$J$1299,主梁数量!$D$4:$D$1299,D$3,主梁数量!$G$4:$G$1299,$B10),SUMIFS(主梁数量!$J$4:$J$1299,主梁数量!$D$4:$D$1299,E$3,主梁数量!$G$4:$G$1299,$B10),SUMIFS(横隔板!$J$4:$J$489,横隔板!$D$4:$D$489,D$3,横隔板!$G$4:$G$489,$B10),SUMIFS(横隔板!$J$4:$J$489,横隔板!$D$4:$D$489,E$3,横隔板!$G$4:$G$489,$B10)) -> 539462.37 | H10: =G10-F10 -> 14985.175
B11: 40 | C11: kg | D11: 497184.5 | E11: 307680.3 | F11: =N(D11)+N(E11) -> 804864.8 | G11: =SUM(SUMIFS(主梁数量!$J$4:$J$1299,主梁数量!$D$4:$D$1299,D$3,主梁数量!$G$4:$G$1299,$B11),SUMIFS(主梁数量!$J$4:$J$1299,主梁数量!$D$4:$D$1299,E$3,主梁数量!$G$4:$G$1299,$B11),SUMIFS(横隔板!$J$4:$J$489,横隔板!$D$4:$D$489,D$3,横隔板!$G$4:$G$489,$B11),SUMIFS(横隔板!$J$4:$J$489,横隔板!$D$4:$D$489,E$3,横隔板!$G$4:$G$489,$B11)) -> 871922.23 | H11: =G11-F11 -> 67057.434
B12: 44 | C12: kg | D12: 140063 | E12: 245856.9 | F12: =N(D12)+N(E12) -> 385919.9 | G12: =SUM(SUMIFS(主梁数量!$J$4:$J$1299,主梁数量!$D$4:$D$1299,D$3,主梁数量!$G$4:$G$1299,$B12),SUMIFS(主梁数量!$J$4:$J$1299,主梁数量!$D$4:$D$1299,E$3,主梁数量!$G$4:$G$1299,$B12),SUMIFS(横隔板!$J$4:$J$489,横隔板!$D$4:$D$489,D$3,横隔板!$G$4:$G$489,$B12),SUMIFS(横隔板!$J$4:$J$489,横隔板!$D$4:$D$489,E$3,横隔板!$G$4:$G$489,$B12)) -> 448954.1 | H12: =G12-F12 -> 63034.2
B13: 48 | C13: kg | D13: 33973.3 | E13: 248026.7 | F13: =N(D13)+N(E13) -> 282000 | G13: =SUM(SUMIFS(主梁数量!$J$4:$J$1299,主梁数量!$D$4:$D$1299,D$3,主梁数量!$G$4:$G$1299,$B13),SUMIFS(主梁数量!$J$4:$J$1299,主梁数量!$D$4:$D$1299,E$3,主梁数量!$G$4:$G$1299,$B13),SUMIFS(横隔板!$J$4:$J$489,横隔板!$D$4:$D$489,D$3,横隔板!$G$4:$G$489,$B13),SUMIFS(横隔板!$J$4:$J$489,横隔板!$D$4:$D$489,E$3,横隔板!$G$4:$G$489,$B13)) -> 305480.77 | H13: =G13-F13 -> 23480.773
B14: 60 | C14: kg | E14: 2458.8 | F14: =N(D14)+N(E14) -> 2458.8 | G14: =SUM(SUMIFS(主梁数量!$J$4:$J$1299,主梁数量!$D$4:$D$1299,D$3,主梁数量!$G$4:$G$1299,$B14),SUMIFS(主梁数量!$J$4:$J$1299,主梁数量!$D$4:$D$1299,E$3,主梁数量!$G$4:$G$1299,$B14),SUMIFS(横隔板!$J$4:$J$489,横隔板!$D$4:$D$489,D$3,横隔板!$G$4:$G$489,$B14),SUMIFS(横隔板!$J$4:$J$489,横隔板!$D$4:$D$489,E$3,横隔板!$G$4:$G$489,$B14)) -> 2466.8154 | H14: =G14-F14 -> 8.0154
B15: 80 | C15: kg | D15: 3052.1 | E15: 6989.7 | F15: =N(D15)+N(E15) -> 10041.8 | G15: =SUM(SUMIFS(主梁数量!$J$4:$J$1299,主梁数量!$D$4:$D$1299,D$3,主梁数量!$G$4:$G$1299,$B15),SUMIFS(主梁数量!$J$4:$J$1299,主梁数量!$D$4:$D$1299,E$3,主梁数量!$G$4:$G$1299,$B15),SUMIFS(横隔板!$J$4:$J$489,横隔板!$D$4:$D$489,D$3,横隔板!$G$4:$G$489,$B15),SUMIFS(横隔板!$J$4:$J$489,横隔板!$D$4:$D$489,E$3,横隔板!$G$4:$G$489,$B15)) -> 9319.52 | H15: =G15-F15 -> -722.28
B16: 100 | C16: kg | D16: 3815.1 | E16: 8737.1 | F16: =N(D16)+N(E16) -> 12552.2 | G16: =SUM(SUMIFS(主梁数量!$J$4:$J$1299,主梁数量!$D$4:$D$1299,D$3,主梁数量!$G$4:$G$1299,$B16),SUMIFS(主梁数量!$J$4:$J$1299,主梁数量!$D$4:$D$1299,E$3,主梁数量!$G$4:$G$1299,$B16),SUMIFS(横隔板!$J$4:$J$489,横隔板!$D$4:$D$489,D$3,横隔板!$G$4:$G$489,$B16),SUMIFS(横隔板!$J$4:$J$489,横隔板!$D$4:$D$489,E$3,横隔板!$G$4:$G$489,$B16)) -> 11649.4 | H16: =G16-F16 -> -902.8
A17: 主桁拼接 | B17: 8 | C17: kg | D17: 1352.2 | F17: =N(D17)+N(E17) -> 1352.2 | G17: =SUM(SUMIFS(主桁拼接!$J$4:$J$574,主桁拼接!$D$4:$D$574,D$3,主桁拼接!$G$4:$G$574,$B17),SUMIFS(主桁拼接!$J$4:$J$574,主桁拼接!$D$4:$D$574,E$3,主桁拼接!$G$4:$G$574,$B17)) -> 1096.488 | H17: =G17-F17 -> -255.712
B18: 12 | C18: kg | D18: 2006.1 | F18: =N(D18)+N(E18) -> 2006.1 | G18: =SUM(SUMIFS(主桁拼接!$J$4:$J$574,主桁拼接!$D$4:$D$574,D$3,主桁拼接!$G$4:$G$574,$B18),SUMIFS(主桁拼接!$J$4:$J$574,主桁拼接!$D$4:$D$574,E$3,主桁拼接!$G$4:$G$574,$B18)) -> 974.028 | H18: =G18-F18 -> -1032.072
B19: 14 | C19: kg | D19: 554.4 | F19: =N(D19)+N(E19) -> 554.4 | G19: =SUM(SUMIFS(主桁拼接!$J$4:$J$574,主桁拼接!$D$4:$D$574,D$3,主桁拼接!$G$4:$G$574,$B19),SUMIFS(主桁拼接!$J$4:$J$574,主桁拼接!$D$4:$D$574,E$3,主桁拼接!$G$4:$G$574,$B19)) -> 0 | H19: =G19-F19 -> -554.4
B20: 16 | C20: kg | D20: 9958.7 | F20: =N(D20)+N(E20) -> 9958.7 | G20: =SUM(SUMIFS(主桁拼接!$J$4:$J$574,主桁拼接!$D$4:$D$574,D$3,主桁拼接!$G$4:$G$574,$B20),SUMIFS(主桁拼接!$J$4:$J$574,主桁拼接!$D$4:$D$574,E$3,主桁拼接!$G$4:$G$574,$B20)) -> 9817.1472 | H20: =G20-F20 -> -141.5528
B21: 20 | C21: kg | D21: 22910.7 | F21: =N(D21)+N(E21) -> 22910.7 | G21: =SUM(SUMIFS(主桁拼接!$J$4:$J$574,主桁拼接!$D$4:$D$574,D$3,主桁拼接!$G$4:$G$574,$B21),SUMIFS(主桁拼接!$J$4:$J$574,主桁拼接!$D$4:$D$574,E$3,主桁拼接!$G$4:$G$574,$B21)) -> 21618.9 | H21: =G21-F21 -> -1291.8
B22: 24 | C22: kg | D22: 43378.8 | E22: 11198.7 | F22: =N(D22)+N(E22) -> 54577.5 | G22: =SUM(SUMIFS(主桁拼接!$J$4:$J$574,主桁拼接!$D$4:$D$574,D$3,主桁拼接!$G$4:$G$574,$B22),SUMIFS(主桁拼接!$J$4:$J$574,主桁拼接!$D$4:$D$574,E$3,主桁拼接!$G$4:$G$574,$B22)) -> 43806.858 | H22: =G22-F22 -> -10770.642
B23: 28 | C23: kg | D23: 45262.6 | E23: 12062.2 | F23: =N(D23)+N(E23) -> 57324.8 | G23: =SUM(SUMIFS(主桁拼接!$J$4:$J$574,主桁拼接!$D$4:$D$574,D$3,主桁拼接!$G$4:$G$574,$B23),SUMIFS(主桁拼接!$J$4:$J$574,主桁拼接!$D$4:$D$574,E$3,主桁拼接!$G$4:$G$574,$B23)) -> 47670.224 | H23: =G23-F23 -> -9654.576
B24: 32 | C24: kg | D24: 9954.8 | E24: 10990.2 | F24: =N(D24)+N(E24) -> 20945 | G24: =SUM(SUMIFS(主桁拼接!$J$4:$J$574,主桁拼接!$D$4:$D$574,D$3,主桁拼接!$G$4:$G$574,$B24),SUMIFS(主桁拼接!$J$4:$J$574,主桁拼接!$D$4:$D$574,E$3,主桁拼接!$G$4:$G$574,$B24)) -> 20314.042 | H24: =G24-F24 -> -630.9584
B25: 36 | C25: kg | D25: 10581.6 | E25: 8986.5 | F25: =N(D25)+N(E25) -> 19568.1 | G25: =SUM(SUMIFS(主桁拼接!$J$4:$J$574,主桁拼接!$D$4:$D$574,D$3,主桁拼接!$G$4:$G$574,$B25),SUMIFS(主桁拼接!$J$4:$J$574,主桁拼接!$D$4:$D$574,E$3,主桁拼接!$G$4:$G$574,$B25)) -> 18017.898 | H25: =G25-F25 -> -1550.2022
B26: 40 | C26: kg | E26: 33604.5 | F26: =N(D26)+N(E26) -> 33604.5 | G26: =SUM(SUMIFS(主桁拼接!$J$4:$J$574,主桁拼接!$D$4:$D$574,D$3,主桁拼接!$G$4:$G$574,$B26),SUMIFS(主桁拼接!$J$4:$J$574,主桁拼接!$D$4:$D$574,E$3,主桁拼接!$G$4:$G$574,$B26)) -> 33115.696 | H26: =G26-F26 -> -488.804
B27: 44 | C27: kg | D27: 10730.2 | E27: 10164.6 | F27: =N(D27)+N(E27) -> 20894.8 | G27: =SUM(SUMIFS(主桁拼接!$J$4:$J$574,主桁拼接!$D$4:$D$574,D$3,主桁拼接!$G$4:$G$574,$B27),SUMIFS(主桁拼接!$J$4:$J$574,主桁拼接!$D$4:$D$574,E$3,主桁拼接!$G$4:$G$574,$B27)) -> 19283.544 | H27: =G27-F27 -> -1611.2562
B28: 48 | C28: kg | E28: 1633.4 | F28: =N(D28)+N(E28) -> 1633.4 | G28: =SUM(SUMIFS(主桁拼接!$J$4:$J$574,主桁拼接!$D$4:$D$574,D$3,主桁拼接!$G$4:$G$574,$B28),SUMIFS(主桁拼接!$J$4:$J$574,主桁拼接!$D$4:$D$574,E$3,主桁拼接!$G$4:$G$574,$B28)) -> 2176.3968 | H28: =G28-F28 -> 542.9968
A29: 上层桥面系 | B29: 10 | C29: kg | D29: 40128 | F29: =N(D29)+N(E29) -> 40128 | G29: =SUMIFS(桥面系!$J$4:$J$63,桥面系!$A$4:$A$63,"上层桥面系",桥面系!$G$4:$G$63,$B29) -> 40128 | H29: =G29-F29 -> 0
B30: 12 | C30: kg | D30: 191453 | F30: =N(D30)+N(E30) -> 191453 | G30: =SUMIFS(桥面系!$J$4:$J$63,桥面系!$A$4:$A$63,"上层桥面系",桥面系!$G$4:$G$63,$B30) -> 191453 | H30: =G30-F30 -> 0
B31: 14 | C31: kg | D31: 789637.2 | F31: =N(D31)+N(E31) -> 789637.2 | G31: =SUMIFS(桥面系!$J$4:$J$63,桥面系!$A$4:$A$63,"上层桥面系",桥面系!$G$4:$G$63,$B31) -> 789637.2 | H31: =G31-F31 -> 0
B32: 16 | C32: kg | D32: 1867.2 | F32: =N(D32)+N(E32) -> 1867.2 | G32: =SUMIFS(桥面系!$J$4:$J$63,桥面系!$A$4:$A$63,"上层桥面系",桥面系!$G$4:$G$63,$B32) -> 1867.2 | H32: =G32-F32 -> 0
B33: 20 | C33: kg | D33: 431122 | F33: =N(D33)+N(E33) -> 431122 | G33: =SUMIFS(桥面系!$J$4:$J$63,桥面系!$A$4:$A$63,"上层桥面系",桥面系!$G$4:$G$63,$B33) -> 431122 | H33: =G33-F33 -> 0
B34: 24 | C34: kg | D34: 545983.2 | F34: =N(D34)+N(E34) -> 545983.2 | G34: =SUMIFS(桥面系!$J$4:$J$63,桥面系!$A$4:$A$63,"上层桥面系",桥面系!$G$4:$G$63,$B34) -> 545983.2 | H34: =G34-F34 -> 0
A35: 下层桥面系 | B35: 4 | C35: kg | D35: 3898.8 | F35: =N(D35)+N(E35) -> 3898.8 | G35: =SUMIFS(桥面系!$J$4:$J$63,桥面系!$A$4:$A$63,"下层桥面系",桥面系!$G$4:$G$63,$B35) -> 3898.8 | H35: =G35-F35 -> 0
B36: 6 | C36: kg | D36: 3898.8 | F36: =N(D36)+N(E36) -> 3898.8 | G36: =SUMIFS(桥面系!$J$4:$J$63,桥面系!$A$4:$A$63,"下层桥面系",桥面系!$G$4:$G$63,$B36) -> 3898.8 | H36: =G36-F36 -> 0
B37: 8 | C37: kg | D37: 823554 | F37: =N(D37)+N(E37) -> 823554 | G37: =SUMIFS(桥面系!$J$4:$J$63,桥面系!$A$4:$A$63,"下层桥面系",桥面系!$G$4:$G$63,$B37) -> 823554 | H37: =G37-F37 -> 0
B38: 10 | C38: kg | D38: 35164.8 | F38: =N(D38)+N(E38) -> 35164.8 | G38: =SUMIFS(桥面系!$J$4:$J$63,桥面系!$A$4:$A$63,"下层桥面系",桥面系!$G$4:$G$63,$B38) -> 35164.8 | H38: =G38-F38 -> 0
B39: 12 | C39: kg | D39: 102008 | F39: =N(D39)+N(E39) -> 102008 | G39: =SUMIFS(桥面系!$J$4:$J$63,桥面系!$A$4:$A$63,"下层桥面系",桥面系!$G$4:$G$63,$B39) -> 102008 | H39: =G39-F39 -> 0
B40: 14 | C40: kg | D40: 2052399 | F40: =N(D40)+N(E40) -> 2052399 | G40: =SUMIFS(桥面系!$J$4:$J$63,桥面系!$A$4:$A$63,"下层桥面系",桥面系!$G$4:$G$63,$B40) -> 2052399 | H40: =G40-F40 -> 0
...

Sheet 主梁数量
A1: 主梁数量 板件计算表（新沙高架桥 K6+418.3 主桥上构）
A2: 节段 | B2: 板件名称 | C2: 编号 | D2: 材质 | E2: 长(mm) | F2: 宽(mm) | G2: 厚(mm) | H2: 单件重(kg) | I2: 数量 | J2: 合计重量(kg) | K2: 备注
E3: mm | F3: mm | G3: mm | H3: kg | I3: 件 | J3: kg
A4: 中桁01 | B4: 中桁01节段 | D4: Q355D | E4: 750 | F4: 320 | G4: 28 | H4: =(E4/1000)*(F4/1000)*(G4/1000)*7850 -> 52.752 | I4: 1 | J4: =H4*I4 -> 52.752
A5: 中桁01 | B5: 中桁01节段 | D5: Q355D | E5: 2100 | F5: 320 | G5: 32 | H5: =(E5/1000)*(F5/1000)*(G5/1000)*7850 -> 168.8064 | I5: 1 | J5: =H5*I5 -> 168.8064
A6: 中桁03 | B6: 中桁03节段 | C6: N11a | D6: Q355D | E6: 15650 | F6: 1000 | G6: 20 | H6: =(E6/1000)*(F6/1000)*(G6/1000)*7850 -> 2457.05 | I6: 1 | J6: =H6*I6 -> 2457.05
A7: 中桁03 | B7: 中桁03节段 | C7: N11b | D7: Q355D | E7: 20050 | F7: 1000 | G7: 20 | H7: =(E7/1000)*(F7/1000)*(G7/1000)*7850 -> 3147.85 | I7: 1 | J7: =H7*I7 -> 3147.85
A8: 中桁03 | B8: 中桁03节段 | C8: N12a | D8: Q355D | E8: 7902 | F8: 1200 | G8: 20 | H8: =(E8/1000)*(F8/1000)*(G8/1000)*7850 -> 1488.7368 | I8: 1 | J8: =H8*I8 -> 1488.7368
A9: 中桁03 | B9: 中桁03节段 | C9: N12b | D9: Q355D | E9: 10151 | F9: 1200 | G9: 20 | H9: =(E9/1000)*(F9/1000)*(G9/1000)*7850 -> 1912.4484 | I9: 1 | J9: =H9*I9 -> 1912.4484
A10: 中桁03 | B10: 中桁03节段 | C10: N13 | D10: Q355D | E10: 22290 | F10: 1000 | G10: 40 | H10: =(E10/1000)*(F10/1000)*(G10/1000)*7850 -> 6999.06 | I10: 2 | J10: =H10*I10 -> 13998.12
A11: 中桁03 | B11: 中桁03节段 | C11: N14 | D11: Q355D | E11: 10351 | F11: 2048 | G11: 20 | H11: =(E11/1000)*(F11/1000)*(G11/1000)*7850 -> 3328.2191 | I11: 2 | J11: =H11*I11 -> 6656.4383
A12: 中桁03 | B12: 中桁03节段 | C12: N16a | D12: Q355D | E12: 7902 | F12: 240 | G12: 20 | H12: =(E12/1000)*(F12/1000)*(G12/1000)*7850 -> 297.74736 | I12: 6 | J12: =H12*I12 -> 1786.4842
A13: 中桁03 | B13: 中桁03节段 | C13: N21a | D13: Q355D | E13: 7902 | F13: 2500 | G13: 24 | H13: =(E13/1000)*(F13/1000)*(G13/1000)*7850 -> 3721.842 | I13: 1 | J13: =H13*I13 -> 3721.842
A14: 中桁03 | B14: 中桁03节段 | C14: N22a | D14: Q355D | E14: 12960 | F14: 1000 | G14: 24 | H14: =(E14/1000)*(F14/1000)*(G14/1000)*7850 -> 2441.664 | I14: 1 | J14: =H14*I14 -> 2441.664
A15: 中桁03 | B15: 中桁03节段 | C15: N22b | D15: Q355D | E15: 15960 | F15: 1000 | G15: 24 | H15: =(E15/1000)*(F15/1000)*(G15/1000)*7850 -> 3006.864 | I15: 1 | J15: =H15*I15 -> 3006.864
A16: 中桁03 | B16: 中桁03节段 | C16: N22b | D16: Q355D | E16: 21840 | F16: 1000 | G16: 40 | H16: =(E16/1000)*(F16/1000)*(G16/1000)*7850 -> 6857.76 | I16: 2 | J16: =H16*I16 -> 13715.52
A17: 中桁03 | B17: 中桁03节段 | C17: N24 | D17: Q355D | E17: 10305 | F17: 1880 | G17: 24 | H17: =(E17/1000)*(F17/1000)*(G17/1000)*7850 -> 3649.9486 | I17: 2 | J17: =H17*I17 -> 7299.8971
... A342: 中桁14 | B342: 中桁14节段 | C342: N26b | D342: Q355D | E342: 7101 | F342: 280 | G342: 24 | H342: =(E342/1000)*(F342/1000)*(G342/1000)*7850 -> 374.59195 | I342: 4 | J342: =H342*I342 -> 1498.3678
A343: 中桁14 | B343: 中桁14节段 | D343: Q355D | E343: 15002 | F343: 170 | G343: 14 | H343: =(E343/1000)*(F343/1000)*(G343/1000)*7850 -> 280.28237 | I343: 2 | J343: =H343*I343 -> 560.56473
A344: 中桁14 | B344: 中桁14节段 | C344: N32 | D344: Q355D | E344: 11958 | F344: 1200 | G344: 32 | H344: =(E344/1000)*(F344/1000)*(G344/1000)*7850 -> 3604.6195 | I344: 1 | J344: =H344*I344 -> 3604.6195
A345: 中桁14 | B345: 中桁14节段 | C345: N33 | D345: Q355D | E345: 10558 | F345: 240 | G345: 24 | H345: =(E345/1000)*(F345/1000)*(G345/1000)*7850 -> 477.39053 | I345: 2 | J345: =H345*I345 -> 954.78106
A346: 中桁14 | B346: 中桁14节段 | C346: N41 | D346: Q355D | E346: 5482 | F346: 1200 | G346: 36 | H346: =(E346/1000)*(F346/1000)*(G346/1000)*7850 -> 1859.0558 | I346: 1 | J346: =H346*I346 -> 1859.0558
A347: 中桁14 | B347: 中桁14节段 | C347: N41a | D347: Q355D | E347: 5782 | F347: 1200 | G347: 36 | H347: =(E347/1000)*(F347/1000)*(G347/1000)*7850 -> 1960.7918 | I347: 1 | J347: =H347*I347 -> 1960.7918
A348: 中桁14 | B348: 中桁14节段 | C348: N43 | D348: Q355D | E348: 3682 | F348: 320 | G348: 32 | H348: =(E348/1000)*(F348/1000)*(G348/1000)*7850 -> 295.97389 | I348: 2 | J348: =H348*I348 -> 591.94778
A349: 中桁14 | B349: 中桁14节段 | C349: N43a | D349: Q355D | E349: 4782 | F349: 320 | G349: 32 | H349: =(E349/1000)*(F349/1000)*(G349/1000)*7850 -> 384.39629 | I349: 1 | J349: =H349*I349 -> 384.39629
A350: 中桁14 | B350: 中桁14节段 | C350: N43b | D350: Q355D | E350: 5082 | F350: 320 | G350: 32 | H350: =(E350/1000)*(F350/1000)*(G350/1000)*7850 -> 408.51149 | I350: 1 | J350: =H350*I350 -> 408.51149
A351: 中桁14 | B351: 中桁14节段 | C351: N51 | D351: Q355D | E351: 3714 | F351: 900 | G351: 36 | H351: =(E351/1000)*(F351/1000)*(G351/1000)*7850 -> 944.61876 | I351: 2 | J351: =H351*I351 -> 1889.2375
A352: 中桁14 | B352: 中桁14节段 | C352: N52 | D352: Q355D | E352: 5914 | F352: 1200 | G352: 32 | H352: =(E352/1000)*(F352/1000)*(G352/1000)*7850 -> 1782.7162 | I352: 1 | J352: =H352*I352 -> 1782.7162
A353: 中桁14 | B353: 中桁14节段 | C353: N53 | D353: Q355D | E353: 4514 | F353: 240 | G353: 24 | H353: =(E353/1000)*(F353/1000)*(G353/1000)*7850 -> 204.10502 | I353: 2 | J353: =H353*I353 -> 408.21005
A354: 中桁14 | B354: 中桁14节段 | C354: N54 | D354: Q355D | E354: 2300 | F354: 320 | G354: 32 | H354: =(E354/1000)*(F354/1000)*(G354/1000)*7850 -> 184.8832 | I354: 2 | J354: =H354*I354 -> 369.7664
A355: 中桁14 | B355: 中桁14节段 | C355: N55 | D355: Q355D | E355: 1200 | F355: 980 | G355: 20 | H355: =(E355/1000)*(F355/1000)*(G355/1000)*7850 -> 184.632 | I355: 1 | J355: =H355*I355 -> 184.632
... A646: 边桁01 | B646: 边桁01节段 | C646: N26b | D646: Q355D | E646: 10105 | F646: 240 | G646: 20 | H646: =(E646/1000)*(F646/1000)*(G646/1000)*7850 -> 380.7564 | I646: 2 | J646: =H646*I646 -> 761.5128
A647: 边桁01 | B647: 边桁01节段 | D647: Q355D | E647: 12897 | F647: 240 | G647: 20 | H647: =(E647/1000)*(F647/1000)*(G647/1000)*7850 -> 485.95896 | I647: 1 | J647: =H647*I647 -> 485.95896
A648: 边桁01 | B648: 边桁01节段 | C648: N26d | D648: Q355D | E648: 10105 | F648: 240 | G648: 20 | H648: =(E648/1000)*(F648/1000)*(G648/1000)*7850 -> 380.7564 | I648: 1 | J648: =H648*I648 -> 380.7564
A649: 边桁01 | B649: 边桁01节段 | C649: N26d | D649: Q355D | E649: 2792 | F649: 320 | G649: 32 | H649: =(E649/1000)*(F649/1000)*(G649/1000)*7850 -> 224.43213 | I649: 1 | J649: =H649*I649 -> 224.43213
A650: 边桁01 | B650: 边桁01节段 | C650: N26d | D650: Q355D | E650: 12897 | F650: 170 | G650: 14 | H650: =(E650/1000)*(F650/1000)*(G650/1000)*7850 -> 240.95465 | I650: 1 | J650: =H650*I650 -> 240.95465
A651: 边桁01 | B651: 边桁01节段 | C651: N26d | D651: Q355D | E651: 14038 | F651: 1200 | G651: 36 | H651: =(E651/1000)*(F651/1000)*(G651/1000)*7850 -> 4760.5666 | I651: 1 | J651: =H651*I651 -> 4760.5666
A652: 边桁01 | B652: 边桁01节段 | C652: N26d | D652: Q355D | E652: 14338 | F652: 1200 | G652: 36 | H652: =(E652/1000)*(F652/1000)*(G652/1000)*7850 -> 4862.3026 | I652: 1 | J652: =H652*I652 -> 4862.3026
A653: 边桁01 | B653: 边桁01节段 | C653: N26d | D653: Q355D | E653: 9838 | F653: 1360 | G653: 36 | H653: =(E653/1000)*(F653/1000)*(G653/1000)*7850 -> 3781.0976 | I653: 2 | J653: =H653*I653 -> 7562.1951
A654: 边桁01 | B654: 边桁01节段 | C654: N26d | D654: Q355D | E654: 9838 | F654: 320 | G654: 32 | H654: =(E654/1000)*(F654/1000)*(G654/1000)*7850 -> 790.81779 | I654: 2 | J654: =H654*I654 -> 1581.6356
...

Sheet 横隔板
A1: 横隔板 板件计算表（新沙高架桥 K6+418.3 主桥上构）
A2: 节段 | B2: 板件名称 | C2: 编号 | D2: 材质 | E2: 长(mm) | F2: 宽(mm) | G2: 厚(mm) | H2: 单件重(kg) | I2: 数量 | J2: 合计重量(kg) | K2: 备注
E3: mm | F3: mm | G3: mm | H3: kg | I3: 件 | J3: kg
A4: 中桁03 | B4: 中桁03节段 | C4: N15 | D4: Q355D | E4: 1980 | F4: 1200 | G4: 16 | H4: =(E4/1000)*(F4/1000)*(G4/1000)*7850 -> 298.4256 | I4: 3 | J4: =H4*I4 -> 895.2768
A5: 中桁03 | B5: 中桁03节段 | C5: N15a | D5: Q355D | E5: 1980 | F5: 1200 | G5: 16 | H5: =(E5/1000)*(F5/1000)*(G5/1000)*7850 -> 298.4256 | I5: 3 | J5: =H5*I5 -> 895.2768
A6: 中桁03 | B6: 中桁03节段 | C6: N15' | D6: Q355D | E6: 2057 | F6: 200 | G6: 16 | H6: =(E6/1000)*(F6/1000)*(G6/1000)*7850 -> 51.67184 | I6: 4 | J6: =H6*I6 -> 206.68736
A7: 中桁03 | B7: 中桁03节段 | C7: N15b | D7: Q355B | E7: 2057 | F7: 40 | G7: 4 | H7: =(E7/1000)*(F7/1000)*(G7/1000)*7850 -> 2.583592 | I7: 4 | J7: =H7*I7 -> 10.334368
A8: 中桁03 | B8: 中桁03节段 | C8: N25 | D8: Q355D | E8: 1800 | F8: 1200 | G8: 16 | H8: =(E8/1000)*(F8/1000)*(G8/1000)*7850 -> 271.296 | I8: 3 | J8: =H8*I8 -> 813.888
A9: 中桁03 | B9: 中桁03节段 | C9: N25a | D9: Q355D | E9: 1800 | F9: 1200 | G9: 16 | H9: =(E9/1000)*(F9/1000)*(G9/1000)*7850 -> 271.296 | I9: 3 | J9: =H9*I9 -> 813.888
A10: 中桁03 | B10: 中桁03节段 | C10: N61 | D10: Q355D | E10: 1980 | F10: 610 | G10: 14 | H10: =(E10/1000)*(F10/1000)*(G10/1000)*7850 -> 132.73722 | I10: 6 | J10: =H10*I10 -> 796.42332
A11: 中桁03 | B11: 中桁03节段 | C11: N61a | D11: Q355D | E11: 1980 | F11: 630 | G11: 14 | H11: =(E11/1000)*(F11/1000)*(G11/1000)*7850 -> 137.08926 | I11: 6 | J11: =H11*I11 -> 822.53556
A12: 中桁03 | B12: 中桁03节段 | C12: N62 | D12: Q355D | E12: 470 | F12: 1000 | G12: 24 | H12: =(E12/1000)*(F12/1000)*(G12/1000)*7850 -> 88.548 | I12: 6 | J12: =H12*I12 -> 531.288
A13: 中桁03 | B13: 中桁03节段 | C13: N62a | D13: Q355D | E13: 480 | F13: 1000 | G13: 24 | H13: =(E13/1000)*(F13/1000)*(G13/1000)*7850 -> 90.432 | I13: 6 | J13: =H13*I13 -> 542.592
A14: 中桁03 | B14: 中桁03节段 | C14: N63 | D14: Q355D | E14: 1800 | F14: 610 | G14: 14 | H14: =(E14/1000)*(F14/1000)*(G14/1000)*7850 -> 120.6702 | I14: 6 | J14: =H14*I14 -> 724.0212
A15: 中桁03 | B15: 中桁03节段 | C15: N63 | D15: Q355D | E15: 1800 | F15: 626 | G15: 14 | H15: =(E15/1000)*(F15/1000)*(G15/1000)*7850 -> 123.83532 | I15: 6 | J15: =H15*I15 -> 743.01192
... A489: 边桁22 | B489: 边桁22节段 | C489: N25 | D489: Q355D | E489: 1450 | F489: 1200 | G489: 16 | H489: =(E489/1000)*(F489/1000)*(G489/1000)*7850 -> 218.544 | I489: 6 | J489: =H489*I489 -> 1311.264
A491: 按板厚汇总（kg）
A492: 材质 | B492: 4 | C492: 6 | D492: 8 | E492: 10 | F492: 12 | G492: 14 | H492: 16 | I492: 20 | J492: 24 | K492: 28 | L492: 32 | M492: 36 | N492: 40 | O492: 44 | P492: 48 | Q492: 50 | R492: 60 | S492: 80 | T492: 100 | U492: 合计
A493: Q355B | B493: =SUMIFS($J$4:$J$489,$D$4:$D$489,$A493,$G$4:$G$489,B$492) -> 186.0136 | C493: =SUMIFS($J$4:$J$489,$D$4:$D$489,$A493,$G$4:$G$489,C$492) -> 0 | D493: =SUMIFS($J$4:$J$489,$D$4:$D$489,$A493,$G$4:$G$489,D$492) -> 0 | E493: =SUMIFS($J$4:$J$489,$D$4:$D$489,$A493,$G$4:$G$489,E$492) -> 0 | F493: =SUMIFS($J$4:$J$489,$D$4:$D$489,$A493,$G$4:$G$489,F$492) -> 0 | G493: =SUMIFS($J$4:$J$489,$D$4:$D$489,$A493,$G$4:$G$489,G$492) -> 0 | H493: =SUMIFS($J$4:$J$489,$D$4:$D$489,$A493,$G$4:$G$489,H$492) -> 0 | I493: =SUMIFS($J$4:$J$489,$D$4:$D$489,$A493,$G$4:$G$489,I$492) -> 0 | ... T493: =SUMIFS($J$4:$J$489,$D$4:$D$489,$A493,$G$4:$G$489,T$492) -> 0 | U493: =SUM(B493:T493) -> 186.0136
A494: Q355D | B494: =SUMIFS($J$4:$J$489,$D$4:$D$489,$A494,$G$4:$G$489,B$492) -> 139.45745 | C494: =SUMIFS($J$4:$J$489,$D$4:$D$489,$A494,$G$4:$G$489,C$492) -> 0 | D494: =SUMIFS($J$4:$J$489,$D$4:$D$489,$A494,$G$4:$G$489,D$492) -> 0 | E494: =SUMIFS($J$4:$J$489,$D$4:$D$489,$A494,$G$4:$G$489,E$492) -> 0 | F494: =SUMIFS($J$4:$J$489,$D$4:$D$489,$A494,$G$4:$G$489,F$492) -> 0 | G494: =SUMIFS($J$4:$J$489,$D$4:$D$489,$A494,$G$4:$G$489,G$492) -> 33817.769 | H494: =SUMIFS($J$4:$J$489,$D$4:$D$489,$A494,$G$4:$G$489,H$492) -> 86408.957 | I494: =SUMIFS($J$4:$J$489,$D$4:$D$489,$A494,$G$4:$G$489,I$492) -> 78136.994 | ... T494: =SUMIFS($J$4:$J$489,$D$4:$D$489,$A494,$G$4:$G$489,T$492) -> 0 | U494: =SUM(B494:T494) -> 339966.88
A495: Q420D | B495: =SUMIFS($J$4:$J$489,$D$4:$D$489,$A495,$G$4:$G$489,B$492) -> 26.858304 | C495: =SUMIFS($J$4:$J$489,$D$4:$D$489,$A495,$G$4:$G$489,C$492) -> 0 | D495: =SUMIFS($J$4:$J$489,$D$4:$D$489,$A495,$G$4:$G$489,D$492) -> 0 | E495: =SUMIFS($J$4:$J$489,$D$4:$D$489,$A495,$G$4:$G$489,E$492) -> 0 | F495: =SUMIFS($J$4:$J$489,$D$4:$D$489,$A495,$G$4:$G$489,F$492) -> 0 | G495: =SUMIFS($J$4:$J$489,$D$4:$D$489,$A495,$G$4:$G$489,G$492) -> 560.49 | H495: =SUMIFS($J$4:$J$489,$D$4:$D$489,$A495,$G$4:$G$489,H$492) -> 17290.925 | I495: =SUMIFS($J$4:$J$489,$D$4:$D$489,$A495,$G$4:$G$489,I$492) -> 0 | ... T495: =SUMIFS($J$4:$J$489,$D$4:$D$489,$A495,$G$4:$G$489,T$492) -> 5824.7 | U495: =SUM(B495:T495) -> 164259.68
A496: 合计 | B496: =SUM(B493:B495) -> 352.32935 | C496: =SUM(C493:C495) -> 0 | D496: =SUM(D493:D495) -> 0 | E496: =SUM(E493:E495) -> 0 | F496: =SUM(F493:F495) -> 0 | G496: =SUM(G493:G495) -> 34378.259 | H496: =SUM(H493:H495) -> 103699.88 | I496: =SUM(I493:I495) -> 78136.994 | ... U496: =SUM(U493:U495) -> 504412.57

Sheet 主桁拼接
A1: 主桁拼接 板件计算表（新沙高架桥 K6+418.3 主桥上构）
A2: 节段 | B2: 板件名称 | C2: 编号 | D2: 材质 | E2: 长(mm) | F2: 宽(mm) | G2: 厚(mm) | H2: 单件重(kg) | I2: 数量 | J2: 合计重量(kg) | K2: 备注
E3: mm | F3: mm | G3: mm | H3: kg | I3: 件 | J3: kg
A4: 拼接-中桁03 | B4: 下弦杆拼接 | C4: K1 | D4: Q355D | E4: 1700 | F4: 820 | G4: 20 | H4: =(E4/1000)*(F4/1000)*(G4/1000)*7850 -> 218.858 | I4: 2 | J4: =H4*I4 -> 437.716
A5: 拼接-中桁03 | B5: 下弦杆拼接 | C5: K2 | D5: Q355D | E5: 820 | F5: 800 | G5: 20 | H5: =(E5/1000)*(F5/1000)*(G5/1000)*7850 -> 102.992 | I5: 4 | J5: =H5*I5 -> 411.968
A6: 拼接-中桁03 | B6: 下弦杆拼接 | C6: K3 | D6: Q355D | E6: 1120 | F6: 1100 | G6: 32 | H6: =(E6/1000)*(F6/1000)*(G6/1000)*7850 -> 309.4784 | I6: 1 | J6: =H6*I6 -> 309.4784
A7: 拼接-中桁03 | B7: 下弦杆拼接 | C7: K4 | D7: Q355D | E7: 1120 | F7: 400 | G7: 32 | H7: =(E7/1000)*(F7/1000)*(G7/1000)*7850 -> 112.5376 | I7: 2 | J7: =H7*I7 -> 225.0752
A8: 拼接-中桁03 | B8: 下弦杆拼接 | C8: K5 | D8: Q355D | E8: 920 | F8: 200 | G8: 20 | H8: =(E8/1000)*(F8/1000)*(G8/1000)*7850 -> 28.888 | I8: 6 | J8: =H8*I8 -> 173.328
A9: 拼接-中桁03 | B9: 下弦杆拼接 | C9: K6 | D9: Q355D | E9: 1700 | F9: 400 | G9: 20 | H9: =(E9/1000)*(F9/1000)*(G9/1000)*7850 -> 106.76 | I9: 2 | J9: =H9*I9 -> 213.52
A10: 拼接-中桁03 | B10: 腹杆拼接 | C10: L1 | D10: Q355D | E10: 1520 | F10: 1100 | G10: 24 | H10: =(E10/1000)*(F10/1000)*(G10/1000)*7850 -> 315.0048 | I10: 2 | J10: =H10*I10 -> 630.0096
A11: 拼接-中桁03 | B11: 腹杆拼接 | C11: L2 | D11: Q355D | E11: 1520 | F11: 500 | G11: 24 | H11: =(E11/1000)*(F11/1000)*(G11/1000)*7850 -> 143.184 | I11: 4 | J11: =H11*I11 -> 572.736
A12: 拼接-中桁03 | B12: 腹杆拼接 | C12: L3 | D12: Q355D | E12: 1320 | F12: 1100 | G12: 28 | H12: =(E12/1000)*(F12/1000)*(G12/1000)*7850 -> 319.1496 | I12: 1 | J12: =H12*I12 -> 319.1496
A13: 拼接-中桁03 | B13: 腹杆拼接 | C13: L4 | D13: Q355D | E13: 1320 | F13: 500 | G13: 28 | H13: =(E13/1000)*(F13/1000)*(G13/1000)*7850 -> 145.068 | I13: 2 | J13: =H13*I13 -> 290.136
A14: 拼接-中桁03 | B14: 腹杆拼接 | C14: L5 | D14: Q355D | E14: 1520 | F14: 1100 | G14: 44 | H14: =(E14/1000)*(F14/1000)*(G14/1000)*7850 -> 577.5088 | I14: 1 | J14: =H14*I14 -> 577.5088
A15: 拼接-中桁03 | B15: 腹杆拼接 | C15: L6 | D15: Q355D | E15: 1520 | F15: 240 | G15: 44 | H15: =(E15/1000)*(F15/1000)*(G15/1000)*7850 -> 126.00192 | I15: 2 | J15: =H15*I15 -> 252.00384
... A574: 拼接-边桁22 | B574: 上弦杆拼接 | C574: P8 | D574: Q355D | E574: 1800 | F574: 500 | G574: 20 | H574: =(E574/1000)*(F574/1000)*(G574/1000)*7850 -> 141.3 | I574: 2 | J574: =H574*I574 -> 282.6
A576: 按板厚汇总（kg）
A577: 材质 | B577: 4 | C577: 6 | D577: 8 | E577: 10 | F577: 12 | G577: 14 | H577: 16 | I577: 20 | J577: 24 | K577: 28 | L577: 32 | M577: 36 | N577: 40 | O577: 44 | P577: 48 | Q577: 50 | R577: 60 | S577: 80 | T577: 100 | U577: 合计
A578: Q355B | B578: =SUMIFS($J$4:$J$574,$D$4:$D$574,$A578,$G$4:$G$574,B$577) -> 0 | C578: =SUMIFS($J$4:$J$574,$D$4:$D$574,$A578,$G$4:$G$574,C$577) -> 0 | D578: =SUMIFS($J$4:$J$574,$D$4:$D$574,$A578,$G$4:$G$574,D$577) -> 0 | E578: =SUMIFS($J$4:$J$574,$D$4:$D$574,$A578,$G$4:$G$574,E$577) -> 0 | F578: =SUMIFS($J$4:$J$574,$D$4:$D$574,$A578,$G$4:$G$574,F$577) -> 0 | G578: =SUMIFS($J$4:$J$574,$D$4:$D$574,$A578,$G$4:$G$574,G$577) -> 0 | H578: =SUMIFS($J$4:$J$574,$D$4:$D$574,$A578,$G$4:$G$574,H$577) -> 0 | I578: =SUMIFS($J$4:$J$574,$D$4:$D$574,$A578,$G$4:$G$574,I$577) -> 0 | ... T578: =SUMIFS($J$4:$J$574,$D$4:$D$574,$A578,$G$4:$G$574,T$577) -> 0 | U578: =SUM(B578:T578) -> 0
A579: Q355D | B579: =SUMIFS($J$4:$J$574,$D$4:$D$574,$A579,$G$4:$G$574,B$577) -> 395.012 | C579: =SUMIFS($J$4:$J$574,$D$4:$D$574,$A579,$G$4:$G$574,C$577) -> 0 | D579: =SUMIFS($J$4:$J$574,$D$4:$D$574,$A579,$G$4:$G$574,D$577) -> 1096.488 | E579: =SUMIFS($J$4:$J$574,$D$4:$D$574,$A579,$G$4:$G$574,E$577) -> 0 | F579: =SUMIFS($J$4:$J$574,$D$4:$D$574,$A579,$G$4:$G$574,F$577) -> 974.028 | G579: =SUMIFS($J$4:$J$574,$D$4:$D$574,$A579,$G$4:$G$574,G$577) -> 0 | H579: =SUMIFS($J$4:$J$574,$D$4:$D$574,$A579,$G$4:$G$574,H$577) -> 9817.1472 | I579: =SUMIFS($J$4:$J$574,$D$4:$D$574,$A579,$G$4:$G$574,I$577) -> 21618.9 | ... T579: =SUMIFS($J$4:$J$574,$D$4:$D$574,$A579,$G$4:$G$574,T$577) -> 0 | U579: =SUM(B579:T579) -> 218286.23
A580: Q420D | B580: =SUMIFS($J$4:$J$574,$D$4:$D$574,$A580,$G$4:$G$574,B$577) -> 0 | C580: =SUMIFS($J$4:$J$574,$D$4:$D$574,$A580,$G$4:$G$574,C$577) -> 0 | D580: =SUMIFS($J$4:$J$574,$D$4:$D$574,$A580,$G$4:$G$574,D$577) -> 0 | E580: =SUMIFS($J$4:$J$574,$D$4:$D$574,$A580,$G$4:$G$574,E$577) -> 0 | F580: =SUMIFS($J$4:$J$574,$D$4:$D$574,$A580,$G$4:$G$574,F$577) -> 0 | G580: =SUMIFS($J$4:$J$574,$D$4:$D$574,$A580,$G$4:$G$574,G$577) -> 0 | H580: =SUMIFS($J$4:$J$574,$D$4:$D$574,$A580,$G$4:$G$574,H$577) -> 0 | I580: =SUMIFS($J$4:$J$574,$D$4:$D$574,$A580,$G$4:$G$574,I$577) -> 0 | ... T580: =SUMIFS($J$4:$J$574,$D$4:$D$574,$A580,$G$4:$G$574,T$577) -> 0 | U580: =SUM(B580:T580) -> 0
A581: 合计 | B581: =SUM(B578:B580) -> 395.012 | C581: =SUM(C578:C580) -> 0 | D581: =SUM(D578:D580) -> 1096.488 | E581: =SUM(E578:E580) -> 0 | F581: =SUM(F578:F580) -> 974.028 | G581: =SUM(G578:G580) -> 0 | H581: =SUM(H578:H580) -> 9817.1472 | I581: =SUM(I578:I580) -> 21618.9 | ... U581: =SUM(U578:U580) -> 218286.23

Sheet 桥面系
A1: 桥面系 板件计算表（新沙高架桥 K6+418.3 主桥上构）
A2: 部位 | B2: 板件名称 | C2: 编号 | D2: 材质 | E2: 长(mm) | F2: 宽(mm) | G2: 厚(mm) | H2: 单件重(kg) | I2: 数量 | J2: 合计重量(kg) | K2: 备注
E3: mm | F3: mm | G3: mm | H3: kg | I3: 件 | J3: kg
A4: 上层桥面系 | B4: 横梁顶板 | C4: T1 | D4: Q355D | G4: 20 | H4: 1648.5 | I4: 228 | J4: =H4*I4 -> 375858 | K4: □17503×600×20
A5: 上层桥面系 | B5: 横梁腹板 | C5: T2 | D5: Q355D | G5: 14 | H5: 3408 | I5: 228 | J5: =H5*I5 -> 777024 | K5: □17500×1955×14
A6: 上层桥面系 | B6: 横梁底板 | C6: T3 | D6: Q355D | G6: 24 | H6: 2307.9 | I6: 228 | J6: =H6*I6 -> 526201.2 | K6: □17500×700×24
A7: 上层桥面系 | B7: 横梁加劲板 | C7: T4 | D7: Q355D | G7: 12 | H7: 19.8 | I7: 4560 | J7: =H7*I7 -> 90288 | K7: □1510×150×12
A8: 上层桥面系 | B8: 横梁加劲板 | C8: T4a | D8: Q355D | G8: 12 | H8: 31.1 | I8: 456 | J8: =H8*I8 -> 14181.6 | K8: □1632×293×12
A9: 上层桥面系 | B9: 小纵梁顶板 | C9: T5 | D9: Q355D | G9: 12 | H9: 134.7 | I9: 202 | J9: =H9*I9 -> 27209.4 | K9: □2380×600×12
A10: 上层桥面系 | B10: 小纵梁顶板 | C10: T5a | D10: Q355D | G10: 12 | H10: 123.4 | I10: 20 | J10: =H10*I10 -> 2468 | K10: □2180×600×12
A11: 上层桥面系 | B11: 小纵梁顶板 | C11: T5b | D11: Q355D | G11: 12 | H11: 106.4 | I11: 4 | J11: =H11*I11 -> 425.6 | K11: □1880×600×12
A12: 上层桥面系 | B12: 小纵梁顶板 | C12: T5c | D12: Q355D | G12: 12 | H12: 82.9 | I12: 4 | J12: =H12*I12 -> 331.6 | K12: □1472×600×12
A13: 上层桥面系 | B13: 小纵梁腹板 | C13: T6 | D13: Q355D | G13: 12 | H13: 112.1 | I13: 202 | J13: =H13*I13 -> 22644.2 | K13: □2380×500×12
A14: 上层桥面系 | B14: 小纵梁腹板 | C14: T6a | D14: Q355D | G14: 12 | H14: 102.7 | I14: 20 | J14: =H14*I14 -> 2054 | K14: □2180×500×12
A15: 上层桥面系 | B15: 小纵梁腹板 | C15: T6b | D15: Q355D | G15: 12 | H15: 88.5 | I15: 4 | J15: =H15*I15 -> 354 | K15: □1880×500×12
... A63: 下层桥面系 | B63: U肋连接内衬板 | C63: D70 | D63: Q355D | G63: 6 | H63: 1.9 | I63: 2052 | J63: =H63*I63 -> 3898.8 | K63: □697×60×6
A65: 按板厚汇总（kg）
A66: 材质 | B66: 4 | C66: 6 | D66: 8 | E66: 10 | F66: 12 | G66: 14 | H66: 16 | I66: 20 | J66: 24 | K66: 28 | L66: 32 | M66: 36 | N66: 40 | O66: 44 | P66: 48 | Q66: 50 | R66: 60 | S66: 80 | T66: 100 | U66: 合计
A67: Q355B | B67: =SUMIFS($J$4:$J$63,$D$4:$D$63,$A67,$G$4:$G$63,B$66) -> 0 | C67: =SUMIFS($J$4:$J$63,$D$4:$D$63,$A67,$G$4:$G$63,C$66) -> 0 | D67: =SUMIFS($J$4:$J$63,$D$4:$D$63,$A67,$G$4:$G$63,D$66) -> 0 | E67: =SUMIFS($J$4:$J$63,$D$4:$D$63,$A67,$G$4:$G$63,E$66) -> 0 | F67: =SUMIFS($J$4:$J$63,$D$4:$D$63,$A67,$G$4:$G$63,F$66) -> 0 | G67: =SUMIFS($J$4:$J$63,$D$4:$D$63,$A67,$G$4:$G$63,G$66) -> 0 | H67: =SUMIFS($J$4:$J$63,$D$4:$D$63,$A67,$G$4:$G$63,H$66) -> 0 | I67: =SUMIFS($J$4:$J$63,$D$4:$D$63,$A67,$G$4:$G$63,I$66) -> 0 | ... T67: =SUMIFS($J$4:$J$63,$D$4:$D$63,$A67,$G$4:$G$63,T$66) -> 0 | U67: =SUM(B67:T67) -> 0
A68: Q355D | B68: =SUMIFS($J$4:$J$63,$D$4:$D$63,$A68,$G$4:$G$63,B$66) -> 3898.8 | C68: =SUMIFS($J$4:$J$63,$D$4:$D$63,$A68,$G$4:$G$63,C$66) -> 3898.8 | D68: =SUMIFS($J$4:$J$63,$D$4:$D$63,$A68,$G$4:$G$63,D$66) -> 823554 | E68: =SUMIFS($J$4:$J$63,$D$4:$D$63,$A68,$G$4:$G$63,E$66) -> 75292.8 | F68: =SUMIFS($J$4:$J$63,$D$4:$D$63,$A68,$G$4:$G$63,F$66) -> 293461 | G68: =SUMIFS($J$4:$J$63,$D$4:$D$63,$A68,$G$4:$G$63,G$66) -> 2842036.2 | H68: =SUMIFS($J$4:$J$63,$D$4:$D$63,$A68,$G$4:$G$63,H$66) -> 6880.8 | I68: =SUMIFS($J$4:$J$63,$D$4:$D$63,$A68,$G$4:$G$63,I$66) -> 500591.6 | ... T68: =SUMIFS($J$4:$J$63,$D$4:$D$63,$A68,$G$4:$G$63,T$66) -> 0 | U68: =SUM(B68:T68) -> 5631169.2
A69: Q420D | B69: =SUMIFS($J$4:$J$63,$D$4:$D$63,$A69,$G$4:$G$63,B$66) -> 0 | C69: =SUMIFS($J$4:$J$63,$D$4:$D$63,$A69,$G$4:$G$63,C$66) -> 0 | D69: =SUMIFS($J$4:$J$63,$D$4:$D$63,$A69,$G$4:$G$63,D$66) -> 0 | E69: =SUMIFS($J$4:$J$63,$D$4:$D$63,$A69,$G$4:$G$63,E$66) -> 0 | F69: =SUMIFS($J$4:$J$63,$D$4:$D$63,$A69,$G$4:$G$63,F$66) -> 0 | G69: =SUMIFS($J$4:$J$63,$D$4:$D$63,$A69,$G$4:$G$63,G$66) -> 0 | H69: =SUMIFS($J$4:$J$63,$D$4:$D$63,$A69,$G$4:$G$63,H$66) -> 0 | I69: =SUMIFS($J$4:$J$63,$D$4:$D$63,$A69,$G$4:$G$63,I$66) -> 0 | ... T69: =SUMIFS($J$4:$J$63,$D$4:$D$63,$A69,$G$4:$G$63,T$66) -> 0 | U69: =SUM(B69:T69) -> 0
A70: 合计 | B70: =SUM(B67:B69) -> 3898.8 | C70: =SUM(C67:C69) -> 3898.8 | D70: =SUM(D67:D69) -> 823554 | E70: =SUM(E67:E69) -> 75292.8 | F70: =SUM(F67:F69) -> 293461 | G70: =SUM(G67:G69) -> 2842036.2 | H70: =SUM(H67:H69) -> 6880.8 | I70: =SUM(I67:I69) -> 500591.6 | ... U70: =SUM(U67:U69) -> 5631169.2

Sheet 梁底挡块
A1: 梁底挡块数量表
A2: 梁板编号 | B2: 板件名称 | C2: 位置 | D2: 材质 | E2: 长(mm) | F2: 宽(mm) | G2: 厚(mm) | H2: 数量 | I2: 单件重(kg) | J2: 全桥数量 | K2: 合计重量(kg)
A3: 本桥主桥上构为钢桁梁，主桁节点采用整体节点板连接，不设混凝土梁底挡块，本表无内容。

Sheet 附属预埋件
A1: 附属工程预埋件数量表
A2: 梁板编号 | B2: 板件名称 | C2: 位置 | D2: 材质 | E2: 长(mm) | F2: 宽(mm) | G2: 厚(mm) | H2: 数量 | I2: 单件重(kg) | J2: 全桥数量 | K2: 合计重量(kg)
A3: 排水 | B3: 泄水管及管卡 | C3: 下层桥面系 | D3: Q355C | H3: 1 | I3: 780.6 | J3: 1 | K3: =I3*J3 -> 780.6
A4: 护栏 | B4: 防撞护栏预埋钢板 | C4: 上层桥面系 | D4: Q355C | H4: 1 | I4: 632 | J4: 1 | K4: =I4*J4 -> 632
A5: 护栏 | B5: 护栏底座预埋 | C5: 上层桥面系 | D5: Q355C | H5: 1 | I5: 782.3 | J5: 1 | K5: =I5*J5 -> 782.3
A6: 护栏 | B6: 人行道栏杆预埋 | C6: 上层桥面系 | D6: Q355C | H6: 1 | I6: 607.9 | J6: 1 | K6: =I6*J6 -> 607.9
A7: 检查车 | B7: 下弦检查车轨道预埋 | C7: 主桁下弦 | D7: Q355B | H7: 1 | I7: 65513.5 | J7: 1 | K7: =I7*J7 -> 65513.5
A8: 伸缩缝 | B8: 伸缩缝预埋钢筋 | C8: 上/下层桥面系 | D8: HRB400 | H8: 1 | I8: 95.1 | J8: 1 | K8: =I8*J8 -> 95.1
A9: 合计 | K9: =SUM(K3:K8) -> 68411.4
A11: 注：附属工程钢构件按《主桥上构工程数量表（二）》附属工程列录入，仅为预埋/附属钢件，不含混凝土、支座本体及涂装。
