Workbook

Sheet 合计数量
A2: 部位 | B2: 板厚 | C2: 单位 | D2: 图纸数量 | G2: 复核数量 | H2: 差异 | I2: 备注
D3: Q355 | E3: Q420 | F3: 合计
A4: 钢梁 | B4: 8 | C4: kg | D4: 1352.2 | E4: 0 | F4: =D4+E4 -> 1352.2 | G4: =主梁数量!N2195+横隔板!N38+附属预埋件!N10 -> 0 | H4: =G4-F4 -> -1352.2 | I4: 节段材料表无该厚度；来源应为拼接板(拼接数量汇总表)未提取→未完成
B5: 10 | C5: kg | D5: 40128 | E5: 0 | F5: =D5+E5 -> 40128 | G5: =主梁数量!O2195+横隔板!O38+附属预埋件!O10 -> 39919.699 | H5: =G5-F5 -> -208.3008 | I5: 节段材料表无该厚度；来源应为上层桥面系T60/T61(已计)与拼接板→部分未完成
B6: 12 | C6: kg | D6: 193459.1 | E6: 0 | F6: =D6+E6 -> 193459.1 | G6: =主梁数量!P2195+横隔板!P38+附属预埋件!P10 -> 191410.41 | H6: =G6-F6 -> -2048.6941 | I6: 节段材料表无该厚度；来源应为拼接板(拼接数量汇总表)未提取→未完成
B7: 14 | C7: kg | D7: 847139 | E7: 2518.5 | F7: =D7+E7 -> 849657.5 | G7: =主梁数量!Q2195+横隔板!Q38+附属预埋件!Q10 -> 907550.14 | H7: =G7-F7 -> 57892.635
B8: 16 | C8: kg | D8: 129234.4 | E8: 27946.9 | F8: =D8+E8 -> 157181.3 | G8: =主梁数量!R2195+横隔板!R38+附属预埋件!R10 -> 285658.71 | H8: =G8-F8 -> 128477.41
B9: 20 | C9: kg | D9: 879520.9 | E9: 0 | F9: =D9+E9 -> 879520.9 | G9: =主梁数量!S2195+横隔板!S38+附属预埋件!S10 -> 1273686.2 | H9: =G9-F9 -> 394165.31
B10: 24 | C10: kg | D10: 890863 | E10: 11198.7 | F10: =D10+E10 -> 902061.7 | G10: =主梁数量!T2195+横隔板!T38+附属预埋件!T10 -> 1143120 | H10: =G10-F10 -> 241058.29
B11: 28 | C11: kg | D11: 105369.4 | E11: 12062.2 | F11: =D11+E11 -> 117431.6 | G11: =主梁数量!U2195+横隔板!U38+附属预埋件!U10 -> 120224.45 | H11: =G11-F11 -> 2792.8456
B12: 32 | C12: kg | D12: 408675.6 | E12: 285997.4 | F12: =D12+E12 -> 694673 | G12: =主梁数量!V2195+横隔板!V38+附属预埋件!V10 -> 1317895.4 | H12: =G12-F12 -> 623222.37
B13: 36 | C13: kg | D13: 531775 | E13: 12270.3 | F13: =D13+E13 -> 544045.3 | G13: =主梁数量!W2195+横隔板!W38+附属预埋件!W10 -> 994751.17 | H13: =G13-F13 -> 450705.87
B14: 40 | C14: kg | D14: 497184.5 | E14: 341284.8 | F14: =D14+E14 -> 838469.3 | G14: =主梁数量!X2195+横隔板!X38+附属预埋件!X10 -> 1603068.5 | H14: =G14-F14 -> 764599.25
B15: 44 | C15: kg | D15: 150793.2 | E15: 256021.5 | F15: =D15+E15 -> 406814.7 | G15: =主梁数量!Y2195+横隔板!Y38+附属预埋件!Y10 -> 771857.73 | H15: =G15-F15 -> 365043.03
B16: 48 | C16: kg | D16: 33973.3 | E16: 249660.1 | F16: =D16+E16 -> 283633.4 | G16: =主梁数量!Z2195+横隔板!Z38+附属预埋件!Z10 -> 547061.53 | H16: =G16-F16 -> 263428.13
B17: 60 | C17: kg | D17: 0 | E17: 2458.8 | F17: =D17+E17 -> 2458.8 | G17: =主梁数量!AA2195+横隔板!AA38+附属预埋件!AA10 -> 4933.6308 | H17: =G17-F17 -> 2474.8308
B18: 80 | C18: kg | D18: 3052.1 | E18: 6989.7 | F18: =D18+E18 -> 10041.8 | G18: =主梁数量!AB2195+横隔板!AB38+附属预埋件!AB10 -> 20083.44 | H18: =G18-F18 -> 10041.64
B19: 100 | C19: kg | D19: 3815.1 | E19: 8737.1 | F19: =D19+E19 -> 12552.2 | G19: =主梁数量!AC2195+横隔板!AC38+附属预埋件!AC10 -> 25104.3 | H19: =G19-F19 -> 12552.1
B20: 焊缝 | C20: kg | D20: 68344.1 | E20: 16927.6 | F20: =D20+E20 -> 85271.7 | G20: =主梁数量!J2192+横隔板!K35 -> 140533.3 | H20: =G20-F20 -> 55261.6 | I20: 按1.5%计
A21: 其他钢板 | B21: — | C21: kg | D21: 66851 | F21: =D21+E21 -> 66851 | G21: =横隔板!K36+附属预埋件!K6 -> 66026.3 | H21: =G21-F21 -> -824.7 | I21: Q355B 66338.2 + Q355C 28.4 + Q235B 484.4
A22: 梁底挡块 | B22: — | C22: kg | F22: =D22+E22 -> 0 | H22: =G22-F22 -> 0 | I22: 上层图册无梁底挡块数量，待设计核实
A23: 钢梁制造合计 | C23: kg | D23: =SUM(D4:D21) -> 4851529.9 | E23: =SUM(E4:E21) -> 1234073.6 | F23: =SUM(F4:F21) -> 6085603.5 | G23: =SUM(G4:G21) -> 9452884.9 | H23: =G23-F23 -> 3367281.4
A24: 附属预埋 | B24: 护栏 | C24: kg | D24: 250569.2 | F24: =D24+E24 -> 250569.2 | G24: =附属预埋件!K4 -> 250569.2 | H24: =G24-F24 -> 0
B25: 路灯 | C25: kg | D25: 314 | F25: =D25+E25 -> 314 | G25: =附属预埋件!K5 -> 314 | H25: =G25-F25 -> 0

Sheet 主梁数量
A2: 梁板编号 | B2: 板件名称 | C2: 位置 | D2: 材质 | E2: 长 | F2: 宽 | G2: 厚 | H2: 单件重 | I2: 数量 | J2: 合计重量 | K2: 备注 | L2: 梁板编号 | M2: 面积A(m2)
E3: mm | F3: mm | G3: mm | H3: kg | J3: kg | N3: 8 | O3: 10 | P3: 12 | Q3: 14 | R3: 16 | S3: 20 | T3: 24 | U3: 28 | V3: 32 | W3: 36 | X3: 40 | Y3: 44 | Z3: 48 | AA3: 60 | AB3: 80 | AC3: 100 | AD3: 合计
A4: 中桁节段01(页48) | B4: 上弦顶板 | C4: N11 | D4: Q355D | G4: 20 | H4: =M4*(G4/1000)*7850 -> 4239 | I4: 1 | J4: =H4*I4 -> 4239 | K4: t=20mm,A=27m2；页48；按净面积计 | M4: 27
A5: 中桁节段01(页48) | B5: （同上） | C5: N71 | D5: Q355D | E5: 1980 | F5: 610 | G5: 16 | H5: =(E5/1000)*(F5/1000)*(G5/1000)*7850 -> 151.69968 | I5: 6 | J5: =H5*I5 -> 910.19808 | K5: 1980x610x16；页48
A6: 中桁节段01(页48) | B6: 上弦底板 | C6: N12 | D6: Q355D | E6: 13350 | F6: 1200 | G6: 20 | H6: =(E6/1000)*(F6/1000)*(G6/1000)*7850 -> 2515.14 | I6: 1 | J6: =H6*I6 -> 2515.14 | K6: 13350x1200×20；页48
A7: 中桁节段01(页48) | B7: （同上） | C7: N71* | D7: Q355D | E7: 1980 | F7: 650 | G7: 16 | H7: =(E7/1000)*(F7/1000)*(G7/1000)*7850 -> 161.6472 | I7: 2 | J7: =H7*I7 -> 323.2944 | K7: 1980x650x16；页48
A8: 中桁节段01(页48) | B8: （同上） | C8: N14 | D8: Q355D | G8: 28 | H8: =M8*(G8/1000)*7850 -> 2868.39 | I8: 2 | J8: =H8*I8 -> 5736.78 | K8: t=28mm,A=13.05m2；页48；按净面积计 | M8: 13.05
A9: 中桁节段01(页48) | B9: （同上） | C9: N71α | D9: Q355D | E9: 1980 | F9: 622 | G9: 16 | H9: =(E9/1000)*(F9/1000)*(G9/1000)*7850 -> 154.68394 | I9: 4 | J9: =H9*I9 -> 618.73574 | K9: 1980x622x16；页48
A10: 中桁节段01(页48) | B10: （同上） | C10: N14α | D10: Q355D | G10: 40 | H10: =M10*(G10/1000)*7850 -> 7850 | I10: 2 | J10: =H10*I10 -> 15700 | K10: t=40mm,A=25m2；页48；按净面积计 | M10: 25
A11: 中桁节段01(页48) | B11: （同上） | C11: N72 | D11: Q355D | G11: 24 | H11: =M11*(G11/1000)*7850 -> 88.548 | I11: 6 | J11: =H11*I11 -> 531.288 | K11: t=24mm,A=0.47m2；页48；按净面积计 | M11: 0.47
A12: 中桁节段01(页48) | B12: （同上） | C12: N15 | D12: Q355D | E12: 1980 | F12: 1200 | G12: 16 | H12: =(E12/1000)*(F12/1000)*(G12/1000)*7850 -> 298.4256 | I12: 6 | J12: =H12*I12 -> 1790.5536 | K12: 1980x1200x16；页48
A13: 中桁节段01(页48) | B13: （同上） | C13: N72' | D13: Q355D | G13: 24 | H13: =M13*(G13/1000)*7850 -> 90.432 | I13: 6 | J13: =H13*I13 -> 542.592 | K13: t=24mm,A=0.48m2；页48；按净面积计 | M13: 0.48
A14: 中桁节段01(页48) | B14: （同上） | C14: N15 “ | D14: Q355D | E14: 2057 | F14: 200 | G14: 16 | H14: =(E14/1000)*(F14/1000)*(G14/1000)*7850 -> 51.67184 | I14: 4 | J14: =H14*I14 -> 206.68736 | K14: 2057×200×16；页48
A15: 中桁节段01(页48) | B15: 横梁接头 | C15: N72a | D15: Q355D | G15: 24 | H15: =M15*(G15/1000)*7850 -> 182.748 | I15: 2 | J15: =H15*I15 -> 365.496 | K15: t=24mm,A=0.97m2；页48；按净面积计 | M15: 0.97
A16: 中桁节段01(页48) | B16: （同上） | C16: N72b | D16: Q355D | G16: 24 | H16: =M16*(G16/1000)*7850 -> 90.432 | I16: 2 | J16: =H16*I16 -> 180.864 | K16: t=24mm,A=0.48m2；页48；按净面积计 | M16: 0.48
A17: 中桁节段01(页48) | B17: （同上） | C17: N15c | D17: Q355D | E17: 800 | F17: 400 | G17: 16 | H17: =(E17/1000)*(F17/1000)*(G17/1000)*7850 -> 40.192 | I17: 4 | J17: =H17*I17 -> 160.768 | K17: 800×400×16；页48
A18: 中桁节段01(页48) | B18: （同上） | C18: N73 | D18: Q355D | E18: 1800 | F18: 626 | G18: 16 | H18: =(E18/1000)*(F18/1000)*(G18/1000)*7850 -> 141.52608 | I18: 8 | J18: =H18*I18 -> 1132.2086 | K18: 1800x626x16；页48
A19: 中桁节段01(页48) | B19: （同上） | C19: N16α | D19: Q355D | E19: 5651 | F19: 240 | G19: 20 | H19: =(E19/1000)*(F19/1000)*(G19/1000)*7850 -> 212.92968 | I19: 4 | J19: =H19*I19 -> 851.71872 | K19: 5651x240×20；页48
A20: 中桁节段01(页48) | B20: （同上） | C20: N730 | D20: Q355D | E20: 1800 | F20: 610 | G20: 28 | H20: =(E20/1000)*(F20/1000)*(G20/1000)*7850 -> 241.3404 | I20: 4 | J20: =H20*I20 -> 965.3616 | K20: 1800x610x28；页48
A21: 中桁节段01(页48) | B21: （同上） | C21: N16b | D21: Q355D | E21: 7700 | F21: 240 | G21: 20 | H21: =(E21/1000)*(F21/1000)*(G21/1000)*7850 -> 290.136 | I21: 4 | J21: =H21*I21 -> 1160.544 | K21: 7700×240×20；页48
A22: 中桁节段01(页48) | B22: （同上） | C22: N81 | D22: Q355D | E22: 1800 | F22: 1200 | G22: 32 | H22: =(E22/1000)*(F22/1000)*(G22/1000)*7850 -> 542.592 | I22: 4 | J22: =H22*I22 -> 2170.368 | K22: 1800x1200×32；页48
A23: 中桁节段01(页48) | B23: 上弦加劲助 | C23: N16c | D23: Q355D | E23: 7700 | F23: 240 | G23: 20 | H23: =(E23/1000)*(F23/1000)*(G23/1000)*7850 -> 290.136 | I23: 0 | J23: =H23*I23 -> 0 | K23: 7700×240×20；页48
A24: 中桁节段01(页48) | B24: （同上） | C24: N82 | D24: Q355D | E24: 502 | F24: 240 | G24: 20 | H24: =(E24/1000)*(F24/1000)*(G24/1000)*7850 -> 18.91536 | I24: 2 | J24: =H24*I24 -> 37.83072 | K24: 502×240x20；页48
A25: 中桁节段01(页48) | B25: （同上） | C25: N16d | D25: Q355D | E25: 13300 | F25: 240 | G25: 20 | H25: =(E25/1000)*(F25/1000)*(G25/1000)*7850 -> 501.144 | I25: 1 | J25: =H25*I25 -> 501.144 | K25: 13300×240×20；页48
A26: 中桁节段01(页48) | B26: 支承加劲肋 | C26: N83 | D26: Q355D | E26: 1800 | F26: 1800 | G26: 100 | H26: =(E26/1000)*(F26/1000)*(G26/1000)*7850 -> 2543.4 | I26: 1 | J26: =H26*I26 -> 2543.4 | K26: 1800×1800x100；页48
A27: 中桁节段01(页48) | B27: （同上） | C27: N16e | D27: Q355D | E27: 13300 | F27: 240 | G27: 20 | H27: =(E27/1000)*(F27/1000)*(G27/1000)*7850 -> 501.144 | I27: 1 | J27: =H27*I27 -> 501.144 | K27: 13300×240×20；页48
A28: 中桁节段01(页48) | B28: （同上） | C28: N84 | D28: Q355D | E28: 1000 | F28: 568 | G28: 32 | H28: =(E28/1000)*(F28/1000)*(G28/1000)*7850 -> 142.6816 | I28: 3 | J28: =H28*I28 -> 428.0448 | K28: 1000x568x32；页48
... A31: 中桁节段01(页48) | B31: （同上） | C31: N21α | D31: Q355D | E31: 10105 | F31: 2500 | G31: 20 | H31: =(E31/1000)*(F31/1000)*(G31/1000)*7850 -> 3966.2125 | I31: 1 | J31: =H31*I31 -> 3966.2125 | K31: 10105x2500x20；页48
A32: 中桁节段01(页48) | B32: （同上） | C32: N22 | D32: Q355D | G32: 36 | H32: =M32*(G32/1000)*7850 -> 2645.136 | I32: 1 | J32: =H32*I32 -> 2645.136 | K32: t=36mm,A=9.36m2；页48；按净面积计 | M32: 9.36
A33: 中桁节段01(页48) | B33: （同上） | C33: N22a | D33: Q355D | G33: 20 | H33: =M33*(G33/1000)*7850 -> 2461.76 | I33: 1 | J33: =H33*I33 -> 2461.76 | K33: t=20mm,A=15.68m2；页48；按净面积计 | M33: 15.68
A34: 中桁节段01(页48) | B34: 下弦腹板 | C34: N23 | D34: Q355D | E34: 10105 | F34: 1880 | G34: 24 | H34: =(E34/1000)*(F34/1000)*(G34/1000)*7850 -> 3579.1102 | I34: 2 | J34: =H34*I34 -> 7158.2203 | K34: 10105x1880x24；页48
A35: 中桁节段01(页48) | B35: 下弦节点板 | C35: N24 | D35: Q355D | G35: 40 | H35: =M35*(G35/1000)*7850 -> 5441.62 | I35: 2 | J35: =H35*I35 -> 10883.24 | K35: t=40mm,A=17.33m2；页48；按净面积计 | M35: 17.33
A36: 中桁节段01(页48) | B36: （同上） | C36: N25 | D36: Q355D | E36: 1800 | F36: 1200 | G36: 16 | H36: =(E36/1000)*(F36/1000)*(G36/1000)*7850 -> 271.296 | I36: 1 | J36: =H36*I36 -> 271.296 | K36: 1800x1200×16；页48
A37: 中桁节段01(页48) | B37: 下弦横隔板 | C37: N25 | D37: Q355D | E37: 2057 | F37: 200 | G37: 16 | H37: =(E37/1000)*(F37/1000)*(G37/1000)*7850 -> 51.67184 | I37: 3 | J37: =H37*I37 -> 155.01552 | K37: 2057×200x16；页48
A38: 中桁节段01(页48) | B38: （同上） | C38: N25α | D38: Q355D | E38: 1800 | F38: 1200 | G38: 16 | H38: =(E38/1000)*(F38/1000)*(G38/1000)*7850 -> 271.296 | I38: 3 | J38: =H38*I38 -> 813.888 | K38: 1800x1200x16；页48
A39: 中桁节段01(页48) | B39: （同上） | C39: N26a | D39: Q355D | E39: 2792 | F39: 240 | G39: 20 | H39: =(E39/1000)*(F39/1000)*(G39/1000)*7850 -> 105.20256 | I39: 2 | J39: =H39*I39 -> 210.40512 | K39: 2792x240×20；页48
A40: 中桁节段01(页48) | B40: （同上） | C40: N26b | D40: Q355D | E40: 10105 | F40: 240 | G40: 20 | H40: =(E40/1000)*(F40/1000)*(G40/1000)*7850 -> 380.7564 | I40: 2 | J40: =H40*I40 -> 761.5128 | K40: 10105x240x20；页48
A41: 中桁节段01(页48) | B41: （同上） | C41: N26c | D41: Q355D | E41: 12897 | F41: 240 | G41: 20 | H41: =(E41/1000)*(F41/1000)*(G41/1000)*7850 -> 485.95896 | I41: 1 | J41: =H41*I41 -> 485.95896 | K41: 12897×240×20；页48
A42: 中桁节段01(页48) | B42: （同上） | C42: N26d | D42: Q355D | E42: 10105 | F42: 240 | G42: 20 | H42: =(E42/1000)*(F42/1000)*(G42/1000)*7850 -> 380.7564 | I42: 1 | J42: =H42*I42 -> 380.7564 | K42: 10105x240x20；页48
A43: 中桁节段01(页48) | B43: （同上） | C43: N26d' | D43: Q355D | E43: 2792 | F43: 320 | G43: 32 | H43: =(E43/1000)*(F43/1000)*(G43/1000)*7850 -> 224.43213 | I43: 1 | J43: =H43*I43 -> 224.43213 | K43: 2792x320x32；页48
...

Sheet 横隔板
A2: 梁板编号 | B2: 板件名称 | C2: 位置 | D2: 材质 | E2: 长 | F2: 宽 | G2: 厚 | H2: 数量 | I2: 单件重 | J2: 全桥数量 | K2: 合计重量 | L2: 备注 | M2: 面积A(m2)
E3: mm | F3: mm | G3: mm | I3: kg | K3: kg | N3: 8 | O3: 10 | P3: 12 | Q3: 14 | R3: 16 | S3: 20 | T3: 24 | U3: 28 | V3: 32 | W3: 36 | X3: 40 | Y3: 44 | Z3: 48 | AA3: 60 | AB3: 80 | AC3: 100 | AD3: 合计
A4: 新沙高架桥 | B4: 横梁顶板 | C4: T1 | D4: Q355D | E4: 17503 | F4: 600 | G4: 20 | H4: 1 | I4: =IF(M4="",(E4/1000)*(F4/1000)*(G4/1000)*7850,M4*(G4/1000)*7850) -> 1648.7826 | J4: 228 | K4: =I4*J4 -> 375922.43
A5: 新沙高架桥 | B5: 横梁腹板 | C5: T2 | D5: Q355D | E5: 17500 | F5: 1955 | G5: 14 | H5: 1 | I5: =IF(M5="",(E5/1000)*(F5/1000)*(G5/1000)*7850,M5*(G5/1000)*7850) -> 3407.999 | J5: 228 | K5: =I5*J5 -> 777023.77 | L5: A=31.01 | M5: 31.01
A6: 新沙高架桥 | B6: 横梁底板 | C6: T3 | D6: Q355D | E6: 17500 | F6: 700 | G6: 24 | H6: 1 | I6: =IF(M6="",(E6/1000)*(F6/1000)*(G6/1000)*7850,M6*(G6/1000)*7850) -> 2307.9 | J6: 228 | K6: =I6*J6 -> 526201.2
A7: 新沙高架桥 | B7: 横梁加劲板 | C7: T4 | D7: Q355D | E7: 1510 | F7: 150 | G7: 12 | H7: 1 | I7: =IF(M7="",(E7/1000)*(F7/1000)*(G7/1000)*7850,M7*(G7/1000)*7850) -> 19.782 | J7: 4560 | K7: =I7*J7 -> 90205.92 | L7: A=0.21 | M7: 0.21
A8: 新沙高架桥 | B8: 横梁加劲板 | C8: T4a | D8: Q355D | E8: 1632 | F8: 293 | G8: 12 | H8: 1 | I8: =IF(M8="",(E8/1000)*(F8/1000)*(G8/1000)*7850,M8*(G8/1000)*7850) -> 31.086 | J8: 456 | K8: =I8*J8 -> 14175.216 | L8: A=0.33 | M8: 0.33
A9: 新沙高架桥 | B9: 小纵梁顶板 | C9: T5 | D9: Q355D | E9: 2380 | F9: 600 | G9: 12 | H9: 1 | I9: =IF(M9="",(E9/1000)*(F9/1000)*(G9/1000)*7850,M9*(G9/1000)*7850) -> 134.706 | J9: 202 | K9: =I9*J9 -> 27210.612 | L9: A=1.43 | M9: 1.43
A10: 新沙高架桥 | B10: 小纵梁顶板 | C10: T5a | D10: Q355D | E10: 2180 | F10: 600 | G10: 12 | H10: 1 | I10: =IF(M10="",(E10/1000)*(F10/1000)*(G10/1000)*7850,M10*(G10/1000)*7850) -> 123.402 | J10: 20 | K10: =I10*J10 -> 2468.04 | L10: A=1.31 | M10: 1.31
A11: 新沙高架桥 | B11: 小纵梁顶板 | C11: T5b | D11: Q355D | E11: 1880 | F11: 600 | G11: 12 | H11: 1 | I11: =IF(M11="",(E11/1000)*(F11/1000)*(G11/1000)*7850,M11*(G11/1000)*7850) -> 106.446 | J11: 4 | K11: =I11*J11 -> 425.784 | L11: A=1.13 | M11: 1.13
A12: 新沙高架桥 | B12: 小纵梁顶板 | C12: T5c | D12: Q355D | E12: 1472 | F12: 600 | G12: 12 | H12: 1 | I12: =IF(M12="",(E12/1000)*(F12/1000)*(G12/1000)*7850,M12*(G12/1000)*7850) -> 82.896 | J12: 4 | K12: =I12*J12 -> 331.584 | L12: A=0.88 | M12: 0.88
A13: 新沙高架桥 | B13: 小纵梁腹板 | C13: T6 | D13: Q355D | E13: 2380 | F13: 500 | G13: 12 | H13: 1 | I13: =IF(M13="",(E13/1000)*(F13/1000)*(G13/1000)*7850,M13*(G13/1000)*7850) -> 112.098 | J13: 202 | K13: =I13*J13 -> 22643.796 | L13: A=1.19 | M13: 1.19
A14: 新沙高架桥 | B14: 小纵梁腹板 | C14: T6a | D14: Q355D | E14: 2180 | F14: 500 | G14: 12 | H14: 1 | I14: =IF(M14="",(E14/1000)*(F14/1000)*(G14/1000)*7850,M14*(G14/1000)*7850) -> 102.678 | J14: 20 | K14: =I14*J14 -> 2053.56 | L14: A=1.09 | M14: 1.09
A15: 新沙高架桥 | B15: 小纵梁腹板 | C15: T6b | D15: Q355D | E15: 1880 | F15: 500 | G15: 12 | H15: 1 | I15: =IF(M15="",(E15/1000)*(F15/1000)*(G15/1000)*7850,M15*(G15/1000)*7850) -> 88.548 | J15: 4 | K15: =I15*J15 -> 354.192 | L15: A=0.94 | M15: 0.94
A16: 新沙高架桥 | B16: 小纵梁腹板 | C16: T6c | D16: Q355D | E16: 1472 | F16: 500 | G16: 12 | H16: 1 | I16: =IF(M16="",(E16/1000)*(F16/1000)*(G16/1000)*7850,M16*(G16/1000)*7850) -> 69.708 | J16: 4 | K16: =I16*J16 -> 278.832 | L16: A=0.74 | M16: 0.74
A17: 新沙高架桥 | B17: 小纵梁底板 | C17: T7 | D17: Q355D | E17: 2380 | F17: 300 | G17: 12 | H17: 1 | I17: =IF(M17="",(E17/1000)*(F17/1000)*(G17/1000)*7850,M17*(G17/1000)*7850) -> 66.882 | J17: 202 | K17: =I17*J17 -> 13510.164 | L17: A=0.71 | M17: 0.71
A18: 新沙高架桥 | B18: 小纵梁底板 | C18: T7a | D18: Q355D | E18: 2180 | F18: 300 | G18: 12 | H18: 1 | I18: =IF(M18="",(E18/1000)*(F18/1000)*(G18/1000)*7850,M18*(G18/1000)*7850) -> 61.23 | J18: 20 | K18: =I18*J18 -> 1224.6 | L18: A=0.65 | M18: 0.65
... A23: 新沙高架桥 | B23: 端横梁腹板 | C23: T22' | D23: Q355D | E23: 17500 | F23: 1955 | G23: 20 | H23: 1 | I23: =IF(M23="",(E23/1000)*(F23/1000)*(G23/1000)*7850,M23*(G23/1000)*7850) -> 4797.92 | J23: 4 | K23: =I23*J23 -> 19191.68 | L23: A=30.56 | M23: 30.56
A24: 新沙高架桥 | B24: 端横梁底板 | C24: T23 | D24: Q355D | E24: 17500 | F24: 1500 | G24: 24 | H24: 1 | I24: =IF(M24="",(E24/1000)*(F24/1000)*(G24/1000)*7850,M24*(G24/1000)*7850) -> 4945.5 | J24: 4 | K24: =I24*J24 -> 19782
A25: 新沙高架桥 | B25: 端横梁加劲板 | C25: T24 | D25: Q355D | E25: 1510 | F25: 220 | G25: 16 | H25: 1 | I25: =IF(M25="",(E25/1000)*(F25/1000)*(G25/1000)*7850,M25*(G25/1000)*7850) -> 38.936 | J25: 48 | K25: =I25*J25 -> 1868.928 | L25: A=0.31 | M25: 0.31
A26: 新沙高架桥 | B26: 端横梁加劲板 | C26: T25 | D26: Q355D | E26: 1396 | F26: 1782 | G26: 12 | H26: 1 | I26: =IF(M26="",(E26/1000)*(F26/1000)*(G26/1000)*7850,M26*(G26/1000)*7850) -> 210.066 | J26: 20 | K26: =I26*J26 -> 4201.32 | L26: A=2.23 | M26: 2.23
A27: 新沙高架桥 | B27: 端横梁隔板加劲 | C27: T26 | D27: Q355D | E27: 2018 | F27: 160 | G27: 12 | H27: 1 | I27: =IF(M27="",(E27/1000)*(F27/1000)*(G27/1000)*7850,M27*(G27/1000)*7850) -> 30.415296 | J27: 20 | K27: =I27*J27 -> 608.30592 | L27: A=0.30
A28: 新沙高架桥 | B28: 小纵梁腹板接头 | C28: T27 | D28: Q355D | E28: 784 | F28: 292 | G28: 12 | H28: 1 | I28: =IF(M28="",(E28/1000)*(F28/1000)*(G28/1000)*7850,M28*(G28/1000)*7850) -> 18.84 | J28: 4 | K28: =I28*J28 -> 75.36 | L28: A=0.2 | M28: 0.2
A29: 新沙高架桥 | B29: 线缆孔加劲 | C29: T30 | D29: Q355D | E29: 1374 | F29: 300 | G29: 14 | H29: 1 | I29: =IF(M29="",(E29/1000)*(F29/1000)*(G29/1000)*7850,M29*(G29/1000)*7850) -> 45.30078 | J29: 236 | K29: =I29*J29 -> 10690.984 | L29: A=0.4
A30: 新沙高架桥 | B30: 小纵梁拼接板 | C30: T50 | D30: Q355D | E30: 400 | F30: 330 | G30: 12 | H30: 1 | I30: =IF(M30="",(E30/1000)*(F30/1000)*(G30/1000)*7850,M30*(G30/1000)*7850) -> 12.246 | J30: 920 | K30: =I30*J30 -> 11266.32 | L30: A=0.13 | M30: 0.13
A31: 新沙高架桥 | B31: 横梁拼接板 | C31: T60 | D31: Q355D | E31: 1840 | F31: 340 | G31: 10 | H31: 1 | I31: =IF(M31="",(E31/1000)*(F31/1000)*(G31/1000)*7850,M31*(G31/1000)*7850) -> 49.1096 | J31: 456 | K31: =I31*J31 -> 22393.978
A32: 新沙高架桥 | B32: 横梁拼接板 | C32: T61 | D32: Q355D | E32: 1440 | F32: 340 | G32: 10 | H32: 1 | I32: =IF(M32="",(E32/1000)*(F32/1000)*(G32/1000)*7850,M32*(G32/1000)*7850) -> 38.4336 | J32: 456 | K32: =I32*J32 -> 17525.722
A33: 新沙高架桥 | B33: 横梁拼接板 | C33: T62 | D33: Q355D | E33: 1840 | F33: 340 | G33: 14 | H33: 1 | I33: =IF(M33="",(E33/1000)*(F33/1000)*(G33/1000)*7850,M33*(G33/1000)*7850) -> 68.75344 | J33: 16 | K33: =I33*J33 -> 1100.055
A34: 新沙高架桥 | B34: 横梁拼接板 | C34: T63 | D34: Q355D | E34: 1440 | F34: 340 | G34: 14 | H34: 1 | I34: =IF(M34="",(E34/1000)*(F34/1000)*(G34/1000)*7850,M34*(G34/1000)*7850) -> 53.80704 | J34: 16 | K34: =I34*J34 -> 860.91264
A35: 新沙高架桥 | B35: 上层桥面系焊缝重 | C35: 焊缝 | D35: Q355D | H35: 1 | I35: 30002.9 | J35: 1 | K35: =I35*J35 -> 30002.9 | L35: 按1.5%计
A36: 新沙高架桥 | B36: 上层桥面系其他 | C36: — | D36: Q235B/Q355C | H36: 1 | I36: 512.8 | J36: 1 | K36: =I36*J36 -> 512.8 | L36: Q235B 484.4 + Q355C 28.4
B37: 小计 | K37: =SUM(K4:K36) -> 2030560.1
B38: 按厚度汇总 | N38: =SUMIF($G$4:$G$36,N$3,$K$4:$K$36) -> 0 | O38: =SUMIF($G$4:$G$36,O$3,$K$4:$K$36) -> 39919.699 | P38: =SUMIF($G$4:$G$36,P$3,$K$4:$K$36) -> 191410.41 | Q38: =SUMIF($G$4:$G$36,Q$3,$K$4:$K$36) -> 789675.72 | R38: =SUMIF($G$4:$G$36,R$3,$K$4:$K$36) -> 1868.928 | S38: =SUMIF($G$4:$G$36,S$3,$K$4:$K$36) -> 431186.43 | T38: =SUMIF($G$4:$G$36,T$3,$K$4:$K$36) -> 545983.2 | U38: =SUMIF($G$4:$G$36,U$3,$K$4:$K$36) -> 0 | ... AC38: =SUMIF($G$4:$G$36,AC$3,$K$4:$K$36) -> 0 | AD38: =SUM(N38:AC38) -> 2000044.4

Sheet 梁底挡块
A2: 梁板编号 | B2: 板件名称 | C2: 位置 | D2: 材质 | E2: 长 | F2: 宽 | G2: 厚 | H2: 数量 | I2: 单件重 | J2: 全桥数量 | K2: 合计重量 | L2: 备注
E3: mm | F3: mm | G3: mm | I3: kg | K3: kg
A4: 新沙高架桥 | B4: 梁底挡块 | C4: — | D4: 待设计核实 | L4: 本册为上层钢桁梁图册，梁底挡块数量见下部构造/支座相关图纸，待核实后补充

Sheet 附属预埋件
A2: 梁板编号 | B2: 板件名称 | C2: 位置 | D2: 材质 | E2: 长 | F2: 宽 | G2: 厚 | H2: 数量 | I2: 单件重 | J2: 全桥数量 | K2: 合计重量 | L2: 备注
E3: mm | F3: mm | G3: mm | I3: kg | K3: kg | N3: 8 | O3: 10 | P3: 12 | Q3: 14 | R3: 16 | S3: 20 | T3: 24 | U3: 28 | V3: 32 | W3: 36 | X3: 40 | Y3: 44 | Z3: 48 | AA3: 60 | AB3: 80 | AC3: 100 | AD3: 合计
A4: 新沙高架桥 | B4: 防撞护栏 | C4: SS级+SA级 | D4: Q355C | H4: 1 | I4: 250569.2 | J4: 1 | K4: =I4*J4 -> 250569.2 | L4: 页21 附属工程
A5: 新沙高架桥 | B5: 路灯底座预埋 | C5: LD | D5: Q355C | H5: 1 | I5: 314 | J5: 1 | K5: =I5*J5 -> 314 | L5: 页21 附属工程
A6: 新沙高架桥 | B6: 伸缩缝 | C6: D240/D320 | D6: Q355B | H6: 1 | I6: 65513.5 | J6: 1 | K6: =I6*J6 -> 65513.5 | L6: 页20 附属工程
A7: 新沙高架桥 | B7: 集中排水 | C7: PS-t20 | D7: Q355D | G7: 20 | H7: 1 | I7: 1753.2 | J7: 1 | K7: =I7*J7 -> 1753.2
A8: 新沙高架桥 | B8: 集中排水 | C8: PS-t16 | D8: Q355D | G8: 16 | H8: 1 | I8: 1623.4 | J8: 1 | K8: =I8*J8 -> 1623.4
B9: 小计 | K9: =SUM(K4:K8) -> 319773.3
B10: 按厚度汇总 | N10: =SUMIF($G$4:$G$8,N$3,$K$4:$K$8) -> 0 | O10: =SUMIF($G$4:$G$8,O$3,$K$4:$K$8) -> 0 | P10: =SUMIF($G$4:$G$8,P$3,$K$4:$K$8) -> 0 | Q10: =SUMIF($G$4:$G$8,Q$3,$K$4:$K$8) -> 0 | R10: =SUMIF($G$4:$G$8,R$3,$K$4:$K$8) -> 1623.4 | S10: =SUMIF($G$4:$G$8,S$3,$K$4:$K$8) -> 1753.2 | T10: =SUMIF($G$4:$G$8,T$3,$K$4:$K$8) -> 0 | U10: =SUMIF($G$4:$G$8,U$3,$K$4:$K$8) -> 0 | ... AC10: =SUMIF($G$4:$G$8,AC$3,$K$4:$K$8) -> 0 | AD10: =SUM(N10:AC10) -> 3376.6
