Workbook

Sheet 节段01材料明细(计算)
A1: 狮子洋通道工程 新沙高架桥 · 中桁节段01 计算底稿 —— 材料数量明细表
A2: 图号：SZYS/04/02/02/01/09（中桁节段01设计图，共5张） 材质：Q355D（N15b为Q355B） 容重：7850 kg/m³ 计算方式：长×宽×厚×7850 或 面积×厚×7850 图纸重量取自图纸“材料数量表”原值（不重算）
A3: 序号 | B3: 部位(名称) | C3: 编号 | D3: 材质 | E3: 长(mm) | F3: 宽(mm) | G3: 面积(m²) | H3: 厚(mm) | I3: 数量 | J3: 计算单件重 (kg) | K3: 计算共重 (kg) | L3: 图纸单件重 (kg) | M3: 图纸共重 (kg) | N3: 差异 (计算-图纸,kg) | O3: 备注
E4: mm | F4: mm | G4: m² | H4: mm | I4: 件 | J4: kg | K4: kg | L4: kg | M4: kg | N4: kg
A5: 1 | B5: 上弦顶板 | C5: N11 | D5: Q355D | G5: 27 | H5: 20 | I5: 1 | J5: =ROUND(IF(G5>0,G5*H5*7.85,E5*F5*H5*7.85/1000000),2) -> 4239 | K5: =ROUND(J5*I5,2) -> 4239 | L5: 4239 | M5: 4239 | N5: =ROUND(K5-M5,2) -> 0 | O5: 面积法 A=27m²
A6: 2 | B6: 上弦底板 | C6: N12 | D6: Q355D | E6: 13350 | F6: 1200 | H6: 20 | I6: 1 | J6: =ROUND(IF(G6>0,G6*H6*7.85,E6*F6*H6*7.85/1000000),2) -> 2515.14 | K6: =ROUND(J6*I6,2) -> 2515.14 | L6: 2515.1 | M6: 2515.1 | N6: =ROUND(K6-M6,2) -> 0.04
A7: 3 | B7: 上弦节点板 | C7: N14 | D7: Q355D | G7: 13.05 | H7: 28 | I7: 2 | J7: =ROUND(IF(G7>0,G7*H7*7.85,E7*F7*H7*7.85/1000000),2) -> 2868.39 | K7: =ROUND(J7*I7,2) -> 5736.78 | L7: 2868.4 | M7: 5736.8 | N7: =ROUND(K7-M7,2) -> -0.02 | O7: 面积法 A=13.05m²
A8: 4 | C8: N14a | D8: Q355D | G8: 25 | H8: 40 | I8: 2 | J8: =ROUND(IF(G8>0,G8*H8*7.85,E8*F8*H8*7.85/1000000),2) -> 7850 | K8: =ROUND(J8*I8,2) -> 15700 | L8: 7850 | M8: 15700 | N8: =ROUND(K8-M8,2) -> 0 | O8: 面积法 A=25m²
A9: 5 | B9: 上弦横隔板 | C9: N15 | D9: Q355D | E9: 1980 | F9: 1200 | H9: 16 | I9: 6 | J9: =ROUND(IF(G9>0,G9*H9*7.85,E9*F9*H9*7.85/1000000),2) -> 298.43 | K9: =ROUND(J9*I9,2) -> 1790.58 | L9: 298.9 | M9: 1793.4 | N9: =ROUND(K9-M9,2) -> -2.82
A10: 6 | C10: N15' | D10: Q355D | E10: 2057 | F10: 200 | H10: 16 | I10: 4 | J10: =ROUND(IF(G10>0,G10*H10*7.85,E10*F10*H10*7.85/1000000),2) -> 51.67 | K10: =ROUND(J10*I10,2) -> 206.68 | L10: 51.5 | M10: 206 | N10: =ROUND(K10-M10,2) -> 0.68
A11: 7 | C11: N15b | D11: Q355B | E11: 2057 | F11: 40 | H11: 4 | I11: 4 | J11: =ROUND(IF(G11>0,G11*H11*7.85,E11*F11*H11*7.85/1000000),2) -> 2.58 | K11: =ROUND(J11*I11,2) -> 10.32 | L11: 2.5 | M11: 10 | N11: =ROUND(K11-M11,2) -> 0.32
A12: 8 | C12: N15c | D12: Q355D | E12: 800 | F12: 400 | H12: 16 | I12: 4 | J12: =ROUND(IF(G12>0,G12*H12*7.85,E12*F12*H12*7.85/1000000),2) -> 40.19 | K12: =ROUND(J12*I12,2) -> 160.76 | L12: 40.2 | M12: 160.8 | N12: =ROUND(K12-M12,2) -> -0.04
A13: 9 | B13: 上弦加劲肋 | C13: N16a | D13: Q355D | E13: 5651 | F13: 240 | H13: 20 | I13: 4 | J13: =ROUND(IF(G13>0,G13*H13*7.85,E13*F13*H13*7.85/1000000),2) -> 212.93 | K13: =ROUND(J13*I13,2) -> 851.72 | L13: 213.5 | M13: 854 | N13: =ROUND(K13-M13,2) -> -2.28
A14: 10 | C14: N16b | D14: Q355D | E14: 7700 | F14: 240 | H14: 20 | I14: 4 | J14: =ROUND(IF(G14>0,G14*H14*7.85,E14*F14*H14*7.85/1000000),2) -> 290.14 | K14: =ROUND(J14*I14,2) -> 1160.56 | L14: 290.5 | M14: 1162 | N14: =ROUND(K14-M14,2) -> -1.44
A15: 11 | C15: N16c | D15: Q355D | E15: 7700 | F15: 240 | H15: 20 | I15: 0 | J15: =ROUND(IF(G15>0,G15*H15*7.85,E15*F15*H15*7.85/1000000),2) -> 290.14 | K15: =ROUND(J15*I15,2) -> 0 | L15: 290.5 | M15: 0 | N15: =ROUND(K15-M15,2) -> 0 | O15: 设计数量为0（待核）
A16: 12 | C16: N16d | D16: Q355D | E16: 13300 | F16: 240 | H16: 20 | I16: 1 | J16: =ROUND(IF(G16>0,G16*H16*7.85,E16*F16*H16*7.85/1000000),2) -> 501.14 | K16: =ROUND(J16*I16,2) -> 501.14 | L16: 500.8 | M16: 500.8 | N16: =ROUND(K16-M16,2) -> 0.34
A17: 13 | C17: N16e | D17: Q355D | E17: 13300 | F17: 240 | H17: 20 | I17: 1 | J17: =ROUND(IF(G17>0,G17*H17*7.85,E17*F17*H17*7.85/1000000),2) -> 501.14 | K17: =ROUND(J17*I17,2) -> 501.14 | L17: 500.8 | M17: 500.8 | N17: =ROUND(K17-M17,2) -> 0.34
A18: 14 | B18: 下弦顶板 | C18: N21 | D18: Q355D | E18: 4790 | F18: 2500 | H18: 20 | I18: 1 | J18: =ROUND(IF(G18>0,G18*H18*7.85,E18*F18*H18*7.85/1000000),2) -> 1880.08 | K18: =ROUND(J18*I18,2) -> 1880.08 | L18: 1880.9 | M18: 1880.9 | N18: =ROUND(K18-M18,2) -> -0.82
A19: 15 | C19: N21a | D19: Q355D | E19: 10105 | F19: 2500 | H19: 20 | I19: 1 | J19: =ROUND(IF(G19>0,G19*H19*7.85,E19*F19*H19*7.85/1000000),2) -> 3966.21 | K19: =ROUND(J19*I19,2) -> 3966.21 | L19: 3965.8 | M19: 3965.8 | N19: =ROUND(K19-M19,2) -> 0.41
A20: 16 | B20: 下弦底板 | C20: N22 | D20: Q355D | G20: 9.36 | H20: 36 | I20: 1 | J20: =ROUND(IF(G20>0,G20*H20*7.85,E20*F20*H20*7.85/1000000),2) -> 2645.14 | K20: =ROUND(J20*I20,2) -> 2645.14 | L20: 2645.1 | M20: 2645.1 | N20: =ROUND(K20-M20,2) -> 0.04 | O20: 面积法 A=9.36m²
A21: 17 | C21: N22a | D21: Q355D | G21: 15.68 | H21: 20 | I21: 1 | J21: =ROUND(IF(G21>0,G21*H21*7.85,E21*F21*H21*7.85/1000000),2) -> 2461.76 | K21: =ROUND(J21*I21,2) -> 2461.76 | L21: 2461.8 | M21: 2461.8 | N21: =ROUND(K21-M21,2) -> -0.04 | O21: 面积法 A=15.68m²
A22: 18 | B22: 下弦腹板 | C22: N23 | D22: Q355D | E22: 10105 | F22: 1880 | H22: 24 | I22: 2 | J22: =ROUND(IF(G22>0,G22*H22*7.85,E22*F22*H22*7.85/1000000),2) -> 3579.11 | K22: =ROUND(J22*I22,2) -> 7158.22 | L22: 3579.6 | M22: 7159.2 | N22: =ROUND(K22-M22,2) -> -0.98
A23: 19 | B23: 下弦节点板 | C23: N24 | D23: Q355D | G23: 17.33 | H23: 40 | I23: 2 | J23: =ROUND(IF(G23>0,G23*H23*7.85,E23*F23*H23*7.85/1000000),2) -> 5441.62 | K23: =ROUND(J23*I23,2) -> 10883.24 | L23: 5441.6 | M23: 10883.2 | N23: =ROUND(K23-M23,2) -> 0.04 | O23: 面积法 A=17.33m², Z35钢
A24: 20 | B24: 下弦横隔板 | C24: N25 | D24: Q355D | E24: 1800 | F24: 1200 | H24: 16 | I24: 1 | J24: =ROUND(IF(G24>0,G24*H24*7.85,E24*F24*H24*7.85/1000000),2) -> 271.3 | K24: =ROUND(J24*I24,2) -> 271.3 | L24: 271.3 | M24: 271.3 | N24: =ROUND(K24-M24,2) -> 0
A25: 21 | C25: N25' | D25: Q355D | E25: 2057 | F25: 200 | H25: 16 | I25: 3 | J25: =ROUND(IF(G25>0,G25*H25*7.85,E25*F25*H25*7.85/1000000),2) -> 51.67 | K25: =ROUND(J25*I25,2) -> 155.01 | L25: 51.5 | M25: 154.5 | N25: =ROUND(K25-M25,2) -> 0.51
A26: 22 | C26: N25a | D26: Q355D | E26: 1800 | F26: 1200 | H26: 16 | I26: 3 | J26: =ROUND(IF(G26>0,G26*H26*7.85,E26*F26*H26*7.85/1000000),2) -> 271.3 | K26: =ROUND(J26*I26,2) -> 813.9 | L26: 271.3 | M26: 813.9 | N26: =ROUND(K26-M26,2) -> 0
A27: 23 | B27: 下弦加劲肋 | C27: N26a | D27: Q355D | E27: 2792 | F27: 240 | H27: 20 | I27: 2 | J27: =ROUND(IF(G27>0,G27*H27*7.85,E27*F27*H27*7.85/1000000),2) -> 105.2 | K27: =ROUND(J27*I27,2) -> 210.4 | L27: 105.2 | M27: 210.4 | N27: =ROUND(K27-M27,2) -> 0
A28: 24 | C28: N26b | D28: Q355D | E28: 10105 | F28: 240 | H28: 20 | I28: 2 | J28: =ROUND(IF(G28>0,G28*H28*7.85,E28*F28*H28*7.85/1000000),2) -> 380.76 | K28: =ROUND(J28*I28,2) -> 761.52 | L28: 381.5 | M28: 763 | N28: =ROUND(K28-M28,2) -> -1.48
A29: 25 | C29: N26c | D29: Q355D | E29: 12897 | F29: 240 | H29: 20 | I29: 1 | J29: =ROUND(IF(G29>0,G29*H29*7.85,E29*F29*H29*7.85/1000000),2) -> 485.96 | K29: =ROUND(J29*I29,2) -> 485.96 | L29: 486.7 | M29: 486.7 | N29: =ROUND(K29-M29,2) -> -0.74
A30: 26 | C30: N26d | D30: Q355D | E30: 10105 | F30: 240 | H30: 20 | I30: 1 | J30: =ROUND(IF(G30>0,G30*H30*7.85,E30*F30*H30*7.85/1000000),2) -> 380.76 | K30: =ROUND(J30*I30,2) -> 380.76 | L30: 381.5 | M30: 381.5 | N30: =ROUND(K30-M30,2) -> -0.74
A31: 27 | C31: N26d' | D31: Q355D | E31: 2792 | F31: 320 | H31: 32 | I31: 1 | J31: =ROUND(IF(G31>0,G31*H31*7.85,E31*F31*H31*7.85/1000000),2) -> 224.43 | K31: =ROUND(J31*I31,2) -> 224.43 | L31: 223.6 | M31: 223.6 | N31: =ROUND(K31-M31,2) -> 0.83
A32: 28 | C32: N26e | D32: Q355D | E32: 12897 | F32: 170 | H32: 14 | I32: 2 | J32: =ROUND(IF(G32>0,G32*H32*7.85,E32*F32*H32*7.85/1000000),2) -> 240.95 | K32: =ROUND(J32*I32,2) -> 481.9 | L32: 240.7 | M32: 481.4 | N32: =ROUND(K32-M32,2) -> 0.5
A33: 29 | B33: 斜腹杆 | C33: N31 | D33: Q355D | E33: 14038 | F33: 1200 | H33: 36 | I33: 1 | J33: =ROUND(IF(G33>0,G33*H33*7.85,E33*F33*H33*7.85/1000000),2) -> 4760.57 | K33: =ROUND(J33*I33,2) -> 4760.57 | L33: 4761.8 | M33: 4761.8 | N33: =ROUND(K33-M33,2) -> -1.23
A34: 30 | C34: N31a | D34: Q355D | E34: 14038 | F34: 1200 | H34: 36 | I34: 1 | J34: =ROUND(IF(G34>0,G34*H34*7.85,E34*F34*H34*7.85/1000000),2) -> 4760.57 | K34: =ROUND(J34*I34,2) -> 4760.57 | L34: 4761.8 | M34: 4761.8 | N34: =ROUND(K34-M34,2) -> -1.23
A35: 31 | C35: N32 | D35: Q355D | E35: 9838 | F35: 1360 | H35: 36 | I35: 2 | J35: =ROUND(IF(G35>0,G35*H35*7.85,E35*F35*H35*7.85/1000000),2) -> 3781.1 | K35: =ROUND(J35*I35,2) -> 7562.2 | L35: 3781.2 | M35: 7562.4 | N35: =ROUND(K35-M35,2) -> -0.2
A36: 32 | C36: N33 | D36: Q355D | E36: 9838 | F36: 320 | H36: 32 | I36: 2 | J36: =ROUND(IF(G36>0,G36*H36*7.85,E36*F36*H36*7.85/1000000),2) -> 790.82 | K36: =ROUND(J36*I36,2) -> 1581.64 | L36: 791.3 | M36: 1582.6 | N36: =ROUND(K36-M36,2) -> -0.96
A37: 33 | C37: N33a | D37: Q355D | E37: 12638 | F37: 320 | H37: 32 | I37: 1 | J37: =ROUND(IF(G37>0,G37*H37*7.85,E37*F37*H37*7.85/1000000),2) -> 1015.89 | K37: =ROUND(J37*I37,2) -> 1015.89 | L37: 1014.8 | M37: 1014.8 | N37: =ROUND(K37-M37,2) -> 1.09
A38: 34 | C38: N33b | D38: Q355D | E38: 12638 | F38: 320 | H38: 32 | I38: 1 | J38: =ROUND(IF(G38>0,G38*H38*7.85,E38*F38*H38*7.85/1000000),2) -> 1015.89 | K38: =ROUND(J38*I38,2) -> 1015.89 | L38: 1014.8 | M38: 1014.8 | N38: =ROUND(K38-M38,2) -> 1.09
A39: 35 | C39: N34 | D39: Q355D | E39: 1200 | F39: 1200 | H39: 16 | I39: 4 | J39: =ROUND(IF(G39>0,G39*H39*7.85,E39*F39*H39*7.85/1000000),2) -> 180.86 | K39: =ROUND(J39*I39,2) -> 723.44 | L39: 180.9 | M39: 723.6 | N39: =ROUND(K39-M39,2) -> -0.16
A40: 36 | C40: N41 | D40: Q355D | E40: 6725 | F40: 1200 | H40: 36 | I40: 1 | J40: =ROUND(IF(G40>0,G40*H40*7.85,E40*F40*H40*7.85/1000000),2) -> 2280.58 | K40: =ROUND(J40*I40,2) -> 2280.58 | L40: 2280.6 | M40: 2280.6 | N40: =ROUND(K40-M40,2) -> -0.02
...

Sheet 按板厚汇总校验
A1: 中桁节段01 材料数量汇总校验表（按板厚）
A2: 计算重量=Σ明细表计算共重；图纸重量=Σ明细表图纸共重（图纸原值）。差异原因未获图纸依据者标注待核。
A4: 板厚 t(mm) | B4: 材质 | C4: 计算重量(kg) | D4: 图纸重量(kg) | E4: 差异(kg) | F4: 差异率 | G4: 差异说明
A5: 100 | B5: Q355D | C5: =ROUND(SUMIF('节段01材料明细(计算)'!$H$5:$H$72,A5,'节段01材料明细(计算)'!$K$5:$K$72),2) -> 2543.4 | D5: =ROUND(SUMIF('节段01材料明细(计算)'!$H$5:$H$72,A5,'节段01材料明细(计算)'!$M$5:$M$72),2) -> 2543.4 | E5: =ROUND(C5-D5,2) -> 0 | F5: =IF(D5=0,"",E5/D5) -> 0 | G5: =IF(ABS(E5)<0.1,"一致（舍入级）","差异原因待核（图纸未标注下料轮廓）") -> 一致（舍入级）
A6: 40 | B6: Q355D | C6: =ROUND(SUMIF('节段01材料明细(计算)'!$H$5:$H$72,A6,'节段01材料明细(计算)'!$K$5:$K$72),2) -> 26583.24 | D6: =ROUND(SUMIF('节段01材料明细(计算)'!$H$5:$H$72,A6,'节段01材料明细(计算)'!$M$5:$M$72),2) -> 26583.2 | E6: =ROUND(C6-D6,2) -> 0.04 | F6: =IF(D6=0,"",E6/D6) -> 1.5047097e-06 | G6: =IF(ABS(E6)<0.1,"一致（舍入级）","差异原因待核（图纸未标注下料轮廓）") -> 一致（舍入级）
A7: 36 | B7: Q355D | C7: =ROUND(SUMIF('节段01材料明细(计算)'!$H$5:$H$72,A7,'节段01材料明细(计算)'!$K$5:$K$72),2) -> 28143.17 | D7: =ROUND(SUMIF('节段01材料明细(计算)'!$H$5:$H$72,A7,'节段01材料明细(计算)'!$M$5:$M$72),2) -> 28146.9 | E7: =ROUND(C7-D7,2) -> -3.73 | F7: =IF(D7=0,"",E7/D7) -> -0.00013251903 | G7: =IF(ABS(E7)<0.1,"一致（舍入级）","差异原因待核（图纸未标注下料轮廓）") -> 差异原因待核（图纸未标注下料轮廓）
A8: 32 | B8: Q355D | C8: =ROUND(SUMIF('节段01材料明细(计算)'!$H$5:$H$72,A8,'节段01材料明细(计算)'!$K$5:$K$72),2) -> 10529.33 | D8: =ROUND(SUMIF('节段01材料明细(计算)'!$H$5:$H$72,A8,'节段01材料明细(计算)'!$M$5:$M$72),2) -> 10530.3 | E8: =ROUND(C8-D8,2) -> -0.97 | F8: =IF(D8=0,"",E8/D8) -> -9.2115134e-05 | G8: =IF(ABS(E8)<0.1,"一致（舍入级）","差异原因待核（图纸未标注下料轮廓）") -> 差异原因待核（图纸未标注下料轮廓）
A9: 28 | B9: Q355D | C9: =ROUND(SUMIF('节段01材料明细(计算)'!$H$5:$H$72,A9,'节段01材料明细(计算)'!$K$5:$K$72),2) -> 6807.64 | D9: =ROUND(SUMIF('节段01材料明细(计算)'!$H$5:$H$72,A9,'节段01材料明细(计算)'!$M$5:$M$72),2) -> 6809.6 | E9: =ROUND(C9-D9,2) -> -1.96 | F9: =IF(D9=0,"",E9/D9) -> -0.00028782895 | G9: =IF(ABS(E9)<0.1,"一致（舍入级）","差异原因待核（图纸未标注下料轮廓）") -> 差异原因待核（图纸未标注下料轮廓）
A10: 24 | B10: Q355D | C10: =ROUND(SUMIF('节段01材料明细(计算)'!$H$5:$H$72,A10,'节段01材料明细(计算)'!$K$5:$K$72),2) -> 8778.46 | D10: =ROUND(SUMIF('节段01材料明细(计算)'!$H$5:$H$72,A10,'节段01材料明细(计算)'!$M$5:$M$72),2) -> 8776 | E10: =ROUND(C10-D10,2) -> 2.46 | F10: =IF(D10=0,"",E10/D10) -> 0.00028030994 | G10: =IF(ABS(E10)<0.1,"一致（舍入级）","差异原因待核（图纸未标注下料轮廓）") -> 差异原因待核（图纸未标注下料轮廓）
A11: 20 | B11: Q355D | C11: =ROUND(SUMIF('节段01材料明细(计算)'!$H$5:$H$72,A11,'节段01材料明细(计算)'!$K$5:$K$72),2) -> 29009.33 | D11: =ROUND(SUMIF('节段01材料明细(计算)'!$H$5:$H$72,A11,'节段01材料明细(计算)'!$M$5:$M$72),2) -> 29015.2 | E11: =ROUND(C11-D11,2) -> -5.87 | F11: =IF(D11=0,"",E11/D11) -> -0.00020230776 | G11: =IF(ABS(E11)<0.1,"一致（舍入级）","差异原因待核（图纸未标注下料轮廓）") -> 差异原因待核（图纸未标注下料轮廓）
A12: 16 | B12: Q355D | C12: =ROUND(SUMIF('节段01材料明细(计算)'!$H$5:$H$72,A12,'节段01材料明细(计算)'!$K$5:$K$72),2) -> 9072.2 | D12: =ROUND(SUMIF('节段01材料明细(计算)'!$H$5:$H$72,A12,'节段01材料明细(计算)'!$M$5:$M$72),2) -> 9079.6 | E12: =ROUND(C12-D12,2) -> -7.4 | F12: =IF(D12=0,"",E12/D12) -> -0.00081501388 | G12: =IF(ABS(E12)<0.1,"一致（舍入级）","差异原因待核（图纸未标注下料轮廓）") -> 差异原因待核（图纸未标注下料轮廓）
A13: 14 | B13: Q355D | C13: =ROUND(SUMIF('节段01材料明细(计算)'!$H$5:$H$72,A13,'节段01材料明细(计算)'!$K$5:$K$72),2) -> 481.9 | D13: =ROUND(SUMIF('节段01材料明细(计算)'!$H$5:$H$72,A13,'节段01材料明细(计算)'!$M$5:$M$72),2) -> 481.4 | E13: =ROUND(C13-D13,2) -> 0.5 | F13: =IF(D13=0,"",E13/D13) -> 0.0010386373 | G13: =IF(ABS(E13)<0.1,"一致（舍入级）","差异原因待核（图纸未标注下料轮廓）") -> 差异原因待核（图纸未标注下料轮廓）
A14: 4 | B14: Q355B | C14: =ROUND(SUMIF('节段01材料明细(计算)'!$H$5:$H$72,A14,'节段01材料明细(计算)'!$K$5:$K$72),2) -> 10.32 | D14: =ROUND(SUMIF('节段01材料明细(计算)'!$H$5:$H$72,A14,'节段01材料明细(计算)'!$M$5:$M$72),2) -> 10 | E14: =ROUND(C14-D14,2) -> 0.32 | F14: =IF(D14=0,"",E14/D14) -> 0.032 | G14: =IF(ABS(E14)<0.1,"一致（舍入级）","差异原因待核（图纸未标注下料轮廓）") -> 差异原因待核（图纸未标注下料轮廓）
A15: 合 计 | C15: =ROUND(SUM(C5:C14),2) -> 121958.99 | D15: =ROUND(SUM(D5:D14),2) -> 121975.6 | E15: =ROUND(C15-D15,2) -> -16.61 | F15: =IF(D15=0,"",E15/D15) -> -0.00013617478 | G15: 材料净重（不含焊缝）
A16: 焊缝重 1.5% | C16: =ROUND(C15*0.015,2) -> 1829.38 | D16: =ROUND(D15*0.015,2) -> 1829.63 | E16: =ROUND(C16-D16,2) -> -0.25 | F16: =IF(D16=0,"",E16/D16) -> -0.00013663965 | G16: 图纸注明焊缝按1.5%计
A17: 合计（含焊缝） | C17: =ROUND(C15+C16,2) -> 123788.37 | D17: =ROUND(D15+D16,2) -> 123805.23 | E17: =ROUND(C17-D17,2) -> -16.86 | F17: =IF(D17=0,"",E17/D17) -> -0.00013618165 | G17: 材料净重+焊缝

Sheet 差异说明与校验报告
A1: 中桁节段01 计算底稿 · 差异说明与校验报告
A3: 一、编制依据
A4: 1. 图纸：《狮子洋通道工程两阶段施工图设计-新沙高架桥上部结构钢桁梁设计图》之《中桁节段01设计图》，图号 SZYS/04/02/02/01/09，图册第40~44页（共5张）。
A5: 2. 模板：《潭州高架桥（计算稿模板）》，沿用其“计算重量—图纸重量分开、按板厚复核、差异对比”的口径与表格结构。
A7: 二、图纸重量来源（图纸数量）
A8: 1. 图纸第5张“节段01材料数量表”给出每个构件的单件重与共重；本底稿“图纸单件重/图纸共重”两列直接取图纸原值，不做任何重算。
A9: 2. 图纸第5张“节段01材料数量汇总表”按板厚给出节段重量，净重小计 121975.6 kg，焊缝重1.5% = 1829.6 kg，合计 123805.2 kg。
A10: 3. 经核对，材料数量表逐项相加与汇总表完全一致（净重121975.6 kg）。
A12: 三、计算重量方法（复核数量）
A13: 1. 钢板按 长(mm)×宽(mm)×厚(mm)÷1e9×7850 kg/m³ 计算；
A14: 2. 图纸以面积标注的板件（如 t=20、A=27m²）按 面积(m²)×厚(mm)÷1000×7850 计算；
A15: 3. 所有单元格均使用公式计算，保留2位小数，未硬编码计算逻辑。
... A27: 六、校验结论（数值自动引用汇总表）
A28: 计算净重(kg) | B28: =按板厚汇总校验!C15 -> 121958.99
A29: 图纸净重(kg) | B29: =按板厚汇总校验!D15 -> 121975.6
A30: 净重差异(kg) | B30: =按板厚汇总校验!E15 -> -16.61
A31: 净重差异率 | B31: =按板厚汇总校验!F15 -> -0.00013617478
A32: 计算合计(kg,含焊缝) | B32: =按板厚汇总校验!C17 -> 123788.37
A33: 图纸合计(kg,含焊缝) | B33: =按板厚汇总校验!D17 -> 123805.23
A34: 合计差异(kg) | B34: =按板厚汇总校验!E17 -> -16.86
A35: 合计差异率 | B35: =按板厚汇总校验!F17 -> -0.00013618165
