Workbook

Sheet 合计数量
A2: 部位 | B2: 板厚 | C2: 单位 | D2: 图纸数量 | G2: 复核数量 | H2: 差异 | I2: 备注
D3: Q355 | E3: Q420 | F3: 合计
A4: 钢梁 | B4: 10 | C4: kg | D4: 40128 | F4: =D4+E4 -> 40128 | G4: =横隔板!N139 -> 3432.9312 | H4: =G4-F4 -> -36695.069 | I4: 图纸数量=新沙高架桥《主桥上构工程数量表(一)》P21（Q355D δ10）
B5: 12 | C5: kg | D5: 193459.1 | F5: =D5+E5 -> 193459.1 | G5: =主梁数量!M432+横隔板!O139 -> 323303.31 | H5: =G5-F5 -> 129844.21 | I5: 图纸数量=新沙 P21（Q355D δ12）
B6: 14 | C6: kg | D6: 847139 | E6: 2518.5 | F6: =D6+E6 -> 849657.5 | G6: =主梁数量!N432+横隔板!P139 -> 650669.9 | H6: =G6-F6 -> -198987.6 | I6: 图纸数量=新沙 P21（Q355D δ14 + Q420D δ14）
B7: 16 | C7: kg | D7: 129234.4 | E7: 27946.9 | F7: =D7+E7 -> 157181.3 | G7: =主梁数量!O432+横隔板!Q139 -> 474025.51 | H7: =G7-F7 -> 316844.21 | I7: 图纸数量=新沙 P21（Q355D δ16 + Q420D δ16）
B8: 20 | C8: kg | D8: 879520.9 | F8: =D8+E8 -> 879520.9 | G8: =主梁数量!P432+横隔板!R139 -> 990076.35 | H8: =G8-F8 -> 110555.45 | I8: 图纸数量=新沙 P21（Q355D δ20）
B9: 24 | C9: kg | D9: 890863 | E9: 11198.7 | F9: =D9+E9 -> 902061.7 | G9: =主梁数量!Q432+横隔板!S139 -> 349743.23 | H9: =G9-F9 -> -552318.47 | I9: 图纸数量=新沙 P21（Q355D δ24 + Q420D δ24）
B10: 28 | C10: kg | D10: 105369.4 | E10: 12062.2 | F10: =D10+E10 -> 117431.6 | G10: =横隔板!T139 -> 23113.6 | H10: =G10-F10 -> -94318 | I10: 图纸数量=新沙 P21（Q355D δ28 + Q420D δ28）
B11: 30 | C11: kg | F11: =D11+E11 -> 0 | G11: =主梁数量!R432+横隔板!U139 -> 38584.32 | H11: =G11-F11 -> 38584.32 | I11: 新沙图纸无δ30板件，图纸数量缺（待设计核实）
B12: 40 | C12: kg | D12: 497184.5 | E12: 341284.8 | F12: =D12+E12 -> 838469.3 | G12: =主梁数量!S432+横隔板!V139 -> 118968.64 | H12: =G12-F12 -> -719500.66 | I12: 图纸数量=新沙 P21（Q355D δ40 含Z35 + Q420D δ40 含Z35）
B13: 50 | C13: kg | F13: =D13+E13 -> 0 | G13: =横隔板!W139 -> 6280 | H13: =G13-F13 -> 6280 | I13: 新沙图纸无δ50板件，图纸数量缺（待设计核实）
A14: 梁底挡块 | B14: 20 | C14: kg | F14: 7638.4 | G14: =梁底挡块!F8 -> 7639.68 | H14: =G14-F14 -> 1.28 | I14: 新沙图纸总表未单列梁底挡块（梁间横梁）数量，待设计核实
A15: 钢梁制造合计 | C15: kg | F15: =SUM(F4:F14) -> 3985547.8 | G15: =SUM(G4:G14) -> 2985837.5 | H15: =G15-F15 -> -999710.32 | I15: 本行仅覆盖模板档位（板厚10/12/14/16/20/24/28/40）共3977.9t；新沙另有δ8/δ32/δ36/δ44/δ48/δ60/δ80/δ100 及Q235B/Q355B/Q355C/焊缝重/螺栓共2107.7t，模板无对应档位行，未纳入；新沙主桥上构钢材合计6085.6t。复核数量G沿用模板（潭州）跨表引用，本次未取得新沙杆件明细（图纸无杆件明细表），差异H暂不可比。
A16: 附属预埋 | B16: 护栏 | C16: kg | F16: 588.9 | G16: 0 | H16: =G16-F16 -> -588.9 | I16: 属于伸缩缝出护栏挡板，与混凝土护栏浇筑标段有冲突，待确认；新沙：防撞护栏设计图P289~P308，数量未单列kg（P22 附属工程表以m/套/个计），待确认
B17: 排水 | C17: kg | F17: =7835.2 -> 7835.2 | G17: =附属预埋件!F11 -> 7836 | H17: =G17-F17 -> 0.8 | I17: 新沙排水为镀锌钢管（P289《全桥排水工程数量表》合计2885.008m），无kg数量，待确认

Sheet 主梁数量
A2: 梁板编号 | B2: 板件名称 | C2: 位置 | D2: 材质 | E2: 长 | F2: 宽 | G2: 厚 | H2: 单件重 | I2: 数量 | J2: 合计重量 | K2: 备注 | L2: 梁板编号 | M2: 复核数量 | U2: 图纸数量 | V2: 差异 | W2: 备注
E3: mm | F3: mm | G3: mm | H3: kg | J3: kg | M3: 12 | N3: 14 | O3: 16 | P3: 20 | Q3: 24 | R3: 30 | S3: 40 | T3: 合计
A4: 上层1# | B4: 顶板 | C4: T1a | D4: Q420MD | E4: 11318.5 | F4: 600 | G4: 20 | H4: =(E4/1000)*(F4/1000)*(G4/1000)*7850 -> 1066.2027 | I4: 2 | J4: =H4*I4 -> 2132.4054 | L4: =A4 -> 上层1# | M4: =SUMIF(G4:G31,$M$3,J4:J31) -> 1174.4323 | N4: =SUMIF(G4:G31,$N$3,J4:J31) -> 40598.087 | O4: =SUMIF(G4:G31,$O$3,J4:J31) -> 24020.364 | P4: =SUMIF(G4:G31,$P$3,J4:J31) -> 45936.228 | Q4: =SUMIF(G4:G31,$Q$3,J4:J31) -> 15162.432 | R4: =SUMIF(G4:G31,$R$3,J4:J31) -> 9043.2 | S4: =SUMIF(G4:G31,$S$3,J4:J31) -> 6933.12 | T4: =SUM(M4:S32) -> 142867.86 | U4: 142867.8 | V4: =T4-U4 -> 0.063177248
C5: T1a' | D5: Q420MD | E5: 12505.7 | F5: 600 | G5: 20 | H5: =(E5/1000)*(F5/1000)*(G5/1000)*7850 -> 1178.0369 | I5: 2 | J5: =H5*I5 -> 2356.0739
C6: T1b | D6: Q420MD | E6: 16000 | F6: 600 | G6: 30 | H6: =(E6/1000)*(F6/1000)*(G6/1000)*7850 -> 2260.8 | I6: 4 | J6: =H6*I6 -> 9043.2
C7: T1b' | D7: Q420MD | E7: 16000 | F7: 600 | G7: 24 | H7: =(E7/1000)*(F7/1000)*(G7/1000)*7850 -> 1808.64 | I7: 4 | J7: =H7*I7 -> 7234.56
C8: T1c | D8: Q420MD | E8: 3700 | F8: 600 | G8: 40 | H8: =(E8/1000)*(F8/1000)*(G8/1000)*7850 -> 697.08 | I8: 2 | J8: =H8*I8 -> 1394.16
C9: T1d | D9: Q420MD | E9: 7200 | F9: 800 | G9: 40 | H9: =(E9/1000)*(F9/1000)*(G9/1000)*7850 -> 1808.64 | I9: 2 | J9: =H9*I9 -> 3617.28
C10: T1e | D10: Q420MD | E10: 5100 | F10: 600 | G10: 40 | H10: =(E10/1000)*(F10/1000)*(G10/1000)*7850 -> 960.84 | I10: 2 | J10: =H10*I10 -> 1921.68
B11: 腹板 | C11: F1a | D11: Q420MD | E11: 11318.5 | F11: 2641.7 | G11: 16 | H11: =(E11/1000)*(F11/1000)*(G11/1000)*7850 -> 3755.4502 | I11: 1 | J11: =H11*I11 -> 3755.4502
C12: F1a' | D12: Q420MD | E12: 11318.5 | F12: 2718.2 | G12: 16 | H12: =(E12/1000)*(F12/1000)*(G12/1000)*7850 -> 3864.2029 | I12: 1 | J12: =H12*I12 -> 3864.2029
C13: F1a'' | D13: Q420MD | E13: 12505.7 | F13: 2641.7 | G13: 16 | H13: =(E13/1000)*(F13/1000)*(G13/1000)*7850 -> 4149.3602 | I13: 1 | J13: =H13*I13 -> 4149.3602
C14: F1a''' | D14: Q420MD | E14: 12505.7 | F14: 2718.2 | G14: 16 | H14: =(E14/1000)*(F14/1000)*(G14/1000)*7850 -> 4269.52 | I14: 1 | J14: =H14*I14 -> 4269.52
C15: F1b | D15: Q420MD | E15: 16000 | F15: 2631.7 | G15: 14 | H15: =(E15/1000)*(F15/1000)*(G15/1000)*7850 -> 4627.5813 | I15: 2 | J15: =H15*I15 -> 9255.1626
C16: F1b' | D16: Q420MD | E16: 16000 | F16: 2708.2 | G16: 14 | H16: =(E16/1000)*(F16/1000)*(G16/1000)*7850 -> 4762.0989 | I16: 2 | J16: =H16*I16 -> 9524.1978
C17: F1b'' | D17: Q420MD | E17: 16000 | F17: 2637.7 | G17: 14 | H17: =(E17/1000)*(F17/1000)*(G17/1000)*7850 -> 4638.1317 | I17: 2 | J17: =H17*I17 -> 9276.2634
C18: F1b''' | D18: Q420MD | E18: 16000 | F18: 2714.2 | G18: 14 | H18: =(E18/1000)*(F18/1000)*(G18/1000)*7850 -> 4772.6493 | I18: 2 | J18: =H18*I18 -> 9545.2986
C19: F1c | D19: Q420MD | E19: 16000 | F19: 2621.7 | G19: 20 | H19: =(E19/1000)*(F19/1000)*(G19/1000)*7850 -> 6585.7104 | I19: 1 | J19: =H19*I19 -> 6585.7104
C20: F1c' | D20: Q420MD | E20: 16000 | F20: 2698.2 | G20: 20 | H20: =(E20/1000)*(F20/1000)*(G20/1000)*7850 -> 6777.8784 | I20: 1 | J20: =H20*I20 -> 6777.8784
B21: 底板 | C21: B1a | D21: Q420MD | E21: 10568.5 | F21: 2630 | G21: 16 | H21: =(E21/1000)*(F21/1000)*(G21/1000)*7850 -> 3491.0715 | I21: 1 | J21: =H21*I21 -> 3491.0715
C22: B1a' | D22: Q420MD | E22: 11755.7 | F22: 2630 | G22: 16 | H22: =(E22/1000)*(F22/1000)*(G22/1000)*7850 -> 3883.2369 | I22: 1 | J22: =H22*I22 -> 3883.2369
C23: B1b | D23: Q420MD | E23: 16000 | F23: 2630 | G23: 20 | H23: =(E23/1000)*(F23/1000)*(G23/1000)*7850 -> 6606.56 | I23: 4 | J23: =H23*I23 -> 26426.24
C24: B1c | D24: Q420MD | E24: 16000 | F24: 2630 | G24: 24 | H24: =(E24/1000)*(F24/1000)*(G24/1000)*7850 -> 7927.872 | I24: 1 | J24: =H24*I24 -> 7927.872
B25: 腹板加劲 | C25: FL1a | D25: Q420MD | E25: 18549.9 | F25: 140 | G25: 12 | H25: =(E25/1000)*(F25/1000)*(G25/1000)*7850 -> 244.63608 | I25: 1 | J25: =H25*I25 -> 244.63608 | K25: 长度待设计核实
C26: FL1b | D26: Q420MD | E26: 70503.2 | F26: 140 | G26: 12 | H26: =(E26/1000)*(F26/1000)*(G26/1000)*7850 -> 929.7962 | I26: 1 | J26: =H26*I26 -> 929.7962 | K26: 长度待设计核实
C27: FL1c | D27: Q420MD | E27: 26872 | F27: 180 | G27: 16 | H27: =(E27/1000)*(F27/1000)*(G27/1000)*7850 -> 607.52218 | I27: 1 | J27: =H27*I27 -> 607.52218 | K27: 长度待设计核实
B28: 底板加劲 | C28: BL1a | D28: Q420MD | E28: 10018.5 | F28: 160 | G28: 14 | H28: =(E28/1000)*(F28/1000)*(G28/1000)*7850 -> 176.1653 | I28: 2 | J28: =H28*I28 -> 352.33061
C29: BL1a' | D29: Q420MD | E29: 11205.7 | F29: 160 | G29: 14 | H29: =(E29/1000)*(F29/1000)*(G29/1000)*7850 -> 197.04103 | I29: 2 | J29: =H29*I29 -> 394.08206
C30: BL1b | D30: Q420MD | E30: 16000 | F30: 160 | G30: 14 | H30: =(E30/1000)*(F30/1000)*(G30/1000)*7850 -> 281.344 | I30: 8 | J30: =H30*I30 -> 2250.752
C31: BL1c | D31: Q420MD | E31: 16000 | F31: 220 | G31: 20 | H31: =(E31/1000)*(F31/1000)*(G31/1000)*7850 -> 552.64 | I31: 3 | J31: =H31*I31 -> 1657.92
B32: 小计 | J32: =SUM(J4:J31) -> 142867.86
A33: 上层2# | B33: 顶板 | C33: T2a | D33: Q420MD | E33: 7074.1 | F33: 600 | G33: 20 | H33: =(E33/1000)*(F33/1000)*(G33/1000)*7850 -> 666.38022 | I33: 2 | J33: =H33*I33 -> 1332.7604 | L33: =A33 -> 上层2# | M33: =SUMIF(G33:G57,$M$3,J33:J57) -> 1188.5936 | N33: =SUMIF(G33:G57,$N$3,J33:J57) -> 40650.853 | O33: =SUMIF(G33:G57,$O$3,J33:J57) -> 24288.51 | P33: =SUMIF(G33:G57,$P$3,J33:J57) -> 45992.823 | Q33: =SUMIF(G33:G57,$Q$3,J33:J57) -> 22396.992 | R33: =SUMIF(G33:G57,$R$3,J33:J57) -> 0 | S33: =SUMIF(G33:G57,$S$3,J33:J57) -> 6933.12 | T33: =SUM(M33:S58) -> 141450.89 | U33: 141450.9 | V33: =T33-U33 -> -0.008425376
C34: T2a' | D34: Q420MD | E34: 17050.5 | F34: 600 | G34: 20 | H34: =(E34/1000)*(F34/1000)*(G34/1000)*7850 -> 1606.1571 | I34: 2 | J34: =H34*I34 -> 3212.3142
C35: T2b | D35: Q420MD | E35: 16000 | F35: 600 | G35: 24 | H35: =(E35/1000)*(F35/1000)*(G35/1000)*7850 -> 1808.64 | I35: 8 | J35: =H35*I35 -> 14469.12
C36: T2c | D36: Q420MD | E36: 3900 | F36: 600 | G36: 40 | H36: =(E36/1000)*(F36/1000)*(G36/1000)*7850 -> 734.76 | I36: 2 | J36: =H36*I36 -> 1469.52
C37: T2d | D37: Q420MD | E37: 7200 | F37: 800 | G37: 40 | H37: =(E37/1000)*(F37/1000)*(G37/1000)*7850 -> 1808.64 | I37: 2 | J37: =H37*I37 -> 3617.28
C38: T2e | D38: Q420MD | E38: 4900 | F38: 600 | G38: 40 | H38: =(E38/1000)*(F38/1000)*(G38/1000)*7850 -> 923.16 | I38: 2 | J38: =H38*I38 -> 1846.32
B39: 腹板 | C39: F2a | D39: Q420MD | E39: 7074.1 | F39: 2641.7 | G39: 16 | H39: =(E39/1000)*(F39/1000)*(G39/1000)*7850 -> 2347.1688 | I39: 1 | J39: =H39*I39 -> 2347.1688
C40: F2a' | D40: Q420MD | E40: 7074.1 | F40: 2718.2 | G40: 16 | H40: =(E40/1000)*(F40/1000)*(G40/1000)*7850 -> 2415.1396 | I40: 1 | J40: =H40*I40 -> 2415.1396
C41: F2a'' | D41: Q420MD | E41: 17050.5 | F41: 2641.7 | G41: 16 | H41: =(E41/1000)*(F41/1000)*(G41/1000)*7850 -> 5657.3136 | I41: 1 | J41: =H41*I41 -> 5657.3136
...

Sheet 横隔板
A2: 梁板编号 | B2: 板件名称 | C2: 位置 | D2: 材质 | E2: 长 | F2: 宽 | G2: 厚 | H2: 数量 | I2: 单件重 | J2: 全桥数量 | K2: 合计重量 | L2: 备注 | M2: 梁板编号 | O2: 复核数量 | Y2: 图纸数量 | Z2: 差异 | AA2: 备注
E3: mm | F3: mm | G3: mm | I3: kg | K3: kg | N3: 10 | O3: 12 | P3: 14 | Q3: 16 | R3: 20 | S3: 24 | T3: 28 | U3: 30 | V3: 40 | W3: 50 | X3: 合计
A4: 横隔板 | B4: Z1边支点横隔板 | C4: N1 | D4: Q355MD | E4: 1951 | F4: 1790 | G4: 20 | H4: 1 | I4: =(E4/1000)*(F4/1000)*(G4/1000)*7850*H4 -> 548.28953 | J4: 32 | K4: =I4*J4 -> 17545.265 | M4: =B4 -> Z1边支点横隔板 | O4: =SUMIF(G4:G22,$O$3,K4:K22) -> 646.4 | P4: =SUMIF(G4:G22,$P$3,K4:K22) -> 0 | Q4: =SUMIF(G4:G22,$Q$3,K4:K22) -> 0 | R4: =SUMIF(G4:G22,$R$3,K4:K22) -> 131616.82 | S4: =SUMIF(G4:G22,$S$3,K4:K22) -> 0 | U4: =SUMIF(G4:G22,$U$3,K4:K22) -> 2411.52 | V4: =SUMIF(G4:G22,$V$3,K4:K22) -> 6430.72 | X4: =SUM(O4:V23) -> 141105.46 | Y4: 141101.8 | Z4: =X4-Y4 -> 3.66464
C5: N2 | D5: Q355MD | E5: 2718 | F5: 2550 | G5: 20 | H5: 1 | I5: 1033.76 | J5: 32 | K5: =I5*J5 -> 33080.32
C6: N3 | D6: Q355MD | E6: 2653 | F6: 470 | G6: 20 | H6: 1 | I6: 132.31 | J6: 32 | K6: =I6*J6 -> 4233.92
C7: N3' | D7: Q355MD | E7: 2653 | F7: 440 | G7: 20 | H7: 1 | I7: 119.56 | J7: 32 | K7: =I7*J7 -> 3825.92
C8: N3a | D8: Q355MD | E8: 2671 | F8: 470 | G8: 20 | H8: 1 | I8: 132.98 | J8: 32 | K8: =I8*J8 -> 4255.36
C9: N3a' | D9: Q355MD | E9: 2671 | F9: 440 | G9: 20 | H9: 1 | I9: 120.24 | J9: 32 | K9: =I9*J9 -> 3847.68
C10: N3b | D10: Q355MD | E10: 2689 | F10: 470 | G10: 20 | H10: 1 | I10: 133.66 | J10: 32 | K10: =I10*J10 -> 4277.12
C11: N3b' | D11: Q355MD | E11: 2689 | F11: 440 | G11: 20 | H11: 1 | I11: 120.91 | J11: 32 | K11: =I11*J11 -> 3869.12
C12: N3c | D12: Q355MD | E12: 2707 | F12: 470 | G12: 20 | H12: 1 | I12: 134.34 | J12: 32 | K12: =I12*J12 -> 4298.88
C13: N3c' | D13: Q355MD | E13: 2707 | F13: 440 | G13: 20 | H13: 1 | I13: 121.59 | J13: 32 | K13: =I13*J13 -> 3890.88
C14: N3d | D14: Q355MD | E14: 1150 | F14: 470 | G14: 20 | H14: 1 | I14: 75.68 | J14: 32 | K14: =I14*J14 -> 2421.76
C15: N3d' | D15: Q355MD | E15: 1150 | F15: 440 | G15: 20 | H15: 1 | I15: 62.32 | J15: 32 | K15: =I15*J15 -> 1994.24
C16: N4 | D16: Q355MD | E16: 776 | F16: 160 | G16: 20 | H16: 2 | I16: =(E16/1000)*(F16/1000)*(G16/1000)*7850*H16 -> 38.98624 | J16: 32 | K16: =I16*J16 -> 1247.5597
C17: N5 | D17: Q355MD | E17: 500 | F17: 240 | G17: 20 | H17: 2 | I17: 33.7 | J17: 32 | K17: =I17*J17 -> 1078.4
C18: N6 | D18: Q355MD | E18: 400 | F18: 400 | G18: 30 | H18: 2 | I18: =(E18/1000)*(F18/1000)*(G18/1000)*7850*H18 -> 75.36 | J18: 32 | K18: =I18*J18 -> 2411.52
C19: N7 | D19: Q355MD | E19: 800 | F19: 800 | G19: 40 | H19: 1 | I19: =(E19/1000)*(F19/1000)*(G19/1000)*7850*H19 -> 200.96 | J19: 32 | K19: =I19*J19 -> 6430.72
C20: N8 | D20: Q355MD | E20: 840 | F20: 540 | G20: 12 | H20: 2 | I20: 20.2 | J20: 32 | K20: =I20*J20 -> 646.4 | L20: 数量有误需设计核实
C21: N9 | D21: Q355MD | E21: 2718 | F21: 2550 | G21: 20 | H21: 1 | I21: 1033.8 | J21: 32 | K21: =I21*J21 -> 33081.6
C22: N10 | D22: Q355MD | E22: 740 | F22: 785 | G22: 20 | H22: 1 | I22: 270.9 | J22: 32 | K22: =I22*J22 -> 8668.8
B23: 小计 | K23: =SUM(K4:K22) -> 141105.46
A24: 横隔板 | B24: T1上层挑梁 | C24: N1T | D24: Q355MD | E24: 1109 | F24: 575 | G24: 20 | H24: 1 | I24: 65.3 | J24: 4 | K24: =I24*J24 -> 261.2 | M24: =B24 -> T1上层挑梁 | N24: =K26 -> 109.2 | Q24: =K27+K28 -> 234 | R24: =K24+K25 -> 1188.4 | X24: =SUM(N24:V24) -> 1531.6 | Y24: 1532.1 | Z24: =X24-Y24 -> -0.5
C25: N2T | D25: Q355MD | E25: 1790 | F25: 825 | G25: 20 | H25: 1 | I25: 231.8 | J25: 4 | K25: =I25*J25 -> 927.2
C26: N3T | D26: Q355MD | E26: 1161 | F26: 300 | G26: 10 | H26: 1 | I26: 27.3 | J26: 4 | K26: =I26*J26 -> 109.2
C27: N4T | D27: Q355MD | E27: 1234 | F27: 160 | G27: 16 | H27: 2 | I27: 49.6 | J27: 4 | K27: =I27*J27 -> 198.4
C28: N4Ta | D28: Q355MD | E28: 444 | F28: 160 | G28: 16 | H28: 1 | I28: 8.9 | J28: 4 | K28: =I28*J28 -> 35.6 | L28: 数量有误需设计核实
B29: 小计 | K29: =SUM(K24:K28) -> 1531.6
A30: 横隔板 | B30: T2上层挑梁 | C30: N1 | D30: Q355MD | E30: 1109 | F30: 575 | G30: 20 | H30: 1 | I30: 59.4 | J30: 4 | K30: =I30*J30 -> 237.6 | M30: =B30 -> T2上层挑梁 | N30: =K32 -> 100.8 | Q30: =K33+K34 -> 234 | R30: =K30+K31 -> 1052.4 | X30: =SUM(N30:V30) -> 1387.2 | Y30: 1387.5 | Z30: =X30-Y30 -> -0.3
C31: N2 | D31: Q355MD | E31: 1790 | F31: 725 | G31: 20 | H31: 1 | I31: 203.7 | J31: 4 | K31: =I31*J31 -> 814.8
C32: N3 | D32: Q355MD | E32: 1071 | F32: 300 | G32: 10 | H32: 1 | I32: 25.2 | J32: 4 | K32: =I32*J32 -> 100.8
C33: N4 | D33: Q355MD | E33: 1234 | F33: 160 | G33: 16 | H33: 2 | I33: 49.6 | J33: 4 | K33: =I33*J33 -> 198.4
C34: N4a | D34: Q355MD | E34: 444 | F34: 160 | G34: 16 | H34: 1 | I34: 8.9 | J34: 4 | K34: =I34*J34 -> 35.6 | L34: 数量有误需设计核实
B35: 小计 | K35: =SUM(K30:K34) -> 1387.2
A36: 横隔板 | B36: T3下层挑梁 | C36: N1' | D36: Q355MD | E36: 634 | F36: 575 | G36: 20 | H36: 1 | I36: 37.2 | J36: 8 | K36: =I36*J36 -> 297.6 | M36: =B36 -> T3下层挑梁 | N36: =K38 -> 139.2 | Q36: =K39+K40 -> 269.6 | R36: =K36+K37 -> 1084.8 | X36: =SUM(N36:V36) -> 1493.6 | Y36: 1492.9 | Z36: =X36-Y36 -> 0.7
C37: N2' | D37: Q355MD | E37: 1790 | F37: 350 | G37: 20 | H37: 1 | I37: 98.4 | J37: 8 | K37: =I37*J37 -> 787.2
C38: N3' | D38: Q355MD | E38: 738 | F38: 300 | G38: 10 | H38: 1 | I38: 17.4 | J38: 8 | K38: =I38*J38 -> 139.2
C39: N4' | D39: Q355MD | E39: 1234 | F39: 160 | G39: 16 | H39: 1 | I39: 24.8 | J39: 8 | K39: =I39*J39 -> 198.4
C40: N4a' | D40: Q355MD | E40: 444 | F40: 160 | G40: 16 | H40: 1 | I40: 8.9 | J40: 8 | K40: =I40*J40 -> 71.2
B41: 小计 | K41: =SUM(K36:K40) -> 1493.6
...

Sheet 梁底挡块
A2: 梁板编号 | B2: 板件名称 | C2: 位置 | D2: 材质 | E2: 长 | F2: 宽 | G2: 厚 | H2: 数量 | I2: 单件重 | J2: 全桥数量 | K2: 合计重量 | L2: 备注 | M2: 梁板编号 | S2: 图纸数量 | T2: 差异 | U2: 备注
E3: mm | F3: mm | G3: mm | I3: kg | K3: kg | N3: 16 | O3: 20 | P3: 24 | Q3: 28 | R3: 合计
A4: 梁间横梁 | B4: XJHL1 | C4: N1 | D4: Q355MD | E4: 600 | F4: 700 | G4: 20 | H4: 1 | I4: =(E4/1000)*(F4/1000)*(G4/1000)*7850*H4 -> 65.94 | J4: 32 | K4: =I4*J4 -> 2110.08 | M4: =B4 -> XJHL1 | O4: =K6 -> 7639.68 | R4: =SUM(N4:Q6) -> 7639.68 | S4: 7638.4 | T4: =R4-S4 -> 1.28
C5: N2 | D5: Q355MD | G5: 20 | H5: 4 | I5: 172.8 | J5: 32 | K5: =I5*J5 -> 5529.6
B6: 小计 | K6: =SUM(K4:K5) -> 7639.68
A7: 名称 | D7: 材质 | E7: 单位 | F7: 复核数量 | G7: 图纸数量 | I7: 差异
A8: 合计 | D8: =D5 -> Q355MD | E8: kg | F8: =R4 -> 7639.68 | G8: =S4 -> 7638.4 | I8: 新沙图纸总表未单列梁间横梁（梁底挡块）数量，图纸数量S4为模板值，待设计核实。

Sheet 附属预埋件
A2: 梁板编号 | B2: 板件名称 | C2: 位置 | D2: 材质 | E2: 长 | F2: 宽 | G2: 厚 | H2: 数量 | I2: 单件重 | J2: 全桥数量 | K2: 合计重量 | L2: 备注 | M2: 梁板编号 | S2: 图纸数量 | T2: 差异 | U2: 备注
E3: mm | F3: mm | G3: mm | I3: kg | K3: kg | N3: 4 | O3: 12 | P3: 24 | Q3: 28 | R3: 合计
A4: 排水 | B4: XJHL1 | C4: 上层N1 | D4: Q355C | E4: 647 | F4: 280 | G4: 12 | H4: 1 | I4: 15.83 | J4: 200 | K4: =I4*J4 -> 3166 | M4: =B4 -> XJHL1 | N4: =K8 -> 668 | O4: =K4+K5+K6+K7 -> 7168 | R4: =SUM(N4:Q9) -> 7836 | S4: 7835.18 | T4: =R4-S4 -> 0.82
C5: 下层N1 | D5: Q355C | E5: 277 | F5: 280 | G5: 12 | H5: 1 | I5: 6.07 | J5: 200 | K5: =I5*J5 -> 1214
C6: 上层N2 | D6: Q355C | E6: 530 | F6: 150 | G6: 12 | H6: 1 | I6: 5.23 | J6: 400 | K6: =I6*J6 -> 2092
C7: 下层N2 | D7: Q355C | E7: 160 | F7: 150 | G7: 12 | H7: 1 | I7: 1.74 | J7: 400 | K7: =I7*J7 -> 696
C8: N3 | D8: Q355C | E8: 663 | F8: 80 | G8: 4 | H8: 1 | I8: 1.67 | J8: 400 | K8: =I8*J8 -> 668
B9: 小计 | K9: =SUM(K4:K8) -> 7836
A10: 名称 | D10: 材质 | E10: 单位 | F10: 复核数量 | G10: 图纸数量 | I10: 差异
A11: 合计 | D11: =D8 -> Q355C | E11: kg | F11: =R4 -> 7836 | G11: =S4 -> 7835.18 | I11: 新沙排水/预埋件为镀锌钢管等（P289/P22），非Q355C板件，图纸数量S4为模板值，待设计核实。
