Workbook

Sheet 合计数量
A2: 部位 | B2: 板厚 | C2: 单位 | D2: 图纸数量 | G2: 复核数量 | H2: 差异 | I2: 备注
D3: Q355 | E3: Q420 | F3: 合计
A4: 钢梁 | B4: 100 | C4: kg | D4: 2543.4 | F4: =D4+E4 -> 2543.4 | G4: =主梁数量!AB4 -> 2543.4 | H4: =G4-F4 -> 0 | I4: 图纸重量：P49《节段01材料数量表》汇总表 δ100；计算重量：主梁数量 明细按厚度 SUMIF(AB 列)
B5: 40 | C5: kg | D5: 26583.2 | F5: =D5+E5 -> 26583.2 | G5: =主梁数量!S4 -> 26583.24 | H5: =G5-F5 -> 0.04 | I5: 图纸重量：P49《节段01材料数量表》汇总表 δ40；计算重量：主梁数量 明细按厚度 SUMIF(S 列)
B6: 36 | C6: kg | D6: 28146.9 | F6: =D6+E6 -> 28146.9 | G6: =主梁数量!AA4 -> 28143.162 | H6: =G6-F6 -> -3.738144 | I6: 图纸重量：P49《节段01材料数量表》汇总表 δ36；计算重量：主梁数量 明细按厚度 SUMIF(AA 列)
B7: 32 | C7: kg | D7: 10530.3 | F7: =D7+E7 -> 10530.3 | G7: =主梁数量!Z4 -> 10529.319 | H7: =G7-F7 -> -0.980704 | I7: 图纸重量：P49《节段01材料数量表》汇总表 δ32；计算重量：主梁数量 明细按厚度 SUMIF(Z 列)
B8: 28 | C8: kg | D8: 6809.6 | F8: =D8+E8 -> 6809.6 | G8: =主梁数量!Y4 -> 6807.6456 | H8: =G8-F8 -> -1.9544 | I8: 图纸重量：P49《节段01材料数量表》汇总表 δ28；计算重量：主梁数量 明细按厚度 SUMIF(Y 列)
B9: 24 | C9: kg | D9: 8776 | F9: =D9+E9 -> 8776 | G9: =主梁数量!Q4 -> 8778.4603 | H9: =G9-F9 -> 2.46032 | I9: 图纸重量：P49《节段01材料数量表》汇总表 δ24；计算重量：主梁数量 明细按厚度 SUMIF(Q 列)
B10: 20 | C10: kg | D10: 29015.2 | F10: =D10+E10 -> 29015.2 | G10: =主梁数量!P4 -> 29046.988 | H10: =G10-F10 -> 31.78762 | I10: 图纸重量：P49《节段01材料数量表》汇总表 δ20；计算重量：主梁数量 明细按厚度 SUMIF(P 列)
B11: 16 | C11: kg | D11: 9079.6 | F11: =D11+E11 -> 9079.6 | G11: =主梁数量!O4 -> 9072.1659 | H11: =G11-F11 -> -7.434128 | I11: 图纸重量：P49《节段01材料数量表》汇总表 δ16；计算重量：主梁数量 明细按厚度 SUMIF(O 列)
B12: 14 | C12: kg | D12: 481.4 | F12: =D12+E12 -> 481.4 | G12: =主梁数量!N4 -> 481.9093 | H12: =G12-F12 -> 0.509302 | I12: 图纸重量：P49《节段01材料数量表》汇总表 δ14；计算重量：主梁数量 明细按厚度 SUMIF(N 列)
B13: 4 | C13: kg | D13: 10 | F13: =D13+E13 -> 10 | G13: =主梁数量!X4 -> 10.334368 | H13: =G13-F13 -> 0.334368 | I13: 图纸重量：P49《节段01材料数量表》汇总表 δ4；计算重量：主梁数量 明细按厚度 SUMIF(X 列)
A14: 焊缝重(1.5%) | C14: kg | D14: 1829.6 | F14: =D14+E14 -> 1829.6 | G14: =SUM(G4:G13)*0.015 -> 1829.9494 | H14: =G14-F14 -> 0.34936351 | I14: 图纸 1829.6kg（P49 汇总表，按板件净重1.5%）；计算=计算板件小计×1.5%
A15: 合计 | C15: kg | F15: =SUM(F4:F14) -> 123805.2 | G15: =SUM(G4:G14) -> 123826.57 | H15: =G15-F15 -> 21.373598 | I15: 图纸合计 123805.2kg（含焊缝重）；计算合计=计算板件+计算焊缝重
A16: 附属预埋 | B16: 内表面涂装 | C16: m² | D16: 677.5 | F16: =D16+E16 -> 677.5 | I16: 图纸 677.5m²（P49 汇总表）；计算未做（需按构件表面展开面积统计）→ 未完成，故不列差异
B17: 外表面涂装 | C17: m² | D17: 460.1 | F17: =D17+E17 -> 460.1 | I17: 图纸 460.1m²（P49 汇总表）；计算未做 → 未完成，故不列差异

Sheet 主梁数量
A2: 梁板编号 | B2: 板件名称 | C2: 位置 | D2: 材质 | E2: 长 | F2: 宽 | G2: 厚 | H2: 单件重 | I2: 数量 | J2: 合计重量 | K2: 备注 | L2: 梁板编号 | M2: 复核数量 | U2: 图纸数量 | V2: 差异 | W2: 备注 | AC2: 净面积 | AD2: 图纸单件重 | AE2: 图纸共重 | AF2: 单件重差异
E3: mm | F3: mm | G3: mm | H3: kg | J3: kg | M3: 12 | N3: 14 | O3: 16 | P3: 20 | Q3: 24 | R3: 30 | S3: 40 | T3: 合计 | X3: 4 | Y3: 28 | Z3: 32 | AA3: 36 | AB3: 100 | AC3: mm² | AD3: kg | AE3: kg | AF3: kg
A4: 节段01 | B4: 上弦顶板 | C4: N11 | D4: Q355D | G4: 20 | H4: =IF(AC4>0,AC4/1000000*(G4/1000)*7850,(E4/1000)*(F4/1000)*(G4/1000)*7850) -> 4239 | I4: 1 | J4: =H4*I4 -> 4239 | L4: =A4 -> 节段01 | N4: =SUMIF($G$4:$G$71,N$3,$J$4:$J$71) -> 481.9093 | O4: =SUMIF($G$4:$G$71,O$3,$J$4:$J$71) -> 9072.1659 | P4: =SUMIF($G$4:$G$71,P$3,$J$4:$J$71) -> 29046.988 | Q4: =SUMIF($G$4:$G$71,Q$3,$J$4:$J$71) -> 8778.4603 | S4: =SUMIF($G$4:$G$71,S$3,$J$4:$J$71) -> 26583.24 | T4: =SUM(M4:S72)+SUM(X4:AB72) -> 121996.62 | U4: =SUM(AE4:AE71) -> 121975.6 | V4: =T4-U4 -> 21.024234 | X4: =SUMIF($G$4:$G$71,X$3,$J$4:$J$71) -> 10.334368 | Y4: =SUMIF($G$4:$G$71,Y$3,$J$4:$J$71) -> 6807.6456 | Z4: =SUMIF($G$4:$G$71,Z$3,$J$4:$J$71) -> 10529.319 | AA4: =SUMIF($G$4:$G$71,AA$3,$J$4:$J$71) -> 28143.162 | AB4: =SUMIF($G$4:$G$71,AB$3,$J$4:$J$71) -> 2543.4 | AC4: 27000000 | AD4: 4239 | AE4: 4239 | AF4: =H4-AD4 -> 0
B5: 上弦底板 | C5: N12 | D5: Q355D | E5: 13550 | F5: 1200 | G5: 20 | H5: =IF(AC5>0,AC5/1000000*(G5/1000)*7850,(E5/1000)*(F5/1000)*(G5/1000)*7850) -> 2552.82 | I5: 1 | J5: =H5*I5 -> 2552.82 | L5: =A5 -> 0 | AD5: 2515.1 | AE5: 2515.1 | AF5: =H5-AD5 -> 37.72
B6: 上弦节点板 | C6: N14 | D6: Q355D | G6: 28 | H6: =IF(AC6>0,AC6/1000000*(G6/1000)*7850,(E6/1000)*(F6/1000)*(G6/1000)*7850) -> 2868.39 | I6: 2 | J6: =H6*I6 -> 5736.78 | L6: =A6 -> 0 | AC6: 13050000 | AD6: 2868.4 | AE6: 5736.8 | AF6: =H6-AD6 -> -0.01
B7: 上弦节点板 | C7: N14a | D7: Q355D | G7: 40 | H7: =IF(AC7>0,AC7/1000000*(G7/1000)*7850,(E7/1000)*(F7/1000)*(G7/1000)*7850) -> 7850 | I7: 2 | J7: =H7*I7 -> 15700 | L7: =A7 -> 0 | AC7: 25000000 | AD7: 7850 | AE7: 15700 | AF7: =H7-AD7 -> 0
B8: 上弦横隔板 | C8: N15 | D8: Q355D | E8: 1980 | F8: 1200 | G8: 16 | H8: =IF(AC8>0,AC8/1000000*(G8/1000)*7850,(E8/1000)*(F8/1000)*(G8/1000)*7850) -> 298.4256 | I8: 6 | J8: =H8*I8 -> 1790.5536 | L8: =A8 -> 0 | AD8: 298.9 | AE8: 1793.4 | AF8: =H8-AD8 -> -0.4744
B9: 上弦横隔板 | C9: N15' | D9: Q355D | E9: 2057 | F9: 200 | G9: 16 | H9: =IF(AC9>0,AC9/1000000*(G9/1000)*7850,(E9/1000)*(F9/1000)*(G9/1000)*7850) -> 51.67184 | I9: 4 | J9: =H9*I9 -> 206.68736 | L9: =A9 -> 0 | AD9: 51.5 | AE9: 206 | AF9: =H9-AD9 -> 0.17184
B10: 上弦横隔板 | C10: N15b | D10: Q355B | E10: 2057 | F10: 40 | G10: 4 | H10: =IF(AC10>0,AC10/1000000*(G10/1000)*7850,(E10/1000)*(F10/1000)*(G10/1000)*7850) -> 2.583592 | I10: 4 | J10: =H10*I10 -> 10.334368 | L10: =A10 -> 0 | AD10: 2.5 | AE10: 10 | AF10: =H10-AD10 -> 0.083592
B11: 上弦横隔板 | C11: N15c | D11: Q355D | E11: 800 | F11: 400 | G11: 16 | H11: =IF(AC11>0,AC11/1000000*(G11/1000)*7850,(E11/1000)*(F11/1000)*(G11/1000)*7850) -> 40.192 | I11: 4 | J11: =H11*I11 -> 160.768 | L11: =A11 -> 0 | AD11: 40.2 | AE11: 160.8 | AF11: =H11-AD11 -> -0.008
B12: 上弦加劲肋 | C12: N16a | D12: Q355D | E12: 5651 | F12: 240 | G12: 20 | H12: =IF(AC12>0,AC12/1000000*(G12/1000)*7850,(E12/1000)*(F12/1000)*(G12/1000)*7850) -> 212.92968 | I12: 4 | J12: =H12*I12 -> 851.71872 | L12: =A12 -> 0 | AD12: 213.5 | AE12: 854 | AF12: =H12-AD12 -> -0.57032
B13: 上弦加劲肋 | C13: N16b | D13: Q355D | E13: 7700 | F13: 240 | G13: 20 | H13: =IF(AC13>0,AC13/1000000*(G13/1000)*7850,(E13/1000)*(F13/1000)*(G13/1000)*7850) -> 290.136 | I13: 4 | J13: =H13*I13 -> 1160.544 | L13: =A13 -> 0 | AD13: 290.5 | AE13: 1162 | AF13: =H13-AD13 -> -0.364
B14: 上弦加劲肋 | C14: N16c | D14: Q355D | E14: 7700 | F14: 240 | G14: 20 | H14: =IF(AC14>0,AC14/1000000*(G14/1000)*7850,(E14/1000)*(F14/1000)*(G14/1000)*7850) -> 290.136 | I14: 0 | J14: =H14*I14 -> 0 | L14: =A14 -> 0 | AD14: 290.5 | AE14: 0 | AF14: =H14-AD14 -> -0.364
B15: 上弦加劲肋 | C15: N16d | D15: Q355D | E15: 13300 | F15: 240 | G15: 20 | H15: =IF(AC15>0,AC15/1000000*(G15/1000)*7850,(E15/1000)*(F15/1000)*(G15/1000)*7850) -> 501.144 | I15: 1 | J15: =H15*I15 -> 501.144 | L15: =A15 -> 0 | AD15: 500.8 | AE15: 500.8 | AF15: =H15-AD15 -> 0.344
B16: 上弦加劲肋 | C16: N16e | D16: Q355D | E16: 13300 | F16: 240 | G16: 20 | H16: =IF(AC16>0,AC16/1000000*(G16/1000)*7850,(E16/1000)*(F16/1000)*(G16/1000)*7850) -> 501.144 | I16: 1 | J16: =H16*I16 -> 501.144 | L16: =A16 -> 0 | AD16: 500.8 | AE16: 500.8 | AF16: =H16-AD16 -> 0.344
B17: 下弦顶板 | C17: N21 | D17: Q355D | E17: 4790 | F17: 2500 | G17: 20 | H17: =IF(AC17>0,AC17/1000000*(G17/1000)*7850,(E17/1000)*(F17/1000)*(G17/1000)*7850) -> 1880.075 | I17: 1 | J17: =H17*I17 -> 1880.075 | L17: =A17 -> 0 | AD17: 1880.9 | AE17: 1880.9 | AF17: =H17-AD17 -> -0.825
B18: 下弦顶板 | C18: N21a | D18: Q355D | E18: 10105 | F18: 2500 | G18: 20 | H18: =IF(AC18>0,AC18/1000000*(G18/1000)*7850,(E18/1000)*(F18/1000)*(G18/1000)*7850) -> 3966.2125 | I18: 1 | J18: =H18*I18 -> 3966.2125 | L18: =A18 -> 0 | AD18: 3965.8 | AE18: 3965.8 | AF18: =H18-AD18 -> 0.4125
B19: 下弦底板 | C19: N22 | D19: Q355D | G19: 36 | H19: =IF(AC19>0,AC19/1000000*(G19/1000)*7850,(E19/1000)*(F19/1000)*(G19/1000)*7850) -> 2645.136 | I19: 1 | J19: =H19*I19 -> 2645.136 | L19: =A19 -> 0 | AC19: 9360000 | AD19: 2645.1 | AE19: 2645.1 | AF19: =H19-AD19 -> 0.036
B20: 下弦底板 | C20: N22a | D20: Q355D | G20: 20 | H20: =IF(AC20>0,AC20/1000000*(G20/1000)*7850,(E20/1000)*(F20/1000)*(G20/1000)*7850) -> 2461.76 | I20: 1 | J20: =H20*I20 -> 2461.76 | L20: =A20 -> 0 | AC20: 15680000 | AD20: 2461.8 | AE20: 2461.8 | AF20: =H20-AD20 -> -0.04
B21: 下弦腹板 | C21: N23 | D21: Q355D | E21: 10105 | F21: 1880 | G21: 24 | H21: =IF(AC21>0,AC21/1000000*(G21/1000)*7850,(E21/1000)*(F21/1000)*(G21/1000)*7850) -> 3579.1102 | I21: 2 | J21: =H21*I21 -> 7158.2203 | L21: =A21 -> 0 | AD21: 3579.6 | AE21: 7159.2 | AF21: =H21-AD21 -> -0.48984
B22: 下弦节点板 | C22: N24 | D22: Q355D | G22: 40 | H22: =IF(AC22>0,AC22/1000000*(G22/1000)*7850,(E22/1000)*(F22/1000)*(G22/1000)*7850) -> 5441.62 | I22: 2 | J22: =H22*I22 -> 10883.24 | L22: =A22 -> 0 | AC22: 17330000 | AD22: 5441.6 | AE22: 10883.2 | AF22: =H22-AD22 -> 0.02
B23: 下弦横隔板 | C23: N25 | D23: Q355D | E23: 1800 | F23: 1200 | G23: 16 | H23: =IF(AC23>0,AC23/1000000*(G23/1000)*7850,(E23/1000)*(F23/1000)*(G23/1000)*7850) -> 271.296 | I23: 1 | J23: =H23*I23 -> 271.296 | L23: =A23 -> 0 | AD23: 271.3 | AE23: 271.3 | AF23: =H23-AD23 -> -0.004
B24: 下弦横隔板 | C24: N25' | D24: Q355D | E24: 2057 | F24: 200 | G24: 16 | H24: =IF(AC24>0,AC24/1000000*(G24/1000)*7850,(E24/1000)*(F24/1000)*(G24/1000)*7850) -> 51.67184 | I24: 3 | J24: =H24*I24 -> 155.01552 | L24: =A24 -> 0 | AD24: 51.5 | AE24: 154.5 | AF24: =H24-AD24 -> 0.17184
B25: 下弦横隔板 | C25: N25a | D25: Q355D | E25: 1800 | F25: 1200 | G25: 16 | H25: =IF(AC25>0,AC25/1000000*(G25/1000)*7850,(E25/1000)*(F25/1000)*(G25/1000)*7850) -> 271.296 | I25: 3 | J25: =H25*I25 -> 813.888 | L25: =A25 -> 0 | AD25: 271.3 | AE25: 813.9 | AF25: =H25-AD25 -> -0.004
B26: 下弦加劲肋 | C26: N26a | D26: Q355D | E26: 2792 | F26: 240 | G26: 20 | H26: =IF(AC26>0,AC26/1000000*(G26/1000)*7850,(E26/1000)*(F26/1000)*(G26/1000)*7850) -> 105.20256 | I26: 2 | J26: =H26*I26 -> 210.40512 | L26: =A26 -> 0 | AD26: 105.2 | AE26: 210.4 | AF26: =H26-AD26 -> 0.00256
B27: 下弦加劲肋 | C27: N26b | D27: Q355D | E27: 10105 | F27: 240 | G27: 20 | H27: =IF(AC27>0,AC27/1000000*(G27/1000)*7850,(E27/1000)*(F27/1000)*(G27/1000)*7850) -> 380.7564 | I27: 2 | J27: =H27*I27 -> 761.5128 | L27: =A27 -> 0 | AD27: 381.5 | AE27: 763 | AF27: =H27-AD27 -> -0.7436
B28: 下弦加劲肋 | C28: N26c | D28: Q355D | E28: 12897 | F28: 240 | G28: 20 | H28: =IF(AC28>0,AC28/1000000*(G28/1000)*7850,(E28/1000)*(F28/1000)*(G28/1000)*7850) -> 485.95896 | I28: 1 | J28: =H28*I28 -> 485.95896 | L28: =A28 -> 0 | AD28: 486.7 | AE28: 486.7 | AF28: =H28-AD28 -> -0.74104
B29: 下弦加劲肋 | C29: N26d | D29: Q355D | E29: 10105 | F29: 240 | G29: 20 | H29: =IF(AC29>0,AC29/1000000*(G29/1000)*7850,(E29/1000)*(F29/1000)*(G29/1000)*7850) -> 380.7564 | I29: 1 | J29: =H29*I29 -> 380.7564 | L29: =A29 -> 0 | AD29: 381.5 | AE29: 381.5 | AF29: =H29-AD29 -> -0.7436
B30: 下弦加劲肋 | C30: N26d' | D30: Q355D | E30: 2792 | F30: 320 | G30: 32 | H30: =IF(AC30>0,AC30/1000000*(G30/1000)*7850,(E30/1000)*(F30/1000)*(G30/1000)*7850) -> 224.43213 | I30: 1 | J30: =H30*I30 -> 224.43213 | L30: =A30 -> 0 | AD30: 223.6 | AE30: 223.6 | AF30: =H30-AD30 -> 0.832128
B31: 下弦加劲肋 | C31: N26e | D31: Q355D | E31: 12897 | F31: 170 | G31: 14 | H31: =IF(AC31>0,AC31/1000000*(G31/1000)*7850,(E31/1000)*(F31/1000)*(G31/1000)*7850) -> 240.95465 | I31: 2 | J31: =H31*I31 -> 481.9093 | L31: =A31 -> 0 | AD31: 240.7 | AE31: 481.4 | AF31: =H31-AD31 -> 0.254651
B32: 斜腹杆 | C32: N31 | D32: Q355D | E32: 14038 | F32: 1200 | G32: 36 | H32: =IF(AC32>0,AC32/1000000*(G32/1000)*7850,(E32/1000)*(F32/1000)*(G32/1000)*7850) -> 4760.5666 | I32: 1 | J32: =H32*I32 -> 4760.5666 | L32: =A32 -> 0 | AD32: 4761.8 | AE32: 4761.8 | AF32: =H32-AD32 -> -1.23344
B33: 斜腹杆 | C33: N31a | D33: Q355D | E33: 14038 | F33: 1200 | G33: 36 | H33: =IF(AC33>0,AC33/1000000*(G33/1000)*7850,(E33/1000)*(F33/1000)*(G33/1000)*7850) -> 4760.5666 | I33: 1 | J33: =H33*I33 -> 4760.5666 | L33: =A33 -> 0 | AD33: 4761.8 | AE33: 4761.8 | AF33: =H33-AD33 -> -1.23344
B34: 斜腹杆 | C34: N32 | D34: Q355D | E34: 9838 | F34: 1360 | G34: 36 | H34: =IF(AC34>0,AC34/1000000*(G34/1000)*7850,(E34/1000)*(F34/1000)*(G34/1000)*7850) -> 3781.0976 | I34: 2 | J34: =H34*I34 -> 7562.1951 | L34: =A34 -> 0 | AD34: 3781.2 | AE34: 7562.4 | AF34: =H34-AD34 -> -0.102432
... B60: 横梁接头 | C60: N71a | D60: Q355D | E60: 1980 | F60: 622 | G60: 16 | H60: =IF(AC60>0,AC60/1000000*(G60/1000)*7850,(E60/1000)*(F60/1000)*(G60/1000)*7850) -> 154.68394 | I60: 4 | J60: =H60*I60 -> 618.73574 | L60: =A60 -> 0 | AD60: 154.5 | AE60: 618 | AF60: =H60-AD60 -> 0.183936
B61: 横梁接头 | C61: N72 | D61: Q355D | G61: 24 | H61: =IF(AC61>0,AC61/1000000*(G61/1000)*7850,(E61/1000)*(F61/1000)*(G61/1000)*7850) -> 88.548 | I61: 6 | J61: =H61*I61 -> 531.288 | L61: =A61 -> 0 | AC61: 470000 | AD61: 88.4 | AE61: 530.4 | AF61: =H61-AD61 -> 0.148
B62: 横梁接头 | C62: N72' | D62: Q355D | G62: 24 | H62: =IF(AC62>0,AC62/1000000*(G62/1000)*7850,(E62/1000)*(F62/1000)*(G62/1000)*7850) -> 90.432 | I62: 6 | J62: =H62*I62 -> 542.592 | L62: =A62 -> 0 | AC62: 480000 | AD62: 90.4 | AE62: 542.4 | AF62: =H62-AD62 -> 0.032
B63: 横梁接头 | C63: N72a | D63: Q355D | G63: 24 | H63: =IF(AC63>0,AC63/1000000*(G63/1000)*7850,(E63/1000)*(F63/1000)*(G63/1000)*7850) -> 182.748 | I63: 2 | J63: =H63*I63 -> 365.496 | L63: =A63 -> 0 | AC63: 970000 | AD63: 182 | AE63: 364 | AF63: =H63-AD63 -> 0.748
B64: 横梁接头 | C64: N72b | D64: Q355D | G64: 24 | H64: =IF(AC64>0,AC64/1000000*(G64/1000)*7850,(E64/1000)*(F64/1000)*(G64/1000)*7850) -> 90.432 | I64: 2 | J64: =H64*I64 -> 180.864 | L64: =A64 -> 0 | AC64: 480000 | AD64: 90 | AE64: 180 | AF64: =H64-AD64 -> 0.432
B65: 横梁接头 | C65: N73 | D65: Q355D | E65: 1800 | F65: 626 | G65: 16 | H65: =IF(AC65>0,AC65/1000000*(G65/1000)*7850,(E65/1000)*(F65/1000)*(G65/1000)*7850) -> 141.52608 | I65: 8 | J65: =H65*I65 -> 1132.2086 | L65: =A65 -> 0 | AD65: 141.9 | AE65: 1135.2 | AF65: =H65-AD65 -> -0.37392
B66: 横梁接头 | C66: N73a | D66: Q355D | E66: 1800 | F66: 610 | G66: 28 | H66: =IF(AC66>0,AC66/1000000*(G66/1000)*7850,(E66/1000)*(F66/1000)*(G66/1000)*7850) -> 241.3404 | I66: 4 | J66: =H66*I66 -> 965.3616 | L66: =A66 -> 0 | AD66: 241.8 | AE66: 967.2 | AF66: =H66-AD66 -> -0.4596
...

Sheet 横隔板
A2: 梁板编号 | B2: 板件名称 | C2: 位置 | D2: 材质 | E2: 长 | F2: 宽 | G2: 厚 | H2: 数量 | I2: 单件重 | J2: 全桥数量 | K2: 合计重量 | L2: 备注 | M2: 梁板编号 | O2: 复核数量 | Y2: 图纸数量 | Z2: 差异 | AA2: 备注
E3: mm | F3: mm | G3: mm | I3: kg | K3: kg | N3: 10 | O3: 12 | P3: 14 | Q3: 16 | R3: 20 | S3: 24 | T3: 28 | U3: 30 | V3: 40 | W3: 50 | X3: 合计
A4: 横隔板 | B4: Z1边支点横隔板 | C4: N1 | D4: Q355MD | O4: =SUMIF(G4:G22,$O$3,K4:K22) -> 0 | P4: =SUMIF(G4:G22,$P$3,K4:K22) -> 0 | Q4: =SUMIF(G4:G22,$Q$3,K4:K22) -> 0 | R4: =SUMIF(G4:G22,$R$3,K4:K22) -> 0 | S4: =SUMIF(G4:G22,$S$3,K4:K22) -> 0 | U4: =SUMIF(G4:G22,$U$3,K4:K22) -> 0 | V4: =SUMIF(G4:G22,$V$3,K4:K22) -> 0 | X4: =SUM(O4:V23) -> 0 | Y4: 141101.8 | Z4: =X4-Y4 -> -141101.8
C5: N2 | D5: Q355MD
C6: N3 | D6: Q355MD
C7: N3' | D7: Q355MD
C8: N3a | D8: Q355MD
C9: N3a' | D9: Q355MD
C10: N3b | D10: Q355MD
C11: N3b' | D11: Q355MD
C12: N3c | D12: Q355MD
C13: N3c' | D13: Q355MD
C14: N3d | D14: Q355MD
C15: N3d' | D15: Q355MD
C16: N4 | D16: Q355MD
... C22: N10 | D22: Q355MD
B23: 小计
A24: 横隔板 | B24: T1上层挑梁 | C24: N1T | D24: Q355MD | Q24: =K27+K28 -> 0 | R24: =K24+K25 -> 0 | X24: =SUM(N24:V24) -> 0 | Y24: 1532.1 | Z24: =X24-Y24 -> -1532.1
C25: N2T | D25: Q355MD
C26: N3T | D26: Q355MD
C27: N4T | D27: Q355MD
C28: N4Ta | D28: Q355MD
B29: 小计
A30: 横隔板 | B30: T2上层挑梁 | C30: N1 | D30: Q355MD | Q30: =K33+K34 -> 0 | R30: =K30+K31 -> 0 | X30: =SUM(N30:V30) -> 0 | Y30: 1387.5 | Z30: =X30-Y30 -> -1387.5
C31: N2 | D31: Q355MD
C32: N3 | D32: Q355MD
C33: N4 | D33: Q355MD
C34: N4a | D34: Q355MD
B35: 小计
A36: 横隔板 | B36: T3下层挑梁 | C36: N1' | D36: Q355MD | Q36: =K39+K40 -> 0 | R36: =K36+K37 -> 0 | X36: =SUM(N36:V36) -> 0 | Y36: 1492.9 | Z36: =X36-Y36 -> -1492.9
C37: N2' | D37: Q355MD
C38: N3' | D38: Q355MD
C39: N4' | D39: Q355MD
C40: N4a' | D40: Q355MD
B41: 小计
A42: 横隔板 | B42: Z2支点横梁 | C42: N1 | D42: Q355MD | O42: =K50 -> 0 | R42: =K42+K48 -> 0 | S42: =K44+K45+K46+K47+K49 -> 0 | T42: =K43 -> 0 | V42: =K51 -> 0 | W42: =K52 -> 0 | X42: =SUM(N42:W53) -> 0 | Y42: =56228.4-831 -> 55397.4 | Z42: =X42-Y42 -> -55397.4
C43: N2 | D43: Q355MD
C44: N3 | D44: Q355MD
C45: N3a | D45: Q355MD
C46: N3b | D46: Q355MD
...

Sheet 梁底挡块
A2: 梁板编号 | B2: 板件名称 | C2: 位置 | D2: 材质 | E2: 长 | F2: 宽 | G2: 厚 | H2: 数量 | I2: 单件重 | J2: 全桥数量 | K2: 合计重量 | L2: 备注 | M2: 梁板编号 | S2: 图纸数量 | T2: 差异 | U2: 备注
E3: mm | F3: mm | G3: mm | I3: kg | K3: kg | N3: 16 | O3: 20 | P3: 24 | Q3: 28 | R3: 合计
A4: 梁间横梁 | B4: XJHL1 | C4: N1 | D4: Q355MD | O4: =K6 -> 0 | R4: =SUM(N4:Q6) -> 0 | S4: 7638.4 | T4: =R4-S4 -> -7638.4
C5: N2 | D5: Q355MD
B6: 小计
A7: 名称 | D7: 材质
A8: 合计 | D8: =D5 -> Q355MD

Sheet 附属预埋件
A2: 梁板编号 | B2: 板件名称 | C2: 位置 | D2: 材质 | E2: 长 | F2: 宽 | G2: 厚 | H2: 数量 | I2: 单件重 | J2: 全桥数量 | K2: 合计重量 | L2: 备注 | M2: 梁板编号 | S2: 图纸数量 | T2: 差异 | U2: 备注
E3: mm | F3: mm | G3: mm | I3: kg | K3: kg | N3: 4 | O3: 12 | P3: 24 | Q3: 28 | R3: 合计
A4: 排水 | B4: XJHL1 | C4: 上层N1 | D4: Q355C | O4: =K4+K5+K6+K7 -> 0 | R4: =SUM(N4:Q9) -> 0 | S4: 7835.18 | T4: =R4-S4 -> -7835.18
C5: 下层N1 | D5: Q355C
C6: 上层N2 | D6: Q355C
C7: 下层N2 | D7: Q355C
C8: N3 | D8: Q355C
B9: 小计
A10: 名称 | D10: 材质
A11: 合计 | D11: =D8 -> Q355C
